2025-06-12 06:12:14,313 - uvicorn.error - INFO - Application startup complete.
2025-06-12 06:13:40,913 - uvicorn.access - INFO - 127.0.0.1:65170 - "POST /api/v1/projects/ HTTP/1.1" 201
2025-06-12 06:14:54,882 - uvicorn.access - INFO - 127.0.0.1:65297 - "GET /api/v1/projects/ HTTP/1.1" 200
2025-06-12 06:15:17,391 - uvicorn.access - INFO - 127.0.0.1:65329 - "POST /api/v1/tasks/ HTTP/1.1" 201
2025-06-12 06:15:40,270 - uvicorn.access - INFO - 127.0.0.1:65374 - "GET /api/v1/tasks/?project_id=53c423c1648c4bb5bc4aa08659a9c608 HTTP/1.1" 200
2025-06-12 06:16:12,979 - uvicorn.access - INFO - 127.0.0.1:65426 - "GET /api/v1/tasks/b5e58f23b7c74715aed026b4f50ce46e HTTP/1.1" 200
2025-06-12 06:16:31,251 - uvicorn.access - INFO - 127.0.0.1:65456 - "PUT /api/v1/tasks/b5e58f23b7c74715aed026b4f50ce46e HTTP/1.1" 200
2025-06-12 06:16:46,831 - uvicorn.access - INFO - 127.0.0.1:65479 - "GET /api/v1/tasks/b5e58f23b7c74715aed026b4f50ce46e HTTP/1.1" 200
2025-06-12 06:17:06,024 - uvicorn.access - INFO - 127.0.0.1:65506 - "DELETE /api/v1/tasks/b5e58f23b7c74715aed026b4f50ce46e HTTP/1.1" 204
2025-06-12 06:17:29,698 - uvicorn.access - INFO - 127.0.0.1:49156 - "GET /api/v1/tasks/b5e58f23b7c74715aed026b4f50ce46e HTTP/1.1" 404
2025-06-12 06:18:20,060 - uvicorn.access - INFO - 127.0.0.1:49242 - "GET /api/v1/tasks/b5e58f23b7c74715aed026b4f50ce46e HTTP/1.1" 404
2025-06-12 06:18:43,878 - uvicorn.access - INFO - 127.0.0.1:49295 - "GET /api/v1/tasks/b5e58f23b7c74715aed026b4f50ce46e HTTP/1.1" 404
2025-06-12 06:19:07,511 - uvicorn.access - INFO - 127.0.0.1:49330 - "GET /api/v1/tasks/b5e58f23b7c74715aed026b4f50ce46e HTTP/1.1" 404
2025-06-12 06:19:41,059 - uvicorn.error - INFO - Shutting down
2025-06-12 06:19:41,166 - uvicorn.error - INFO - Waiting for application shutdown.
2025-06-12 06:19:41,167 - uvicorn.error - INFO - Application shutdown complete.
2025-06-12 06:19:41,167 - uvicorn.error - INFO - Finished server process [36372]
2025-06-12 06:19:41,762 - uvicorn.error - INFO - Application startup complete.
2025-06-12 06:20:07,819 - uvicorn.error - INFO - Shutting down
2025-06-12 06:20:07,926 - uvicorn.error - INFO - Waiting for application shutdown.
2025-06-12 06:20:07,926 - uvicorn.error - INFO - Application shutdown complete.
2025-06-12 06:20:07,927 - uvicorn.error - INFO - Finished server process [11748]
2025-06-12 06:20:08,613 - uvicorn.error - INFO - Application startup complete.
2025-06-12 06:20:36,790 - uvicorn.error - INFO - Shutting down
2025-06-12 06:20:36,898 - uvicorn.error - INFO - Waiting for application shutdown.
2025-06-12 06:20:36,899 - uvicorn.error - INFO - Application shutdown complete.
2025-06-12 06:20:36,899 - uvicorn.error - INFO - Finished server process [29832]
2025-06-12 06:20:37,509 - uvicorn.error - INFO - Application startup complete.
2025-06-12 06:20:37,512 - uvicorn.error - ERROR - Traceback (most recent call last):
  File "C:\Program Files\Python311\Lib\asyncio\runners.py", line 118, in run
    return self._loop.run_until_complete(task)
           ^^^^^^^^^^^^^^^^^^^^^^^^^^^^^^^^^^^
  File "C:\Program Files\Python311\Lib\asyncio\base_events.py", line 650, in run_until_complete
    return future.result()
           ^^^^^^^^^^^^^^^
asyncio.exceptions.CancelledError

During handling of the above exception, another exception occurred:

Traceback (most recent call last):
  File "C:\Program Files\Python311\Lib\asyncio\runners.py", line 190, in run
    return runner.run(main)
           ^^^^^^^^^^^^^^^^
  File "C:\Program Files\Python311\Lib\asyncio\runners.py", line 123, in run
    raise KeyboardInterrupt()
KeyboardInterrupt

During handling of the above exception, another exception occurred:

Traceback (most recent call last):
  File "C:\Program Files\Python311\Lib\contextlib.py", line 222, in __aexit__
    await self.gen.athrow(typ, value, traceback)
  File "E:\tech\trm-os-branches\trm_api\main.py", line 13, in lifespan
    yield
  File "e:\tech\trm-os-branches\.venv\Lib\site-packages\starlette\routing.py", line 743, in lifespan
    await receive()
  File "e:\tech\trm-os-branches\.venv\Lib\site-packages\uvicorn\lifespan\on.py", line 137, in receive
    return await self.receive_queue.get()
           ^^^^^^^^^^^^^^^^^^^^^^^^^^^^^^
  File "C:\Program Files\Python311\Lib\asyncio\queues.py", line 158, in get
    await getter
asyncio.exceptions.CancelledError

2025-06-12 06:20:38,141 - uvicorn.error - INFO - Application startup complete.
2025-06-12 06:21:18,150 - uvicorn.error - INFO - Shutting down
2025-06-12 06:21:18,259 - uvicorn.error - INFO - Waiting for application shutdown.
2025-06-12 06:21:18,260 - uvicorn.error - INFO - Application shutdown complete.
2025-06-12 06:21:18,261 - uvicorn.error - INFO - Finished server process [40520]
2025-06-12 06:21:18,935 - uvicorn.error - INFO - Application startup complete.
2025-06-12 06:22:45,632 - uvicorn.error - INFO - Shutting down
2025-06-12 06:22:45,740 - uvicorn.error - INFO - Waiting for application shutdown.
2025-06-12 06:22:45,740 - uvicorn.error - INFO - Application shutdown complete.
2025-06-12 06:22:45,740 - uvicorn.error - INFO - Finished server process [18264]
2025-06-12 06:22:46,362 - uvicorn.error - INFO - Application startup complete.
2025-06-12 06:22:55,076 - uvicorn.error - INFO - Shutting down
2025-06-12 06:22:55,184 - uvicorn.error - INFO - Waiting for application shutdown.
2025-06-12 06:22:55,185 - uvicorn.error - INFO - Application shutdown complete.
2025-06-12 06:22:55,185 - uvicorn.error - INFO - Finished server process [36348]
2025-06-12 06:22:55,800 - uvicorn.error - INFO - Application startup complete.
2025-06-12 06:24:08,797 - uvicorn.access - INFO - 127.0.0.1:49946 - "GET /api/v1/users/ HTTP/1.1" 200
2025-06-12 06:24:23,463 - uvicorn.access - INFO - 127.0.0.1:49974 - "GET /api/v1/users/ HTTP/1.1" 200
2025-06-12 06:26:16,937 - uvicorn.access - INFO - 127.0.0.1:50186 - "POST /api/v1/users/ HTTP/1.1" 201
2025-06-12 06:27:53,597 - uvicorn.access - INFO - 127.0.0.1:50322 - "POST /api/v1/teams/ HTTP/1.1" 201
2025-06-12 06:28:11,996 - uvicorn.access - INFO - 127.0.0.1:50351 - "GET /api/v1/teams/ HTTP/1.1" 200
2025-06-12 06:29:08,994 - uvicorn.access - INFO - 127.0.0.1:50427 - "GET /api/v1/teams/5636a33398654f0489f36ea1a8dc07f3 HTTP/1.1" 200
2025-06-12 06:29:40,130 - uvicorn.access - INFO - 127.0.0.1:50479 - "GET /api/v1/teams/5636a33398654f0489f36ea1a8dc07f3 HTTP/1.1" 200
2025-06-12 06:30:06,285 - uvicorn.access - INFO - 127.0.0.1:50518 - "POST /api/v1/teams/5636a33398654f0489f36ea1a8dc07f3/members/e95a29d2a97b4d1b860bde848af1332d HTTP/1.1" 200
2025-06-12 06:30:29,659 - uvicorn.access - INFO - 127.0.0.1:50563 - "GET /api/v1/teams/5636a33398654f0489f36ea1a8dc07f3/members HTTP/1.1" 200
2025-06-12 06:30:50,137 - uvicorn.access - INFO - 127.0.0.1:50596 - "PUT /api/v1/teams/5636a33398654f0489f36ea1a8dc07f3 HTTP/1.1" 200
2025-06-12 06:31:06,642 - uvicorn.access - INFO - 127.0.0.1:50621 - "GET /api/v1/teams/5636a33398654f0489f36ea1a8dc07f3 HTTP/1.1" 200
2025-06-12 06:31:30,564 - uvicorn.access - INFO - 127.0.0.1:50654 - "DELETE /api/v1/teams/5636a33398654f0489f36ea1a8dc07f3 HTTP/1.1" 204
2025-06-12 06:31:51,409 - uvicorn.access - INFO - 127.0.0.1:50685 - "GET /api/v1/teams/5636a33398654f0489f36ea1a8dc07f3 HTTP/1.1" 404
2025-06-12 06:32:45,809 - uvicorn.error - INFO - Shutting down
2025-06-12 06:32:45,919 - uvicorn.error - INFO - Waiting for application shutdown.
2025-06-12 06:32:45,920 - uvicorn.error - INFO - Application shutdown complete.
2025-06-12 06:32:45,920 - uvicorn.error - INFO - Finished server process [1900]
2025-06-12 06:32:46,593 - uvicorn.error - INFO - Application startup complete.
2025-06-12 06:32:46,595 - uvicorn.error - ERROR - Traceback (most recent call last):
  File "C:\Program Files\Python311\Lib\asyncio\runners.py", line 118, in run
    return self._loop.run_until_complete(task)
           ^^^^^^^^^^^^^^^^^^^^^^^^^^^^^^^^^^^
  File "C:\Program Files\Python311\Lib\asyncio\base_events.py", line 650, in run_until_complete
    return future.result()
           ^^^^^^^^^^^^^^^
asyncio.exceptions.CancelledError

During handling of the above exception, another exception occurred:

Traceback (most recent call last):
  File "C:\Program Files\Python311\Lib\asyncio\runners.py", line 190, in run
    return runner.run(main)
           ^^^^^^^^^^^^^^^^
  File "C:\Program Files\Python311\Lib\asyncio\runners.py", line 123, in run
    raise KeyboardInterrupt()
KeyboardInterrupt

During handling of the above exception, another exception occurred:

Traceback (most recent call last):
  File "C:\Program Files\Python311\Lib\contextlib.py", line 222, in __aexit__
    await self.gen.athrow(typ, value, traceback)
  File "E:\tech\trm-os-branches\trm_api\main.py", line 13, in lifespan
    yield
  File "e:\tech\trm-os-branches\.venv\Lib\site-packages\starlette\routing.py", line 743, in lifespan
    await receive()
  File "e:\tech\trm-os-branches\.venv\Lib\site-packages\uvicorn\lifespan\on.py", line 137, in receive
    return await self.receive_queue.get()
           ^^^^^^^^^^^^^^^^^^^^^^^^^^^^^^
  File "C:\Program Files\Python311\Lib\asyncio\queues.py", line 158, in get
    await getter
asyncio.exceptions.CancelledError

2025-06-12 06:32:47,173 - uvicorn.error - INFO - Application startup complete.
2025-06-12 06:33:19,620 - uvicorn.error - INFO - Shutting down
2025-06-12 06:33:19,727 - uvicorn.error - INFO - Waiting for application shutdown.
2025-06-12 06:33:19,729 - uvicorn.error - INFO - Application shutdown complete.
2025-06-12 06:33:19,729 - uvicorn.error - INFO - Finished server process [27984]
2025-06-12 06:33:20,331 - uvicorn.error - INFO - Application startup complete.
2025-06-12 06:33:34,048 - uvicorn.error - INFO - Shutting down
2025-06-12 06:33:34,157 - uvicorn.error - INFO - Waiting for application shutdown.
2025-06-12 06:33:34,157 - uvicorn.error - INFO - Application shutdown complete.
2025-06-12 06:33:34,157 - uvicorn.error - INFO - Finished server process [39128]
2025-06-12 06:33:34,889 - uvicorn.error - INFO - Application startup complete.
2025-06-12 06:34:34,941 - uvicorn.error - INFO - Shutting down
2025-06-12 06:34:35,049 - uvicorn.error - INFO - Waiting for application shutdown.
2025-06-12 06:34:35,050 - uvicorn.error - INFO - Application shutdown complete.
2025-06-12 06:34:35,050 - uvicorn.error - INFO - Finished server process [34272]
2025-06-12 06:34:35,650 - uvicorn.error - INFO - Application startup complete.
2025-06-12 06:34:50,564 - uvicorn.error - INFO - Shutting down
2025-06-12 06:34:50,673 - uvicorn.error - INFO - Waiting for application shutdown.
2025-06-12 06:34:50,673 - uvicorn.error - INFO - Application shutdown complete.
2025-06-12 06:34:50,674 - uvicorn.error - INFO - Finished server process [37264]
2025-06-12 06:34:51,320 - uvicorn.error - INFO - Application startup complete.
2025-06-12 06:35:20,932 - uvicorn.error - INFO - Shutting down
2025-06-12 06:35:21,040 - uvicorn.error - INFO - Waiting for application shutdown.
2025-06-12 06:35:21,041 - uvicorn.error - INFO - Application shutdown complete.
2025-06-12 06:35:21,041 - uvicorn.error - INFO - Finished server process [2496]
2025-06-12 06:35:21,643 - uvicorn.error - INFO - Application startup complete.
2025-06-12 06:36:06,023 - uvicorn.error - INFO - Shutting down
2025-06-12 06:36:06,131 - uvicorn.error - INFO - Waiting for application shutdown.
2025-06-12 06:36:06,131 - uvicorn.error - INFO - Application shutdown complete.
2025-06-12 06:36:06,132 - uvicorn.error - INFO - Finished server process [40184]
2025-06-12 06:36:06,740 - uvicorn.error - INFO - Application startup complete.
2025-06-12 06:37:02,975 - uvicorn.access - INFO - 127.0.0.1:51202 - "POST /api/v1/skills/ HTTP/1.1" 500
2025-06-12 06:37:02,975 - uvicorn.error - ERROR - Exception in ASGI application
Traceback (most recent call last):
  File "e:\tech\trm-os-branches\.venv\Lib\site-packages\uvicorn\protocols\http\httptools_impl.py", line 411, in run_asgi
    result = await app(  # type: ignore[func-returns-value]
             ^^^^^^^^^^^^^^^^^^^^^^^^^^^^^^^^^^^^^^^^^^^^^^
  File "e:\tech\trm-os-branches\.venv\Lib\site-packages\uvicorn\middleware\proxy_headers.py", line 69, in __call__
    return await self.app(scope, receive, send)
           ^^^^^^^^^^^^^^^^^^^^^^^^^^^^^^^^^^^^
  File "e:\tech\trm-os-branches\.venv\Lib\site-packages\fastapi\applications.py", line 1054, in __call__
    await super().__call__(scope, receive, send)
  File "e:\tech\trm-os-branches\.venv\Lib\site-packages\starlette\applications.py", line 123, in __call__
    await self.middleware_stack(scope, receive, send)
  File "e:\tech\trm-os-branches\.venv\Lib\site-packages\starlette\middleware\errors.py", line 186, in __call__
    raise exc
  File "e:\tech\trm-os-branches\.venv\Lib\site-packages\starlette\middleware\errors.py", line 164, in __call__
    await self.app(scope, receive, _send)
  File "e:\tech\trm-os-branches\.venv\Lib\site-packages\starlette\middleware\exceptions.py", line 62, in __call__
    await wrap_app_handling_exceptions(self.app, conn)(scope, receive, send)
  File "e:\tech\trm-os-branches\.venv\Lib\site-packages\starlette\_exception_handler.py", line 64, in wrapped_app
    raise exc
  File "e:\tech\trm-os-branches\.venv\Lib\site-packages\starlette\_exception_handler.py", line 53, in wrapped_app
    await app(scope, receive, sender)
  File "e:\tech\trm-os-branches\.venv\Lib\site-packages\starlette\routing.py", line 758, in __call__
    await self.middleware_stack(scope, receive, send)
  File "e:\tech\trm-os-branches\.venv\Lib\site-packages\starlette\routing.py", line 778, in app
    await route.handle(scope, receive, send)
  File "e:\tech\trm-os-branches\.venv\Lib\site-packages\starlette\routing.py", line 299, in handle
    await self.app(scope, receive, send)
  File "e:\tech\trm-os-branches\.venv\Lib\site-packages\starlette\routing.py", line 79, in app
    await wrap_app_handling_exceptions(app, request)(scope, receive, send)
  File "e:\tech\trm-os-branches\.venv\Lib\site-packages\starlette\_exception_handler.py", line 64, in wrapped_app
    raise exc
  File "e:\tech\trm-os-branches\.venv\Lib\site-packages\starlette\_exception_handler.py", line 53, in wrapped_app
    await app(scope, receive, sender)
  File "e:\tech\trm-os-branches\.venv\Lib\site-packages\starlette\routing.py", line 74, in app
    response = await func(request)
               ^^^^^^^^^^^^^^^^^^^
  File "e:\tech\trm-os-branches\.venv\Lib\site-packages\fastapi\routing.py", line 278, in app
    raw_response = await run_endpoint_function(
                   ^^^^^^^^^^^^^^^^^^^^^^^^^^^^
  File "e:\tech\trm-os-branches\.venv\Lib\site-packages\fastapi\routing.py", line 193, in run_endpoint_function
    return await run_in_threadpool(dependant.call, **values)
           ^^^^^^^^^^^^^^^^^^^^^^^^^^^^^^^^^^^^^^^^^^^^^^^^^
  File "e:\tech\trm-os-branches\.venv\Lib\site-packages\starlette\concurrency.py", line 42, in run_in_threadpool
    return await anyio.to_thread.run_sync(func, *args)
           ^^^^^^^^^^^^^^^^^^^^^^^^^^^^^^^^^^^^^^^^^^^
  File "e:\tech\trm-os-branches\.venv\Lib\site-packages\anyio\to_thread.py", line 56, in run_sync
    return await get_async_backend().run_sync_in_worker_thread(
           ^^^^^^^^^^^^^^^^^^^^^^^^^^^^^^^^^^^^^^^^^^^^^^^^^^^^
  File "e:\tech\trm-os-branches\.venv\Lib\site-packages\anyio\_backends\_asyncio.py", line 2470, in run_sync_in_worker_thread
    return await future
           ^^^^^^^^^^^^
  File "e:\tech\trm-os-branches\.venv\Lib\site-packages\anyio\_backends\_asyncio.py", line 967, in run
    result = context.run(func, *args)
             ^^^^^^^^^^^^^^^^^^^^^^^^
  File "E:\tech\trm-os-branches\trm_api\api\v1\endpoints\skill.py", line 15, in create_skill
    return repository.create_skill(skill_data=skill_in)
           ^^^^^^^^^^^^^^^^^^^^^^^^^^^^^^^^^^^^^^^^^^^^
  File "E:\tech\trm-os-branches\trm_api\repositories\skill.py", line 20, in create_skill
    skill = GraphSkill(**skill_data.model_dump()).save()
            ^^^^^^^^^^^^^^^^^^^^^^^^^^^^^^^^^^^^^
  File "e:\tech\trm-os-branches\.venv\Lib\site-packages\neomodel\sync_\core.py", line 1113, in __init__
    self.__dict__[key] = val.build_manager(self, key)
                         ^^^^^^^^^^^^^^^^^^^^^^^^^^^^
  File "e:\tech\trm-os-branches\.venv\Lib\site-packages\neomodel\sync_\relationship_manager.py", line 496, in build_manager
    self.lookup_node_class()
  File "e:\tech\trm-os-branches\.venv\Lib\site-packages\neomodel\sync_\relationship_manager.py", line 493, in lookup_node_class
    self.definition["node_class"] = getattr(sys.modules[module], name)
                                    ^^^^^^^^^^^^^^^^^^^^^^^^^^^^^^^^^^
AttributeError: module 'trm_api.graph_models.user' has no attribute 'GraphUser'
2025-06-12 06:37:27,610 - uvicorn.access - INFO - 127.0.0.1:51254 - "GET /api/v1/skills/ HTTP/1.1" 500
2025-06-12 06:37:27,610 - uvicorn.error - ERROR - Exception in ASGI application
Traceback (most recent call last):
  File "e:\tech\trm-os-branches\.venv\Lib\site-packages\uvicorn\protocols\http\httptools_impl.py", line 411, in run_asgi
    result = await app(  # type: ignore[func-returns-value]
             ^^^^^^^^^^^^^^^^^^^^^^^^^^^^^^^^^^^^^^^^^^^^^^
  File "e:\tech\trm-os-branches\.venv\Lib\site-packages\uvicorn\middleware\proxy_headers.py", line 69, in __call__
    return await self.app(scope, receive, send)
           ^^^^^^^^^^^^^^^^^^^^^^^^^^^^^^^^^^^^
  File "e:\tech\trm-os-branches\.venv\Lib\site-packages\fastapi\applications.py", line 1054, in __call__
    await super().__call__(scope, receive, send)
  File "e:\tech\trm-os-branches\.venv\Lib\site-packages\starlette\applications.py", line 123, in __call__
    await self.middleware_stack(scope, receive, send)
  File "e:\tech\trm-os-branches\.venv\Lib\site-packages\starlette\middleware\errors.py", line 186, in __call__
    raise exc
  File "e:\tech\trm-os-branches\.venv\Lib\site-packages\starlette\middleware\errors.py", line 164, in __call__
    await self.app(scope, receive, _send)
  File "e:\tech\trm-os-branches\.venv\Lib\site-packages\starlette\middleware\exceptions.py", line 62, in __call__
    await wrap_app_handling_exceptions(self.app, conn)(scope, receive, send)
  File "e:\tech\trm-os-branches\.venv\Lib\site-packages\starlette\_exception_handler.py", line 64, in wrapped_app
    raise exc
  File "e:\tech\trm-os-branches\.venv\Lib\site-packages\starlette\_exception_handler.py", line 53, in wrapped_app
    await app(scope, receive, sender)
  File "e:\tech\trm-os-branches\.venv\Lib\site-packages\starlette\routing.py", line 758, in __call__
    await self.middleware_stack(scope, receive, send)
  File "e:\tech\trm-os-branches\.venv\Lib\site-packages\starlette\routing.py", line 778, in app
    await route.handle(scope, receive, send)
  File "e:\tech\trm-os-branches\.venv\Lib\site-packages\starlette\routing.py", line 299, in handle
    await self.app(scope, receive, send)
  File "e:\tech\trm-os-branches\.venv\Lib\site-packages\starlette\routing.py", line 79, in app
    await wrap_app_handling_exceptions(app, request)(scope, receive, send)
  File "e:\tech\trm-os-branches\.venv\Lib\site-packages\starlette\_exception_handler.py", line 64, in wrapped_app
    raise exc
  File "e:\tech\trm-os-branches\.venv\Lib\site-packages\starlette\_exception_handler.py", line 53, in wrapped_app
    await app(scope, receive, sender)
  File "e:\tech\trm-os-branches\.venv\Lib\site-packages\starlette\routing.py", line 74, in app
    response = await func(request)
               ^^^^^^^^^^^^^^^^^^^
  File "e:\tech\trm-os-branches\.venv\Lib\site-packages\fastapi\routing.py", line 278, in app
    raw_response = await run_endpoint_function(
                   ^^^^^^^^^^^^^^^^^^^^^^^^^^^^
  File "e:\tech\trm-os-branches\.venv\Lib\site-packages\fastapi\routing.py", line 193, in run_endpoint_function
    return await run_in_threadpool(dependant.call, **values)
           ^^^^^^^^^^^^^^^^^^^^^^^^^^^^^^^^^^^^^^^^^^^^^^^^^
  File "e:\tech\trm-os-branches\.venv\Lib\site-packages\starlette\concurrency.py", line 42, in run_in_threadpool
    return await anyio.to_thread.run_sync(func, *args)
           ^^^^^^^^^^^^^^^^^^^^^^^^^^^^^^^^^^^^^^^^^^^
  File "e:\tech\trm-os-branches\.venv\Lib\site-packages\anyio\to_thread.py", line 56, in run_sync
    return await get_async_backend().run_sync_in_worker_thread(
           ^^^^^^^^^^^^^^^^^^^^^^^^^^^^^^^^^^^^^^^^^^^^^^^^^^^^
  File "e:\tech\trm-os-branches\.venv\Lib\site-packages\anyio\_backends\_asyncio.py", line 2470, in run_sync_in_worker_thread
    return await future
           ^^^^^^^^^^^^
  File "e:\tech\trm-os-branches\.venv\Lib\site-packages\anyio\_backends\_asyncio.py", line 967, in run
    result = context.run(func, *args)
             ^^^^^^^^^^^^^^^^^^^^^^^^
  File "E:\tech\trm-os-branches\trm_api\api\v1\endpoints\skill.py", line 32, in list_skills
    return repository.list_all_skills()
           ^^^^^^^^^^^^^^^^^^^^^^^^^^^^
  File "E:\tech\trm-os-branches\trm_api\repositories\skill.py", line 42, in list_all_skills
    return GraphSkill.nodes.all()
           ^^^^^^^^^^^^^^^^
  File "e:\tech\trm-os-branches\.venv\Lib\site-packages\neomodel\util.py", line 27, in __get__
    return self.getter(type)
           ^^^^^^^^^^^^^^^^^
  File "e:\tech\trm-os-branches\.venv\Lib\site-packages\neomodel\sync_\core.py", line 1150, in nodes
    return NodeSet(cls)
           ^^^^^^^^^^^^
  File "e:\tech\trm-os-branches\.venv\Lib\site-packages\neomodel\sync_\match.py", line 891, in __init__
    install_traversals(self.source_class, self)
  File "e:\tech\trm-os-branches\.venv\Lib\site-packages\neomodel\sync_\match.py", line 210, in install_traversals
    rel.lookup_node_class()
  File "e:\tech\trm-os-branches\.venv\Lib\site-packages\neomodel\sync_\relationship_manager.py", line 493, in lookup_node_class
    self.definition["node_class"] = getattr(sys.modules[module], name)
                                    ^^^^^^^^^^^^^^^^^^^^^^^^^^^^^^^^^^
AttributeError: module 'trm_api.graph_models.user' has no attribute 'GraphUser'
2025-06-12 06:37:54,205 - uvicorn.access - INFO - 127.0.0.1:51293 - "GET /api/v1/skills/ HTTP/1.1" 500
2025-06-12 06:37:54,206 - uvicorn.error - ERROR - Exception in ASGI application
Traceback (most recent call last):
  File "e:\tech\trm-os-branches\.venv\Lib\site-packages\uvicorn\protocols\http\httptools_impl.py", line 411, in run_asgi
    result = await app(  # type: ignore[func-returns-value]
             ^^^^^^^^^^^^^^^^^^^^^^^^^^^^^^^^^^^^^^^^^^^^^^
  File "e:\tech\trm-os-branches\.venv\Lib\site-packages\uvicorn\middleware\proxy_headers.py", line 69, in __call__
    return await self.app(scope, receive, send)
           ^^^^^^^^^^^^^^^^^^^^^^^^^^^^^^^^^^^^
  File "e:\tech\trm-os-branches\.venv\Lib\site-packages\fastapi\applications.py", line 1054, in __call__
    await super().__call__(scope, receive, send)
  File "e:\tech\trm-os-branches\.venv\Lib\site-packages\starlette\applications.py", line 123, in __call__
    await self.middleware_stack(scope, receive, send)
  File "e:\tech\trm-os-branches\.venv\Lib\site-packages\starlette\middleware\errors.py", line 186, in __call__
    raise exc
  File "e:\tech\trm-os-branches\.venv\Lib\site-packages\starlette\middleware\errors.py", line 164, in __call__
    await self.app(scope, receive, _send)
  File "e:\tech\trm-os-branches\.venv\Lib\site-packages\starlette\middleware\exceptions.py", line 62, in __call__
    await wrap_app_handling_exceptions(self.app, conn)(scope, receive, send)
  File "e:\tech\trm-os-branches\.venv\Lib\site-packages\starlette\_exception_handler.py", line 64, in wrapped_app
    raise exc
  File "e:\tech\trm-os-branches\.venv\Lib\site-packages\starlette\_exception_handler.py", line 53, in wrapped_app
    await app(scope, receive, sender)
  File "e:\tech\trm-os-branches\.venv\Lib\site-packages\starlette\routing.py", line 758, in __call__
    await self.middleware_stack(scope, receive, send)
  File "e:\tech\trm-os-branches\.venv\Lib\site-packages\starlette\routing.py", line 778, in app
    await route.handle(scope, receive, send)
  File "e:\tech\trm-os-branches\.venv\Lib\site-packages\starlette\routing.py", line 299, in handle
    await self.app(scope, receive, send)
  File "e:\tech\trm-os-branches\.venv\Lib\site-packages\starlette\routing.py", line 79, in app
    await wrap_app_handling_exceptions(app, request)(scope, receive, send)
  File "e:\tech\trm-os-branches\.venv\Lib\site-packages\starlette\_exception_handler.py", line 64, in wrapped_app
    raise exc
  File "e:\tech\trm-os-branches\.venv\Lib\site-packages\starlette\_exception_handler.py", line 53, in wrapped_app
    await app(scope, receive, sender)
  File "e:\tech\trm-os-branches\.venv\Lib\site-packages\starlette\routing.py", line 74, in app
    response = await func(request)
               ^^^^^^^^^^^^^^^^^^^
  File "e:\tech\trm-os-branches\.venv\Lib\site-packages\fastapi\routing.py", line 278, in app
    raw_response = await run_endpoint_function(
                   ^^^^^^^^^^^^^^^^^^^^^^^^^^^^
  File "e:\tech\trm-os-branches\.venv\Lib\site-packages\fastapi\routing.py", line 193, in run_endpoint_function
    return await run_in_threadpool(dependant.call, **values)
           ^^^^^^^^^^^^^^^^^^^^^^^^^^^^^^^^^^^^^^^^^^^^^^^^^
  File "e:\tech\trm-os-branches\.venv\Lib\site-packages\starlette\concurrency.py", line 42, in run_in_threadpool
    return await anyio.to_thread.run_sync(func, *args)
           ^^^^^^^^^^^^^^^^^^^^^^^^^^^^^^^^^^^^^^^^^^^
  File "e:\tech\trm-os-branches\.venv\Lib\site-packages\anyio\to_thread.py", line 56, in run_sync
    return await get_async_backend().run_sync_in_worker_thread(
           ^^^^^^^^^^^^^^^^^^^^^^^^^^^^^^^^^^^^^^^^^^^^^^^^^^^^
  File "e:\tech\trm-os-branches\.venv\Lib\site-packages\anyio\_backends\_asyncio.py", line 2470, in run_sync_in_worker_thread
    return await future
           ^^^^^^^^^^^^
  File "e:\tech\trm-os-branches\.venv\Lib\site-packages\anyio\_backends\_asyncio.py", line 967, in run
    result = context.run(func, *args)
             ^^^^^^^^^^^^^^^^^^^^^^^^
  File "E:\tech\trm-os-branches\trm_api\api\v1\endpoints\skill.py", line 32, in list_skills
    return repository.list_all_skills()
           ^^^^^^^^^^^^^^^^^^^^^^^^^^^^
  File "E:\tech\trm-os-branches\trm_api\repositories\skill.py", line 42, in list_all_skills
    return GraphSkill.nodes.all()
           ^^^^^^^^^^^^^^^^
  File "e:\tech\trm-os-branches\.venv\Lib\site-packages\neomodel\util.py", line 27, in __get__
    return self.getter(type)
           ^^^^^^^^^^^^^^^^^
  File "e:\tech\trm-os-branches\.venv\Lib\site-packages\neomodel\sync_\core.py", line 1150, in nodes
    return NodeSet(cls)
           ^^^^^^^^^^^^
  File "e:\tech\trm-os-branches\.venv\Lib\site-packages\neomodel\sync_\match.py", line 891, in __init__
    install_traversals(self.source_class, self)
  File "e:\tech\trm-os-branches\.venv\Lib\site-packages\neomodel\sync_\match.py", line 210, in install_traversals
    rel.lookup_node_class()
  File "e:\tech\trm-os-branches\.venv\Lib\site-packages\neomodel\sync_\relationship_manager.py", line 493, in lookup_node_class
    self.definition["node_class"] = getattr(sys.modules[module], name)
                                    ^^^^^^^^^^^^^^^^^^^^^^^^^^^^^^^^^^
AttributeError: module 'trm_api.graph_models.user' has no attribute 'GraphUser'
2025-06-12 06:38:17,420 - uvicorn.access - INFO - 127.0.0.1:51330 - "GET /api/v1/skills/ HTTP/1.1" 500
2025-06-12 06:38:17,421 - uvicorn.error - ERROR - Exception in ASGI application
Traceback (most recent call last):
  File "e:\tech\trm-os-branches\.venv\Lib\site-packages\uvicorn\protocols\http\httptools_impl.py", line 411, in run_asgi
    result = await app(  # type: ignore[func-returns-value]
             ^^^^^^^^^^^^^^^^^^^^^^^^^^^^^^^^^^^^^^^^^^^^^^
  File "e:\tech\trm-os-branches\.venv\Lib\site-packages\uvicorn\middleware\proxy_headers.py", line 69, in __call__
    return await self.app(scope, receive, send)
           ^^^^^^^^^^^^^^^^^^^^^^^^^^^^^^^^^^^^
  File "e:\tech\trm-os-branches\.venv\Lib\site-packages\fastapi\applications.py", line 1054, in __call__
    await super().__call__(scope, receive, send)
  File "e:\tech\trm-os-branches\.venv\Lib\site-packages\starlette\applications.py", line 123, in __call__
    await self.middleware_stack(scope, receive, send)
  File "e:\tech\trm-os-branches\.venv\Lib\site-packages\starlette\middleware\errors.py", line 186, in __call__
    raise exc
  File "e:\tech\trm-os-branches\.venv\Lib\site-packages\starlette\middleware\errors.py", line 164, in __call__
    await self.app(scope, receive, _send)
  File "e:\tech\trm-os-branches\.venv\Lib\site-packages\starlette\middleware\exceptions.py", line 62, in __call__
    await wrap_app_handling_exceptions(self.app, conn)(scope, receive, send)
  File "e:\tech\trm-os-branches\.venv\Lib\site-packages\starlette\_exception_handler.py", line 64, in wrapped_app
    raise exc
  File "e:\tech\trm-os-branches\.venv\Lib\site-packages\starlette\_exception_handler.py", line 53, in wrapped_app
    await app(scope, receive, sender)
  File "e:\tech\trm-os-branches\.venv\Lib\site-packages\starlette\routing.py", line 758, in __call__
    await self.middleware_stack(scope, receive, send)
  File "e:\tech\trm-os-branches\.venv\Lib\site-packages\starlette\routing.py", line 778, in app
    await route.handle(scope, receive, send)
  File "e:\tech\trm-os-branches\.venv\Lib\site-packages\starlette\routing.py", line 299, in handle
    await self.app(scope, receive, send)
  File "e:\tech\trm-os-branches\.venv\Lib\site-packages\starlette\routing.py", line 79, in app
    await wrap_app_handling_exceptions(app, request)(scope, receive, send)
  File "e:\tech\trm-os-branches\.venv\Lib\site-packages\starlette\_exception_handler.py", line 64, in wrapped_app
    raise exc
  File "e:\tech\trm-os-branches\.venv\Lib\site-packages\starlette\_exception_handler.py", line 53, in wrapped_app
    await app(scope, receive, sender)
  File "e:\tech\trm-os-branches\.venv\Lib\site-packages\starlette\routing.py", line 74, in app
    response = await func(request)
               ^^^^^^^^^^^^^^^^^^^
  File "e:\tech\trm-os-branches\.venv\Lib\site-packages\fastapi\routing.py", line 278, in app
    raw_response = await run_endpoint_function(
                   ^^^^^^^^^^^^^^^^^^^^^^^^^^^^
  File "e:\tech\trm-os-branches\.venv\Lib\site-packages\fastapi\routing.py", line 193, in run_endpoint_function
    return await run_in_threadpool(dependant.call, **values)
           ^^^^^^^^^^^^^^^^^^^^^^^^^^^^^^^^^^^^^^^^^^^^^^^^^
  File "e:\tech\trm-os-branches\.venv\Lib\site-packages\starlette\concurrency.py", line 42, in run_in_threadpool
    return await anyio.to_thread.run_sync(func, *args)
           ^^^^^^^^^^^^^^^^^^^^^^^^^^^^^^^^^^^^^^^^^^^
  File "e:\tech\trm-os-branches\.venv\Lib\site-packages\anyio\to_thread.py", line 56, in run_sync
    return await get_async_backend().run_sync_in_worker_thread(
           ^^^^^^^^^^^^^^^^^^^^^^^^^^^^^^^^^^^^^^^^^^^^^^^^^^^^
  File "e:\tech\trm-os-branches\.venv\Lib\site-packages\anyio\_backends\_asyncio.py", line 2470, in run_sync_in_worker_thread
    return await future
           ^^^^^^^^^^^^
  File "e:\tech\trm-os-branches\.venv\Lib\site-packages\anyio\_backends\_asyncio.py", line 967, in run
    result = context.run(func, *args)
             ^^^^^^^^^^^^^^^^^^^^^^^^
  File "E:\tech\trm-os-branches\trm_api\api\v1\endpoints\skill.py", line 32, in list_skills
    return repository.list_all_skills()
           ^^^^^^^^^^^^^^^^^^^^^^^^^^^^
  File "E:\tech\trm-os-branches\trm_api\repositories\skill.py", line 42, in list_all_skills
    return GraphSkill.nodes.all()
           ^^^^^^^^^^^^^^^^
  File "e:\tech\trm-os-branches\.venv\Lib\site-packages\neomodel\util.py", line 27, in __get__
    return self.getter(type)
           ^^^^^^^^^^^^^^^^^
  File "e:\tech\trm-os-branches\.venv\Lib\site-packages\neomodel\sync_\core.py", line 1150, in nodes
    return NodeSet(cls)
           ^^^^^^^^^^^^
  File "e:\tech\trm-os-branches\.venv\Lib\site-packages\neomodel\sync_\match.py", line 891, in __init__
    install_traversals(self.source_class, self)
  File "e:\tech\trm-os-branches\.venv\Lib\site-packages\neomodel\sync_\match.py", line 210, in install_traversals
    rel.lookup_node_class()
  File "e:\tech\trm-os-branches\.venv\Lib\site-packages\neomodel\sync_\relationship_manager.py", line 493, in lookup_node_class
    self.definition["node_class"] = getattr(sys.modules[module], name)
                                    ^^^^^^^^^^^^^^^^^^^^^^^^^^^^^^^^^^
AttributeError: module 'trm_api.graph_models.user' has no attribute 'GraphUser'
2025-06-12 07:20:43,257 - uvicorn.error - INFO - Application startup complete.
2025-06-12 07:20:45,877 - uvicorn.error - INFO - Shutting down
2025-06-12 07:20:45,984 - uvicorn.error - INFO - Waiting for application shutdown.
2025-06-12 07:20:45,984 - uvicorn.error - INFO - Application shutdown complete.
2025-06-12 07:20:45,984 - uvicorn.error - INFO - Finished server process [20884]
2025-06-12 15:16:35,877 - uvicorn.error - INFO - Application startup complete.
2025-06-12 15:16:35,877 - uvicorn.error - INFO - Uvicorn running on http://0.0.0.0:8000 (Press CTRL+C to quit)
2025-06-12 15:18:02,731 - uvicorn.access - INFO - 127.0.0.1:55563 - "GET /api/v1/docs HTTP/1.1" 404
2025-06-12 15:18:04,797 - uvicorn.access - INFO - 127.0.0.1:55572 - "POST /api/v1/users/ HTTP/1.1" 500
2025-06-12 15:18:04,798 - uvicorn.error - ERROR - Exception in ASGI application
Traceback (most recent call last):
  File "C:\Users\devpc\AppData\Roaming\Python\Python311\site-packages\uvicorn\protocols\http\httptools_impl.py", line 411, in run_asgi
    result = await app(  # type: ignore[func-returns-value]
             ^^^^^^^^^^^^^^^^^^^^^^^^^^^^^^^^^^^^^^^^^^^^^^
  File "C:\Users\devpc\AppData\Roaming\Python\Python311\site-packages\uvicorn\middleware\proxy_headers.py", line 69, in __call__
    return await self.app(scope, receive, send)
           ^^^^^^^^^^^^^^^^^^^^^^^^^^^^^^^^^^^^
  File "C:\Users\devpc\AppData\Roaming\Python\Python311\site-packages\fastapi\applications.py", line 1054, in __call__
    await super().__call__(scope, receive, send)
  File "C:\Users\devpc\AppData\Roaming\Python\Python311\site-packages\starlette\applications.py", line 123, in __call__
    await self.middleware_stack(scope, receive, send)
  File "C:\Users\devpc\AppData\Roaming\Python\Python311\site-packages\starlette\middleware\errors.py", line 186, in __call__
    raise exc
  File "C:\Users\devpc\AppData\Roaming\Python\Python311\site-packages\starlette\middleware\errors.py", line 164, in __call__
    await self.app(scope, receive, _send)
  File "C:\Users\devpc\AppData\Roaming\Python\Python311\site-packages\starlette\middleware\exceptions.py", line 62, in __call__
    await wrap_app_handling_exceptions(self.app, conn)(scope, receive, send)
  File "C:\Users\devpc\AppData\Roaming\Python\Python311\site-packages\starlette\_exception_handler.py", line 64, in wrapped_app
    raise exc
  File "C:\Users\devpc\AppData\Roaming\Python\Python311\site-packages\starlette\_exception_handler.py", line 53, in wrapped_app
    await app(scope, receive, sender)
  File "C:\Users\devpc\AppData\Roaming\Python\Python311\site-packages\starlette\routing.py", line 758, in __call__
    await self.middleware_stack(scope, receive, send)
  File "C:\Users\devpc\AppData\Roaming\Python\Python311\site-packages\starlette\routing.py", line 778, in app
    await route.handle(scope, receive, send)
  File "C:\Users\devpc\AppData\Roaming\Python\Python311\site-packages\starlette\routing.py", line 299, in handle
    await self.app(scope, receive, send)
  File "C:\Users\devpc\AppData\Roaming\Python\Python311\site-packages\starlette\routing.py", line 79, in app
    await wrap_app_handling_exceptions(app, request)(scope, receive, send)
  File "C:\Users\devpc\AppData\Roaming\Python\Python311\site-packages\starlette\_exception_handler.py", line 64, in wrapped_app
    raise exc
  File "C:\Users\devpc\AppData\Roaming\Python\Python311\site-packages\starlette\_exception_handler.py", line 53, in wrapped_app
    await app(scope, receive, sender)
  File "C:\Users\devpc\AppData\Roaming\Python\Python311\site-packages\starlette\routing.py", line 74, in app
    response = await func(request)
               ^^^^^^^^^^^^^^^^^^^
  File "C:\Users\devpc\AppData\Roaming\Python\Python311\site-packages\fastapi\routing.py", line 278, in app
    raw_response = await run_endpoint_function(
                   ^^^^^^^^^^^^^^^^^^^^^^^^^^^^
  File "C:\Users\devpc\AppData\Roaming\Python\Python311\site-packages\fastapi\routing.py", line 193, in run_endpoint_function
    return await run_in_threadpool(dependant.call, **values)
           ^^^^^^^^^^^^^^^^^^^^^^^^^^^^^^^^^^^^^^^^^^^^^^^^^
  File "C:\Users\devpc\AppData\Roaming\Python\Python311\site-packages\starlette\concurrency.py", line 42, in run_in_threadpool
    return await anyio.to_thread.run_sync(func, *args)
           ^^^^^^^^^^^^^^^^^^^^^^^^^^^^^^^^^^^^^^^^^^^
  File "C:\Users\devpc\AppData\Roaming\Python\Python311\site-packages\anyio\to_thread.py", line 56, in run_sync
    return await get_async_backend().run_sync_in_worker_thread(
           ^^^^^^^^^^^^^^^^^^^^^^^^^^^^^^^^^^^^^^^^^^^^^^^^^^^^
  File "C:\Users\devpc\AppData\Roaming\Python\Python311\site-packages\anyio\_backends\_asyncio.py", line 2470, in run_sync_in_worker_thread
    return await future
           ^^^^^^^^^^^^
  File "C:\Users\devpc\AppData\Roaming\Python\Python311\site-packages\anyio\_backends\_asyncio.py", line 967, in run
    result = context.run(func, *args)
             ^^^^^^^^^^^^^^^^^^^^^^^^
  File "E:\tech\trm-os-branches\trm_api\api\v1\endpoints\user.py", line 23, in create_user
    db_user = repo.get_user_by_email(email=user_in.email)
              ^^^^^^^^^^^^^^^^^^^^^^^^^^^^^^^^^^^^^^^^^^^
  File "E:\tech\trm-os-branches\trm_api\repositories\user_repository.py", line 43, in get_user_by_email
    return GraphUser.nodes.get(email=email)
           ^^^^^^^^^^^^^^^
  File "C:\Users\devpc\AppData\Roaming\Python\Python311\site-packages\neomodel\util.py", line 27, in __get__
    return self.getter(type)
           ^^^^^^^^^^^^^^^^^
  File "C:\Users\devpc\AppData\Roaming\Python\Python311\site-packages\neomodel\sync_\core.py", line 1150, in nodes
    return NodeSet(cls)
           ^^^^^^^^^^^^
  File "C:\Users\devpc\AppData\Roaming\Python\Python311\site-packages\neomodel\sync_\match.py", line 891, in __init__
    install_traversals(self.source_class, self)
  File "C:\Users\devpc\AppData\Roaming\Python\Python311\site-packages\neomodel\sync_\match.py", line 210, in install_traversals
    rel.lookup_node_class()
  File "C:\Users\devpc\AppData\Roaming\Python\Python311\site-packages\neomodel\sync_\relationship_manager.py", line 493, in lookup_node_class
    self.definition["node_class"] = getattr(sys.modules[module], name)
                                    ^^^^^^^^^^^^^^^^^^^^^^^^^^^^^^^^^^
AttributeError: module 'trm_api.graph_models.skill' has no attribute 'Skill'
2025-06-12 15:23:42,683 - uvicorn.error - INFO - Application startup complete.
2025-06-12 15:23:42,683 - uvicorn.error - ERROR - [Errno 10048] error while attempting to bind on address ('0.0.0.0', 8000): only one usage of each socket address (protocol/network address/port) is normally permitted
2025-06-12 15:23:42,683 - uvicorn.error - INFO - Waiting for application shutdown.
2025-06-12 15:23:42,683 - uvicorn.error - INFO - Application shutdown complete.
2025-06-12 15:24:42,154 - uvicorn.access - INFO - 127.0.0.1:56598 - "GET /api/v1/docs HTTP/1.1" 404
2025-06-12 15:24:44,205 - uvicorn.access - INFO - 127.0.0.1:56604 - "POST /api/v1/users/ HTTP/1.1" 500
2025-06-12 15:24:44,206 - uvicorn.error - ERROR - Exception in ASGI application
Traceback (most recent call last):
  File "C:\Users\devpc\AppData\Roaming\Python\Python311\site-packages\uvicorn\protocols\http\httptools_impl.py", line 411, in run_asgi
    result = await app(  # type: ignore[func-returns-value]
             ^^^^^^^^^^^^^^^^^^^^^^^^^^^^^^^^^^^^^^^^^^^^^^
  File "C:\Users\devpc\AppData\Roaming\Python\Python311\site-packages\uvicorn\middleware\proxy_headers.py", line 69, in __call__
    return await self.app(scope, receive, send)
           ^^^^^^^^^^^^^^^^^^^^^^^^^^^^^^^^^^^^
  File "C:\Users\devpc\AppData\Roaming\Python\Python311\site-packages\fastapi\applications.py", line 1054, in __call__
    await super().__call__(scope, receive, send)
  File "C:\Users\devpc\AppData\Roaming\Python\Python311\site-packages\starlette\applications.py", line 123, in __call__
    await self.middleware_stack(scope, receive, send)
  File "C:\Users\devpc\AppData\Roaming\Python\Python311\site-packages\starlette\middleware\errors.py", line 186, in __call__
    raise exc
  File "C:\Users\devpc\AppData\Roaming\Python\Python311\site-packages\starlette\middleware\errors.py", line 164, in __call__
    await self.app(scope, receive, _send)
  File "C:\Users\devpc\AppData\Roaming\Python\Python311\site-packages\starlette\middleware\exceptions.py", line 62, in __call__
    await wrap_app_handling_exceptions(self.app, conn)(scope, receive, send)
  File "C:\Users\devpc\AppData\Roaming\Python\Python311\site-packages\starlette\_exception_handler.py", line 64, in wrapped_app
    raise exc
  File "C:\Users\devpc\AppData\Roaming\Python\Python311\site-packages\starlette\_exception_handler.py", line 53, in wrapped_app
    await app(scope, receive, sender)
  File "C:\Users\devpc\AppData\Roaming\Python\Python311\site-packages\starlette\routing.py", line 758, in __call__
    await self.middleware_stack(scope, receive, send)
  File "C:\Users\devpc\AppData\Roaming\Python\Python311\site-packages\starlette\routing.py", line 778, in app
    await route.handle(scope, receive, send)
  File "C:\Users\devpc\AppData\Roaming\Python\Python311\site-packages\starlette\routing.py", line 299, in handle
    await self.app(scope, receive, send)
  File "C:\Users\devpc\AppData\Roaming\Python\Python311\site-packages\starlette\routing.py", line 79, in app
    await wrap_app_handling_exceptions(app, request)(scope, receive, send)
  File "C:\Users\devpc\AppData\Roaming\Python\Python311\site-packages\starlette\_exception_handler.py", line 64, in wrapped_app
    raise exc
  File "C:\Users\devpc\AppData\Roaming\Python\Python311\site-packages\starlette\_exception_handler.py", line 53, in wrapped_app
    await app(scope, receive, sender)
  File "C:\Users\devpc\AppData\Roaming\Python\Python311\site-packages\starlette\routing.py", line 74, in app
    response = await func(request)
               ^^^^^^^^^^^^^^^^^^^
  File "C:\Users\devpc\AppData\Roaming\Python\Python311\site-packages\fastapi\routing.py", line 278, in app
    raw_response = await run_endpoint_function(
                   ^^^^^^^^^^^^^^^^^^^^^^^^^^^^
  File "C:\Users\devpc\AppData\Roaming\Python\Python311\site-packages\fastapi\routing.py", line 193, in run_endpoint_function
    return await run_in_threadpool(dependant.call, **values)
           ^^^^^^^^^^^^^^^^^^^^^^^^^^^^^^^^^^^^^^^^^^^^^^^^^
  File "C:\Users\devpc\AppData\Roaming\Python\Python311\site-packages\starlette\concurrency.py", line 42, in run_in_threadpool
    return await anyio.to_thread.run_sync(func, *args)
           ^^^^^^^^^^^^^^^^^^^^^^^^^^^^^^^^^^^^^^^^^^^
  File "C:\Users\devpc\AppData\Roaming\Python\Python311\site-packages\anyio\to_thread.py", line 56, in run_sync
    return await get_async_backend().run_sync_in_worker_thread(
           ^^^^^^^^^^^^^^^^^^^^^^^^^^^^^^^^^^^^^^^^^^^^^^^^^^^^
  File "C:\Users\devpc\AppData\Roaming\Python\Python311\site-packages\anyio\_backends\_asyncio.py", line 2470, in run_sync_in_worker_thread
    return await future
           ^^^^^^^^^^^^
  File "C:\Users\devpc\AppData\Roaming\Python\Python311\site-packages\anyio\_backends\_asyncio.py", line 967, in run
    result = context.run(func, *args)
             ^^^^^^^^^^^^^^^^^^^^^^^^
  File "E:\tech\trm-os-branches\trm_api\api\v1\endpoints\user.py", line 23, in create_user
    db_user = repo.get_user_by_email(email=user_in.email)
              ^^^^^^^^^^^^^^^^^^^^^^^^^^^^^^^^^^^^^^^^^^^
  File "E:\tech\trm-os-branches\trm_api\repositories\user_repository.py", line 43, in get_user_by_email
    def get_user_by_username(self, username: str) -> Optional[GraphUser]:
                   ^^^^^^^^^^^^^^^
  File "C:\Users\devpc\AppData\Roaming\Python\Python311\site-packages\neomodel\util.py", line 27, in __get__
    return self.getter(type)
           ^^^^^^^^^^^^^^^^^
  File "C:\Users\devpc\AppData\Roaming\Python\Python311\site-packages\neomodel\sync_\core.py", line 1150, in nodes
    return NodeSet(cls)
           ^^^^^^^^^^^^
  File "C:\Users\devpc\AppData\Roaming\Python\Python311\site-packages\neomodel\sync_\match.py", line 891, in __init__
    install_traversals(self.source_class, self)
  File "C:\Users\devpc\AppData\Roaming\Python\Python311\site-packages\neomodel\sync_\match.py", line 210, in install_traversals
    rel.lookup_node_class()
  File "C:\Users\devpc\AppData\Roaming\Python\Python311\site-packages\neomodel\sync_\relationship_manager.py", line 493, in lookup_node_class
    self.definition["node_class"] = getattr(sys.modules[module], name)
                                    ^^^^^^^^^^^^^^^^^^^^^^^^^^^^^^^^^^
AttributeError: module 'trm_api.graph_models.skill' has no attribute 'Skill'
2025-06-12 15:31:35,624 - uvicorn.error - INFO - Application startup complete.
2025-06-12 15:31:35,624 - uvicorn.error - ERROR - [Errno 10048] error while attempting to bind on address ('0.0.0.0', 8000): only one usage of each socket address (protocol/network address/port) is normally permitted
2025-06-12 15:31:35,624 - uvicorn.error - INFO - Waiting for application shutdown.
2025-06-12 15:31:35,624 - uvicorn.error - INFO - Application shutdown complete.
2025-06-12 15:33:16,822 - uvicorn.access - INFO - 127.0.0.1:58105 - "GET /api/v1/docs HTTP/1.1" 404
2025-06-12 15:33:18,870 - uvicorn.access - INFO - 127.0.0.1:58119 - "POST /api/v1/users/ HTTP/1.1" 500
2025-06-12 15:33:18,871 - uvicorn.error - ERROR - Exception in ASGI application
Traceback (most recent call last):
  File "C:\Users\devpc\AppData\Roaming\Python\Python311\site-packages\uvicorn\protocols\http\httptools_impl.py", line 411, in run_asgi
    result = await app(  # type: ignore[func-returns-value]
             ^^^^^^^^^^^^^^^^^^^^^^^^^^^^^^^^^^^^^^^^^^^^^^
  File "C:\Users\devpc\AppData\Roaming\Python\Python311\site-packages\uvicorn\middleware\proxy_headers.py", line 69, in __call__
    return await self.app(scope, receive, send)
           ^^^^^^^^^^^^^^^^^^^^^^^^^^^^^^^^^^^^
  File "C:\Users\devpc\AppData\Roaming\Python\Python311\site-packages\fastapi\applications.py", line 1054, in __call__
    await super().__call__(scope, receive, send)
  File "C:\Users\devpc\AppData\Roaming\Python\Python311\site-packages\starlette\applications.py", line 123, in __call__
    await self.middleware_stack(scope, receive, send)
  File "C:\Users\devpc\AppData\Roaming\Python\Python311\site-packages\starlette\middleware\errors.py", line 186, in __call__
    raise exc
  File "C:\Users\devpc\AppData\Roaming\Python\Python311\site-packages\starlette\middleware\errors.py", line 164, in __call__
    await self.app(scope, receive, _send)
  File "C:\Users\devpc\AppData\Roaming\Python\Python311\site-packages\starlette\middleware\exceptions.py", line 62, in __call__
    await wrap_app_handling_exceptions(self.app, conn)(scope, receive, send)
  File "C:\Users\devpc\AppData\Roaming\Python\Python311\site-packages\starlette\_exception_handler.py", line 64, in wrapped_app
    raise exc
  File "C:\Users\devpc\AppData\Roaming\Python\Python311\site-packages\starlette\_exception_handler.py", line 53, in wrapped_app
    await app(scope, receive, sender)
  File "C:\Users\devpc\AppData\Roaming\Python\Python311\site-packages\starlette\routing.py", line 758, in __call__
    await self.middleware_stack(scope, receive, send)
  File "C:\Users\devpc\AppData\Roaming\Python\Python311\site-packages\starlette\routing.py", line 778, in app
    await route.handle(scope, receive, send)
  File "C:\Users\devpc\AppData\Roaming\Python\Python311\site-packages\starlette\routing.py", line 299, in handle
    await self.app(scope, receive, send)
  File "C:\Users\devpc\AppData\Roaming\Python\Python311\site-packages\starlette\routing.py", line 79, in app
    await wrap_app_handling_exceptions(app, request)(scope, receive, send)
  File "C:\Users\devpc\AppData\Roaming\Python\Python311\site-packages\starlette\_exception_handler.py", line 64, in wrapped_app
    raise exc
  File "C:\Users\devpc\AppData\Roaming\Python\Python311\site-packages\starlette\_exception_handler.py", line 53, in wrapped_app
    await app(scope, receive, sender)
  File "C:\Users\devpc\AppData\Roaming\Python\Python311\site-packages\starlette\routing.py", line 74, in app
    response = await func(request)
               ^^^^^^^^^^^^^^^^^^^
  File "C:\Users\devpc\AppData\Roaming\Python\Python311\site-packages\fastapi\routing.py", line 278, in app
    raw_response = await run_endpoint_function(
                   ^^^^^^^^^^^^^^^^^^^^^^^^^^^^
  File "C:\Users\devpc\AppData\Roaming\Python\Python311\site-packages\fastapi\routing.py", line 193, in run_endpoint_function
    return await run_in_threadpool(dependant.call, **values)
           ^^^^^^^^^^^^^^^^^^^^^^^^^^^^^^^^^^^^^^^^^^^^^^^^^
  File "C:\Users\devpc\AppData\Roaming\Python\Python311\site-packages\starlette\concurrency.py", line 42, in run_in_threadpool
    return await anyio.to_thread.run_sync(func, *args)
           ^^^^^^^^^^^^^^^^^^^^^^^^^^^^^^^^^^^^^^^^^^^
  File "C:\Users\devpc\AppData\Roaming\Python\Python311\site-packages\anyio\to_thread.py", line 56, in run_sync
    return await get_async_backend().run_sync_in_worker_thread(
           ^^^^^^^^^^^^^^^^^^^^^^^^^^^^^^^^^^^^^^^^^^^^^^^^^^^^
  File "C:\Users\devpc\AppData\Roaming\Python\Python311\site-packages\anyio\_backends\_asyncio.py", line 2470, in run_sync_in_worker_thread
    return await future
           ^^^^^^^^^^^^
  File "C:\Users\devpc\AppData\Roaming\Python\Python311\site-packages\anyio\_backends\_asyncio.py", line 967, in run
    result = context.run(func, *args)
             ^^^^^^^^^^^^^^^^^^^^^^^^
  File "E:\tech\trm-os-branches\trm_api\api\v1\endpoints\user.py", line 23, in create_user
    db_user = repo.get_user_by_email(email=user_in.email)
              ^^^^^^^^^^^^^^^^^^^^^^^^^^^^^^^^^^^^^^^^^^^
  File "E:\tech\trm-os-branches\trm_api\repositories\user_repository.py", line 43, in get_user_by_email
    def get_user_by_username(self, username: str) -> Optional[GraphUser]:
                   ^^^^^^^^^^^^^^^
  File "C:\Users\devpc\AppData\Roaming\Python\Python311\site-packages\neomodel\util.py", line 27, in __get__
    return self.getter(type)
           ^^^^^^^^^^^^^^^^^
  File "C:\Users\devpc\AppData\Roaming\Python\Python311\site-packages\neomodel\sync_\core.py", line 1150, in nodes
    return NodeSet(cls)
           ^^^^^^^^^^^^
  File "C:\Users\devpc\AppData\Roaming\Python\Python311\site-packages\neomodel\sync_\match.py", line 891, in __init__
    install_traversals(self.source_class, self)
  File "C:\Users\devpc\AppData\Roaming\Python\Python311\site-packages\neomodel\sync_\match.py", line 210, in install_traversals
    rel.lookup_node_class()
  File "C:\Users\devpc\AppData\Roaming\Python\Python311\site-packages\neomodel\sync_\relationship_manager.py", line 493, in lookup_node_class
    self.definition["node_class"] = getattr(sys.modules[module], name)
                                    ^^^^^^^^^^^^^^^^^^^^^^^^^^^^^^^^^^
AttributeError: module 'trm_api.graph_models.skill' has no attribute 'Skill'
2025-06-12 15:34:41,270 - uvicorn.access - INFO - 127.0.0.1:58378 - "GET /api/v1/docs HTTP/1.1" 404
2025-06-12 15:34:43,327 - uvicorn.access - INFO - 127.0.0.1:58385 - "POST /api/v1/users/ HTTP/1.1" 500
2025-06-12 15:34:43,327 - uvicorn.error - ERROR - Exception in ASGI application
Traceback (most recent call last):
  File "C:\Users\devpc\AppData\Roaming\Python\Python311\site-packages\uvicorn\protocols\http\httptools_impl.py", line 411, in run_asgi
    result = await app(  # type: ignore[func-returns-value]
             ^^^^^^^^^^^^^^^^^^^^^^^^^^^^^^^^^^^^^^^^^^^^^^
  File "C:\Users\devpc\AppData\Roaming\Python\Python311\site-packages\uvicorn\middleware\proxy_headers.py", line 69, in __call__
    return await self.app(scope, receive, send)
           ^^^^^^^^^^^^^^^^^^^^^^^^^^^^^^^^^^^^
  File "C:\Users\devpc\AppData\Roaming\Python\Python311\site-packages\fastapi\applications.py", line 1054, in __call__
    await super().__call__(scope, receive, send)
  File "C:\Users\devpc\AppData\Roaming\Python\Python311\site-packages\starlette\applications.py", line 123, in __call__
    await self.middleware_stack(scope, receive, send)
  File "C:\Users\devpc\AppData\Roaming\Python\Python311\site-packages\starlette\middleware\errors.py", line 186, in __call__
    raise exc
  File "C:\Users\devpc\AppData\Roaming\Python\Python311\site-packages\starlette\middleware\errors.py", line 164, in __call__
    await self.app(scope, receive, _send)
  File "C:\Users\devpc\AppData\Roaming\Python\Python311\site-packages\starlette\middleware\exceptions.py", line 62, in __call__
    await wrap_app_handling_exceptions(self.app, conn)(scope, receive, send)
  File "C:\Users\devpc\AppData\Roaming\Python\Python311\site-packages\starlette\_exception_handler.py", line 64, in wrapped_app
    raise exc
  File "C:\Users\devpc\AppData\Roaming\Python\Python311\site-packages\starlette\_exception_handler.py", line 53, in wrapped_app
    await app(scope, receive, sender)
  File "C:\Users\devpc\AppData\Roaming\Python\Python311\site-packages\starlette\routing.py", line 758, in __call__
    await self.middleware_stack(scope, receive, send)
  File "C:\Users\devpc\AppData\Roaming\Python\Python311\site-packages\starlette\routing.py", line 778, in app
    await route.handle(scope, receive, send)
  File "C:\Users\devpc\AppData\Roaming\Python\Python311\site-packages\starlette\routing.py", line 299, in handle
    await self.app(scope, receive, send)
  File "C:\Users\devpc\AppData\Roaming\Python\Python311\site-packages\starlette\routing.py", line 79, in app
    await wrap_app_handling_exceptions(app, request)(scope, receive, send)
  File "C:\Users\devpc\AppData\Roaming\Python\Python311\site-packages\starlette\_exception_handler.py", line 64, in wrapped_app
    raise exc
  File "C:\Users\devpc\AppData\Roaming\Python\Python311\site-packages\starlette\_exception_handler.py", line 53, in wrapped_app
    await app(scope, receive, sender)
  File "C:\Users\devpc\AppData\Roaming\Python\Python311\site-packages\starlette\routing.py", line 74, in app
    response = await func(request)
               ^^^^^^^^^^^^^^^^^^^
  File "C:\Users\devpc\AppData\Roaming\Python\Python311\site-packages\fastapi\routing.py", line 278, in app
    raw_response = await run_endpoint_function(
                   ^^^^^^^^^^^^^^^^^^^^^^^^^^^^
  File "C:\Users\devpc\AppData\Roaming\Python\Python311\site-packages\fastapi\routing.py", line 193, in run_endpoint_function
    return await run_in_threadpool(dependant.call, **values)
           ^^^^^^^^^^^^^^^^^^^^^^^^^^^^^^^^^^^^^^^^^^^^^^^^^
  File "C:\Users\devpc\AppData\Roaming\Python\Python311\site-packages\starlette\concurrency.py", line 42, in run_in_threadpool
    return await anyio.to_thread.run_sync(func, *args)
           ^^^^^^^^^^^^^^^^^^^^^^^^^^^^^^^^^^^^^^^^^^^
  File "C:\Users\devpc\AppData\Roaming\Python\Python311\site-packages\anyio\to_thread.py", line 56, in run_sync
    return await get_async_backend().run_sync_in_worker_thread(
           ^^^^^^^^^^^^^^^^^^^^^^^^^^^^^^^^^^^^^^^^^^^^^^^^^^^^
  File "C:\Users\devpc\AppData\Roaming\Python\Python311\site-packages\anyio\_backends\_asyncio.py", line 2470, in run_sync_in_worker_thread
    return await future
           ^^^^^^^^^^^^
  File "C:\Users\devpc\AppData\Roaming\Python\Python311\site-packages\anyio\_backends\_asyncio.py", line 967, in run
    result = context.run(func, *args)
             ^^^^^^^^^^^^^^^^^^^^^^^^
  File "E:\tech\trm-os-branches\trm_api\api\v1\endpoints\user.py", line 23, in create_user
    db_user = repo.get_user_by_email(email=user_in.email)
              ^^^^^^^^^^^^^^^^^^^^^^^^^^^^^^^^^^^^^^^^^^^
  File "E:\tech\trm-os-branches\trm_api\repositories\user_repository.py", line 43, in get_user_by_email
    def get_user_by_username(self, username: str) -> Optional[GraphUser]:
                   ^^^^^^^^^^^^^^^
  File "C:\Users\devpc\AppData\Roaming\Python\Python311\site-packages\neomodel\util.py", line 27, in __get__
    return self.getter(type)
           ^^^^^^^^^^^^^^^^^
  File "C:\Users\devpc\AppData\Roaming\Python\Python311\site-packages\neomodel\sync_\core.py", line 1150, in nodes
    return NodeSet(cls)
           ^^^^^^^^^^^^
  File "C:\Users\devpc\AppData\Roaming\Python\Python311\site-packages\neomodel\sync_\match.py", line 891, in __init__
    install_traversals(self.source_class, self)
  File "C:\Users\devpc\AppData\Roaming\Python\Python311\site-packages\neomodel\sync_\match.py", line 210, in install_traversals
    rel.lookup_node_class()
  File "C:\Users\devpc\AppData\Roaming\Python\Python311\site-packages\neomodel\sync_\relationship_manager.py", line 493, in lookup_node_class
    self.definition["node_class"] = getattr(sys.modules[module], name)
                                    ^^^^^^^^^^^^^^^^^^^^^^^^^^^^^^^^^^
AttributeError: module 'trm_api.graph_models.skill' has no attribute 'Skill'
2025-06-12 15:35:27,223 - uvicorn.access - INFO - 127.0.0.1:58496 - "POST /api/v1/users/ HTTP/1.1" 500
2025-06-12 15:35:27,223 - uvicorn.error - ERROR - Exception in ASGI application
Traceback (most recent call last):
  File "C:\Users\devpc\AppData\Roaming\Python\Python311\site-packages\uvicorn\protocols\http\httptools_impl.py", line 411, in run_asgi
    result = await app(  # type: ignore[func-returns-value]
             ^^^^^^^^^^^^^^^^^^^^^^^^^^^^^^^^^^^^^^^^^^^^^^
  File "C:\Users\devpc\AppData\Roaming\Python\Python311\site-packages\uvicorn\middleware\proxy_headers.py", line 69, in __call__
    return await self.app(scope, receive, send)
           ^^^^^^^^^^^^^^^^^^^^^^^^^^^^^^^^^^^^
  File "C:\Users\devpc\AppData\Roaming\Python\Python311\site-packages\fastapi\applications.py", line 1054, in __call__
    await super().__call__(scope, receive, send)
  File "C:\Users\devpc\AppData\Roaming\Python\Python311\site-packages\starlette\applications.py", line 123, in __call__
    await self.middleware_stack(scope, receive, send)
  File "C:\Users\devpc\AppData\Roaming\Python\Python311\site-packages\starlette\middleware\errors.py", line 186, in __call__
    raise exc
  File "C:\Users\devpc\AppData\Roaming\Python\Python311\site-packages\starlette\middleware\errors.py", line 164, in __call__
    await self.app(scope, receive, _send)
  File "C:\Users\devpc\AppData\Roaming\Python\Python311\site-packages\starlette\middleware\exceptions.py", line 62, in __call__
    await wrap_app_handling_exceptions(self.app, conn)(scope, receive, send)
  File "C:\Users\devpc\AppData\Roaming\Python\Python311\site-packages\starlette\_exception_handler.py", line 64, in wrapped_app
    raise exc
  File "C:\Users\devpc\AppData\Roaming\Python\Python311\site-packages\starlette\_exception_handler.py", line 53, in wrapped_app
    await app(scope, receive, sender)
  File "C:\Users\devpc\AppData\Roaming\Python\Python311\site-packages\starlette\routing.py", line 758, in __call__
    await self.middleware_stack(scope, receive, send)
  File "C:\Users\devpc\AppData\Roaming\Python\Python311\site-packages\starlette\routing.py", line 778, in app
    await route.handle(scope, receive, send)
  File "C:\Users\devpc\AppData\Roaming\Python\Python311\site-packages\starlette\routing.py", line 299, in handle
    await self.app(scope, receive, send)
  File "C:\Users\devpc\AppData\Roaming\Python\Python311\site-packages\starlette\routing.py", line 79, in app
    await wrap_app_handling_exceptions(app, request)(scope, receive, send)
  File "C:\Users\devpc\AppData\Roaming\Python\Python311\site-packages\starlette\_exception_handler.py", line 64, in wrapped_app
    raise exc
  File "C:\Users\devpc\AppData\Roaming\Python\Python311\site-packages\starlette\_exception_handler.py", line 53, in wrapped_app
    await app(scope, receive, sender)
  File "C:\Users\devpc\AppData\Roaming\Python\Python311\site-packages\starlette\routing.py", line 74, in app
    response = await func(request)
               ^^^^^^^^^^^^^^^^^^^
  File "C:\Users\devpc\AppData\Roaming\Python\Python311\site-packages\fastapi\routing.py", line 278, in app
    raw_response = await run_endpoint_function(
                   ^^^^^^^^^^^^^^^^^^^^^^^^^^^^
  File "C:\Users\devpc\AppData\Roaming\Python\Python311\site-packages\fastapi\routing.py", line 193, in run_endpoint_function
    return await run_in_threadpool(dependant.call, **values)
           ^^^^^^^^^^^^^^^^^^^^^^^^^^^^^^^^^^^^^^^^^^^^^^^^^
  File "C:\Users\devpc\AppData\Roaming\Python\Python311\site-packages\starlette\concurrency.py", line 42, in run_in_threadpool
    return await anyio.to_thread.run_sync(func, *args)
           ^^^^^^^^^^^^^^^^^^^^^^^^^^^^^^^^^^^^^^^^^^^
  File "C:\Users\devpc\AppData\Roaming\Python\Python311\site-packages\anyio\to_thread.py", line 56, in run_sync
    return await get_async_backend().run_sync_in_worker_thread(
           ^^^^^^^^^^^^^^^^^^^^^^^^^^^^^^^^^^^^^^^^^^^^^^^^^^^^
  File "C:\Users\devpc\AppData\Roaming\Python\Python311\site-packages\anyio\_backends\_asyncio.py", line 2470, in run_sync_in_worker_thread
    return await future
           ^^^^^^^^^^^^
  File "C:\Users\devpc\AppData\Roaming\Python\Python311\site-packages\anyio\_backends\_asyncio.py", line 967, in run
    result = context.run(func, *args)
             ^^^^^^^^^^^^^^^^^^^^^^^^
  File "E:\tech\trm-os-branches\trm_api\api\v1\endpoints\user.py", line 23, in create_user
    db_user = repo.get_user_by_email(email=user_in.email)
              ^^^^^^^^^^^^^^^^^^^^^^^^^^^^^^^^^^^^^^^^^^^
  File "E:\tech\trm-os-branches\trm_api\repositories\user_repository.py", line 43, in get_user_by_email
    def get_user_by_username(self, username: str) -> Optional[GraphUser]:
                   ^^^^^^^^^^^^^^^
  File "C:\Users\devpc\AppData\Roaming\Python\Python311\site-packages\neomodel\util.py", line 27, in __get__
    return self.getter(type)
           ^^^^^^^^^^^^^^^^^
  File "C:\Users\devpc\AppData\Roaming\Python\Python311\site-packages\neomodel\sync_\core.py", line 1150, in nodes
    return NodeSet(cls)
           ^^^^^^^^^^^^
  File "C:\Users\devpc\AppData\Roaming\Python\Python311\site-packages\neomodel\sync_\match.py", line 891, in __init__
    install_traversals(self.source_class, self)
  File "C:\Users\devpc\AppData\Roaming\Python\Python311\site-packages\neomodel\sync_\match.py", line 210, in install_traversals
    rel.lookup_node_class()
  File "C:\Users\devpc\AppData\Roaming\Python\Python311\site-packages\neomodel\sync_\relationship_manager.py", line 493, in lookup_node_class
    self.definition["node_class"] = getattr(sys.modules[module], name)
                                    ^^^^^^^^^^^^^^^^^^^^^^^^^^^^^^^^^^
AttributeError: module 'trm_api.graph_models.skill' has no attribute 'Skill'
2025-06-12 15:38:08,315 - uvicorn.error - INFO - Application startup complete.
2025-06-12 15:38:08,315 - uvicorn.error - INFO - Uvicorn running on http://0.0.0.0:8000 (Press CTRL+C to quit)
2025-06-12 15:39:26,608 - uvicorn.error - INFO - Shutting down
2025-06-12 15:39:26,718 - uvicorn.error - INFO - Waiting for application shutdown.
2025-06-12 15:39:26,719 - uvicorn.error - INFO - Application shutdown complete.
2025-06-12 15:39:26,719 - uvicorn.error - INFO - Finished server process [6876]
2025-06-12 15:47:55,433 - uvicorn.error - INFO - Application startup complete.
2025-06-12 15:47:55,433 - uvicorn.error - INFO - Uvicorn running on http://0.0.0.0:8000 (Press CTRL+C to quit)
2025-06-12 15:50:01,183 - uvicorn.error - INFO - Shutting down
2025-06-12 15:50:01,291 - uvicorn.error - INFO - Waiting for application shutdown.
2025-06-12 15:50:01,292 - uvicorn.error - INFO - Application shutdown complete.
2025-06-12 15:50:01,293 - uvicorn.error - INFO - Finished server process [29592]
2025-06-12 15:51:56,266 - uvicorn.error - INFO - Application startup complete.
2025-06-12 15:51:56,267 - uvicorn.error - INFO - Uvicorn running on http://0.0.0.0:8000 (Press CTRL+C to quit)
2025-06-12 15:53:05,262 - uvicorn.error - INFO - Shutting down
2025-06-12 15:53:05,372 - uvicorn.error - INFO - Waiting for application shutdown.
2025-06-12 15:53:05,373 - uvicorn.error - INFO - Application shutdown complete.
2025-06-12 15:53:05,373 - uvicorn.error - INFO - Finished server process [16756]
2025-06-12 15:53:39,319 - uvicorn.error - INFO - Application startup complete.
2025-06-12 15:53:39,320 - uvicorn.error - INFO - Uvicorn running on http://127.0.0.1:8000 (Press CTRL+C to quit)
2025-06-12 15:54:36,558 - uvicorn.access - INFO - 127.0.0.1:62448 - "GET /api/v1/docs HTTP/1.1" 404
2025-06-12 15:54:38,614 - uvicorn.access - INFO - 127.0.0.1:62455 - "POST /api/v1/users/ HTTP/1.1" 500
2025-06-12 15:54:38,615 - uvicorn.error - ERROR - Exception in ASGI application
Traceback (most recent call last):
  File "E:\tech\trm-os-branches\.venv\Lib\site-packages\uvicorn\protocols\http\httptools_impl.py", line 411, in run_asgi
    result = await app(  # type: ignore[func-returns-value]
             ^^^^^^^^^^^^^^^^^^^^^^^^^^^^^^^^^^^^^^^^^^^^^^
  File "E:\tech\trm-os-branches\.venv\Lib\site-packages\uvicorn\middleware\proxy_headers.py", line 69, in __call__
    return await self.app(scope, receive, send)
           ^^^^^^^^^^^^^^^^^^^^^^^^^^^^^^^^^^^^
  File "E:\tech\trm-os-branches\.venv\Lib\site-packages\fastapi\applications.py", line 1054, in __call__
    await super().__call__(scope, receive, send)
  File "E:\tech\trm-os-branches\.venv\Lib\site-packages\starlette\applications.py", line 123, in __call__
    await self.middleware_stack(scope, receive, send)
  File "E:\tech\trm-os-branches\.venv\Lib\site-packages\starlette\middleware\errors.py", line 186, in __call__
    raise exc
  File "E:\tech\trm-os-branches\.venv\Lib\site-packages\starlette\middleware\errors.py", line 164, in __call__
    await self.app(scope, receive, _send)
  File "E:\tech\trm-os-branches\.venv\Lib\site-packages\starlette\middleware\exceptions.py", line 62, in __call__
    await wrap_app_handling_exceptions(self.app, conn)(scope, receive, send)
  File "E:\tech\trm-os-branches\.venv\Lib\site-packages\starlette\_exception_handler.py", line 64, in wrapped_app
    raise exc
  File "E:\tech\trm-os-branches\.venv\Lib\site-packages\starlette\_exception_handler.py", line 53, in wrapped_app
    await app(scope, receive, sender)
  File "E:\tech\trm-os-branches\.venv\Lib\site-packages\starlette\routing.py", line 758, in __call__
    await self.middleware_stack(scope, receive, send)
  File "E:\tech\trm-os-branches\.venv\Lib\site-packages\starlette\routing.py", line 778, in app
    await route.handle(scope, receive, send)
  File "E:\tech\trm-os-branches\.venv\Lib\site-packages\starlette\routing.py", line 299, in handle
    await self.app(scope, receive, send)
  File "E:\tech\trm-os-branches\.venv\Lib\site-packages\starlette\routing.py", line 79, in app
    await wrap_app_handling_exceptions(app, request)(scope, receive, send)
  File "E:\tech\trm-os-branches\.venv\Lib\site-packages\starlette\_exception_handler.py", line 64, in wrapped_app
    raise exc
  File "E:\tech\trm-os-branches\.venv\Lib\site-packages\starlette\_exception_handler.py", line 53, in wrapped_app
    await app(scope, receive, sender)
  File "E:\tech\trm-os-branches\.venv\Lib\site-packages\starlette\routing.py", line 74, in app
    response = await func(request)
               ^^^^^^^^^^^^^^^^^^^
  File "E:\tech\trm-os-branches\.venv\Lib\site-packages\fastapi\routing.py", line 278, in app
    raw_response = await run_endpoint_function(
                   ^^^^^^^^^^^^^^^^^^^^^^^^^^^^
  File "E:\tech\trm-os-branches\.venv\Lib\site-packages\fastapi\routing.py", line 193, in run_endpoint_function
    return await run_in_threadpool(dependant.call, **values)
           ^^^^^^^^^^^^^^^^^^^^^^^^^^^^^^^^^^^^^^^^^^^^^^^^^
  File "E:\tech\trm-os-branches\.venv\Lib\site-packages\starlette\concurrency.py", line 42, in run_in_threadpool
    return await anyio.to_thread.run_sync(func, *args)
           ^^^^^^^^^^^^^^^^^^^^^^^^^^^^^^^^^^^^^^^^^^^
  File "E:\tech\trm-os-branches\.venv\Lib\site-packages\anyio\to_thread.py", line 56, in run_sync
    return await get_async_backend().run_sync_in_worker_thread(
           ^^^^^^^^^^^^^^^^^^^^^^^^^^^^^^^^^^^^^^^^^^^^^^^^^^^^
  File "E:\tech\trm-os-branches\.venv\Lib\site-packages\anyio\_backends\_asyncio.py", line 2470, in run_sync_in_worker_thread
    return await future
           ^^^^^^^^^^^^
  File "E:\tech\trm-os-branches\.venv\Lib\site-packages\anyio\_backends\_asyncio.py", line 967, in run
    result = context.run(func, *args)
             ^^^^^^^^^^^^^^^^^^^^^^^^
  File "E:\tech\trm-os-branches\trm_api\api\v1\endpoints\user.py", line 23, in create_user
    db_user = repo.get_user_by_email(email=user_in.email)
              ^^^^^^^^^^^^^^^^^^^^^^^^^^^^^^^^^^^^^^^^^^^
  File "E:\tech\trm-os-branches\trm_api\repositories\user_repository.py", line 57, in get_user_by_email
    return GraphUser.nodes.get(email=email)
           ^^^^^^^^^^^^^^^
  File "E:\tech\trm-os-branches\.venv\Lib\site-packages\neomodel\util.py", line 27, in __get__
    return self.getter(type)
           ^^^^^^^^^^^^^^^^^
  File "E:\tech\trm-os-branches\.venv\Lib\site-packages\neomodel\sync_\core.py", line 1150, in nodes
    return NodeSet(cls)
           ^^^^^^^^^^^^
  File "E:\tech\trm-os-branches\.venv\Lib\site-packages\neomodel\sync_\match.py", line 891, in __init__
    install_traversals(self.source_class, self)
  File "E:\tech\trm-os-branches\.venv\Lib\site-packages\neomodel\sync_\match.py", line 210, in install_traversals
    rel.lookup_node_class()
  File "E:\tech\trm-os-branches\.venv\Lib\site-packages\neomodel\sync_\relationship_manager.py", line 493, in lookup_node_class
    self.definition["node_class"] = getattr(sys.modules[module], name)
                                    ^^^^^^^^^^^^^^^^^^^^^^^^^^^^^^^^^^
AttributeError: module 'trm_api.graph_models.skill' has no attribute 'Skill'
2025-06-12 15:59:24,893 - uvicorn.error - INFO - Application startup complete.
2025-06-12 15:59:24,895 - uvicorn.error - INFO - Uvicorn running on http://127.0.0.1:8000 (Press CTRL+C to quit)
2025-06-12 16:03:22,657 - uvicorn.error - INFO - Shutting down
2025-06-12 16:03:22,767 - uvicorn.error - INFO - Waiting for application shutdown.
2025-06-12 16:03:22,768 - uvicorn.error - INFO - Application shutdown complete.
2025-06-12 16:03:22,768 - uvicorn.error - INFO - Finished server process [31204]
2025-06-12 16:10:16,622 - uvicorn.error - INFO - Application startup complete.
2025-06-12 16:10:16,623 - uvicorn.error - INFO - Uvicorn running on http://127.0.0.1:8000 (Press CTRL+C to quit)
2025-06-12 16:10:41,679 - uvicorn.access - INFO - 127.0.0.1:65404 - "GET /api/v1/docs HTTP/1.1" 404
2025-06-12 16:10:45,276 - uvicorn.access - INFO - 127.0.0.1:65413 - "POST /api/v1/users/ HTTP/1.1" 201
2025-06-12 16:10:47,455 - uvicorn.access - INFO - 127.0.0.1:65424 - "POST /api/v1/projects/ HTTP/1.1" 201
2025-06-12 16:10:49,778 - uvicorn.access - INFO - 127.0.0.1:65434 - "POST /api/v1/tasks/ HTTP/1.1" 500
2025-06-12 16:10:49,778 - uvicorn.error - ERROR - Exception in ASGI application
Traceback (most recent call last):
  File "E:\tech\trm-os-branches\.venv\Lib\site-packages\uvicorn\protocols\http\httptools_impl.py", line 411, in run_asgi
    result = await app(  # type: ignore[func-returns-value]
             ^^^^^^^^^^^^^^^^^^^^^^^^^^^^^^^^^^^^^^^^^^^^^^
  File "E:\tech\trm-os-branches\.venv\Lib\site-packages\uvicorn\middleware\proxy_headers.py", line 69, in __call__
    return await self.app(scope, receive, send)
           ^^^^^^^^^^^^^^^^^^^^^^^^^^^^^^^^^^^^
  File "E:\tech\trm-os-branches\.venv\Lib\site-packages\fastapi\applications.py", line 1054, in __call__
    await super().__call__(scope, receive, send)
  File "E:\tech\trm-os-branches\.venv\Lib\site-packages\starlette\applications.py", line 123, in __call__
    await self.middleware_stack(scope, receive, send)
  File "E:\tech\trm-os-branches\.venv\Lib\site-packages\starlette\middleware\errors.py", line 186, in __call__
    raise exc
  File "E:\tech\trm-os-branches\.venv\Lib\site-packages\starlette\middleware\errors.py", line 164, in __call__
    await self.app(scope, receive, _send)
  File "E:\tech\trm-os-branches\.venv\Lib\site-packages\starlette\middleware\exceptions.py", line 62, in __call__
    await wrap_app_handling_exceptions(self.app, conn)(scope, receive, send)
  File "E:\tech\trm-os-branches\.venv\Lib\site-packages\starlette\_exception_handler.py", line 64, in wrapped_app
    raise exc
  File "E:\tech\trm-os-branches\.venv\Lib\site-packages\starlette\_exception_handler.py", line 53, in wrapped_app
    await app(scope, receive, sender)
  File "E:\tech\trm-os-branches\.venv\Lib\site-packages\starlette\routing.py", line 758, in __call__
    await self.middleware_stack(scope, receive, send)
  File "E:\tech\trm-os-branches\.venv\Lib\site-packages\starlette\routing.py", line 778, in app
    await route.handle(scope, receive, send)
  File "E:\tech\trm-os-branches\.venv\Lib\site-packages\starlette\routing.py", line 299, in handle
    await self.app(scope, receive, send)
  File "E:\tech\trm-os-branches\.venv\Lib\site-packages\starlette\routing.py", line 79, in app
    await wrap_app_handling_exceptions(app, request)(scope, receive, send)
  File "E:\tech\trm-os-branches\.venv\Lib\site-packages\starlette\_exception_handler.py", line 64, in wrapped_app
    raise exc
  File "E:\tech\trm-os-branches\.venv\Lib\site-packages\starlette\_exception_handler.py", line 53, in wrapped_app
    await app(scope, receive, sender)
  File "E:\tech\trm-os-branches\.venv\Lib\site-packages\starlette\routing.py", line 74, in app
    response = await func(request)
               ^^^^^^^^^^^^^^^^^^^
  File "E:\tech\trm-os-branches\.venv\Lib\site-packages\fastapi\routing.py", line 278, in app
    raw_response = await run_endpoint_function(
                   ^^^^^^^^^^^^^^^^^^^^^^^^^^^^
  File "E:\tech\trm-os-branches\.venv\Lib\site-packages\fastapi\routing.py", line 193, in run_endpoint_function
    return await run_in_threadpool(dependant.call, **values)
           ^^^^^^^^^^^^^^^^^^^^^^^^^^^^^^^^^^^^^^^^^^^^^^^^^
  File "E:\tech\trm-os-branches\.venv\Lib\site-packages\starlette\concurrency.py", line 42, in run_in_threadpool
    return await anyio.to_thread.run_sync(func, *args)
           ^^^^^^^^^^^^^^^^^^^^^^^^^^^^^^^^^^^^^^^^^^^
  File "E:\tech\trm-os-branches\.venv\Lib\site-packages\anyio\to_thread.py", line 56, in run_sync
    return await get_async_backend().run_sync_in_worker_thread(
           ^^^^^^^^^^^^^^^^^^^^^^^^^^^^^^^^^^^^^^^^^^^^^^^^^^^^
  File "E:\tech\trm-os-branches\.venv\Lib\site-packages\anyio\_backends\_asyncio.py", line 2470, in run_sync_in_worker_thread
    return await future
           ^^^^^^^^^^^^
  File "E:\tech\trm-os-branches\.venv\Lib\site-packages\anyio\_backends\_asyncio.py", line 967, in run
    result = context.run(func, *args)
             ^^^^^^^^^^^^^^^^^^^^^^^^
  File "E:\tech\trm-os-branches\trm_api\api\v1\endpoints\task.py", line 36, in create_task
    created_task = repo.create_task(task_data=task_in)
                   ^^^^^^^^^^^^^^^^^^^^^^^^^^^^^^^^^^^
  File "E:\tech\trm-os-branches\.venv\Lib\site-packages\neomodel\sync_\core.py", line 962, in wrapper
    return func(*args, **kwargs)
           ^^^^^^^^^^^^^^^^^^^^^
  File "E:\tech\trm-os-branches\trm_api\repositories\task_repository.py", line 39, in create_task
    project.tasks.connect(new_task)
  File "E:\tech\trm-os-branches\.venv\Lib\site-packages\neomodel\sync_\relationship_manager.py", line 32, in checker
    return fn(self, *args, **kwargs)
           ^^^^^^^^^^^^^^^^^^^^^^^^^
  File "E:\tech\trm-os-branches\.venv\Lib\site-packages\neomodel\sync_\relationship_manager.py", line 106, in connect
    for prop, val in rel_model.deflate(tmp.__properties__).items():
                     ^^^^^^^^^^^^^^^^^^^^^^^^^^^^^^^^^^^^^
  File "E:\tech\trm-os-branches\.venv\Lib\site-packages\neomodel\sync_\property_manager.py", line 93, in deflate
    raise RequiredProperty(name, cls)
neomodel.exceptions.RequiredProperty: property 'relationshipId' on objects of class IsPartOfProjectRel
2025-06-12 16:10:52,045 - uvicorn.access - INFO - 127.0.0.1:65443 - "DELETE /api/v1/projects/0c401f83c6ab4a5ca4bd8f74585b4a2b HTTP/1.1" 204
2025-06-12 16:10:54,355 - uvicorn.access - INFO - 127.0.0.1:65451 - "DELETE /api/v1/users/b09361adf1e64bc0b4408d12bd4af34c HTTP/1.1" 204
2025-06-12 16:16:25,451 - uvicorn.access - INFO - 127.0.0.1:50168 - "GET /api/health HTTP/1.1" 404
2025-06-12 16:16:25,454 - uvicorn.access - INFO - 127.0.0.1:50166 - "GET /api/health HTTP/1.1" 404
2025-06-12 16:20:58,793 - uvicorn.access - INFO - 127.0.0.1:51069 - "GET /api/v1/docs HTTP/1.1" 404
2025-06-12 16:21:01,477 - uvicorn.access - INFO - 127.0.0.1:51078 - "POST /api/v1/users/ HTTP/1.1" 201
2025-06-12 16:21:03,657 - uvicorn.access - INFO - 127.0.0.1:51087 - "POST /api/v1/projects/ HTTP/1.1" 201
2025-06-12 16:21:05,969 - uvicorn.access - INFO - 127.0.0.1:51094 - "POST /api/v1/tasks/ HTTP/1.1" 500
2025-06-12 16:21:05,970 - uvicorn.error - ERROR - Exception in ASGI application
Traceback (most recent call last):
  File "E:\tech\trm-os-branches\.venv\Lib\site-packages\uvicorn\protocols\http\httptools_impl.py", line 411, in run_asgi
    result = await app(  # type: ignore[func-returns-value]
             ^^^^^^^^^^^^^^^^^^^^^^^^^^^^^^^^^^^^^^^^^^^^^^
  File "E:\tech\trm-os-branches\.venv\Lib\site-packages\uvicorn\middleware\proxy_headers.py", line 69, in __call__
    return await self.app(scope, receive, send)
           ^^^^^^^^^^^^^^^^^^^^^^^^^^^^^^^^^^^^
  File "E:\tech\trm-os-branches\.venv\Lib\site-packages\fastapi\applications.py", line 1054, in __call__
    await super().__call__(scope, receive, send)
  File "E:\tech\trm-os-branches\.venv\Lib\site-packages\starlette\applications.py", line 123, in __call__
    await self.middleware_stack(scope, receive, send)
  File "E:\tech\trm-os-branches\.venv\Lib\site-packages\starlette\middleware\errors.py", line 186, in __call__
    raise exc
  File "E:\tech\trm-os-branches\.venv\Lib\site-packages\starlette\middleware\errors.py", line 164, in __call__
    await self.app(scope, receive, _send)
  File "E:\tech\trm-os-branches\.venv\Lib\site-packages\starlette\middleware\exceptions.py", line 62, in __call__
    await wrap_app_handling_exceptions(self.app, conn)(scope, receive, send)
  File "E:\tech\trm-os-branches\.venv\Lib\site-packages\starlette\_exception_handler.py", line 64, in wrapped_app
    raise exc
  File "E:\tech\trm-os-branches\.venv\Lib\site-packages\starlette\_exception_handler.py", line 53, in wrapped_app
    await app(scope, receive, sender)
  File "E:\tech\trm-os-branches\.venv\Lib\site-packages\starlette\routing.py", line 758, in __call__
    await self.middleware_stack(scope, receive, send)
  File "E:\tech\trm-os-branches\.venv\Lib\site-packages\starlette\routing.py", line 778, in app
    await route.handle(scope, receive, send)
  File "E:\tech\trm-os-branches\.venv\Lib\site-packages\starlette\routing.py", line 299, in handle
    await self.app(scope, receive, send)
  File "E:\tech\trm-os-branches\.venv\Lib\site-packages\starlette\routing.py", line 79, in app
    await wrap_app_handling_exceptions(app, request)(scope, receive, send)
  File "E:\tech\trm-os-branches\.venv\Lib\site-packages\starlette\_exception_handler.py", line 64, in wrapped_app
    raise exc
  File "E:\tech\trm-os-branches\.venv\Lib\site-packages\starlette\_exception_handler.py", line 53, in wrapped_app
    await app(scope, receive, sender)
  File "E:\tech\trm-os-branches\.venv\Lib\site-packages\starlette\routing.py", line 74, in app
    response = await func(request)
               ^^^^^^^^^^^^^^^^^^^
  File "E:\tech\trm-os-branches\.venv\Lib\site-packages\fastapi\routing.py", line 278, in app
    raw_response = await run_endpoint_function(
                   ^^^^^^^^^^^^^^^^^^^^^^^^^^^^
  File "E:\tech\trm-os-branches\.venv\Lib\site-packages\fastapi\routing.py", line 193, in run_endpoint_function
    return await run_in_threadpool(dependant.call, **values)
           ^^^^^^^^^^^^^^^^^^^^^^^^^^^^^^^^^^^^^^^^^^^^^^^^^
  File "E:\tech\trm-os-branches\.venv\Lib\site-packages\starlette\concurrency.py", line 42, in run_in_threadpool
    return await anyio.to_thread.run_sync(func, *args)
           ^^^^^^^^^^^^^^^^^^^^^^^^^^^^^^^^^^^^^^^^^^^
  File "E:\tech\trm-os-branches\.venv\Lib\site-packages\anyio\to_thread.py", line 56, in run_sync
    return await get_async_backend().run_sync_in_worker_thread(
           ^^^^^^^^^^^^^^^^^^^^^^^^^^^^^^^^^^^^^^^^^^^^^^^^^^^^
  File "E:\tech\trm-os-branches\.venv\Lib\site-packages\anyio\_backends\_asyncio.py", line 2470, in run_sync_in_worker_thread
    return await future
           ^^^^^^^^^^^^
  File "E:\tech\trm-os-branches\.venv\Lib\site-packages\anyio\_backends\_asyncio.py", line 967, in run
    result = context.run(func, *args)
             ^^^^^^^^^^^^^^^^^^^^^^^^
  File "E:\tech\trm-os-branches\trm_api\api\v1\endpoints\task.py", line 36, in create_task
    created_task = repo.create_task(task_data=task_in)
                   ^^^^^^^^^^^^^^^^^^^^^^^^^^^^^^^^^^^
  File "E:\tech\trm-os-branches\.venv\Lib\site-packages\neomodel\sync_\core.py", line 962, in wrapper
    return func(*args, **kwargs)
           ^^^^^^^^^^^^^^^^^^^^^
  File "E:\tech\trm-os-branches\trm_api\repositories\task_repository.py", line 39, in create_task
    project.tasks.connect(new_task)
  File "E:\tech\trm-os-branches\.venv\Lib\site-packages\neomodel\sync_\relationship_manager.py", line 32, in checker
    return fn(self, *args, **kwargs)
           ^^^^^^^^^^^^^^^^^^^^^^^^^
  File "E:\tech\trm-os-branches\.venv\Lib\site-packages\neomodel\sync_\relationship_manager.py", line 106, in connect
    for prop, val in rel_model.deflate(tmp.__properties__).items():
                     ^^^^^^^^^^^^^^^^^^^^^^^^^^^^^^^^^^^^^
  File "E:\tech\trm-os-branches\.venv\Lib\site-packages\neomodel\sync_\property_manager.py", line 93, in deflate
    raise RequiredProperty(name, cls)
neomodel.exceptions.RequiredProperty: property 'relationshipId' on objects of class IsPartOfProjectRel
2025-06-12 16:21:08,261 - uvicorn.access - INFO - 127.0.0.1:51100 - "DELETE /api/v1/projects/21e10ef60fe94ce5aaaafb49149179b1 HTTP/1.1" 204
2025-06-12 16:21:10,566 - uvicorn.access - INFO - 127.0.0.1:51111 - "DELETE /api/v1/users/cacdf4acd1f6411ab2f6e469b100550b HTTP/1.1" 204
2025-06-12 16:22:00,477 - uvicorn.access - INFO - 127.0.0.1:51263 - "GET /api/v1/users HTTP/1.1" 307
2025-06-12 16:22:00,626 - uvicorn.access - INFO - 127.0.0.1:51263 - "GET /api/v1/users/ HTTP/1.1" 200
2025-06-12 16:23:34,885 - uvicorn.access - INFO - 127.0.0.1:51518 - "GET /api/v1/users HTTP/1.1" 307
2025-06-12 16:23:35,045 - uvicorn.access - INFO - 127.0.0.1:51518 - "GET /api/v1/users/ HTTP/1.1" 200
2025-06-12 16:23:37,660 - uvicorn.access - INFO - 127.0.0.1:51525 - "POST /api/v1/users/ HTTP/1.1" 201
2025-06-12 16:23:39,841 - uvicorn.access - INFO - 127.0.0.1:51531 - "POST /api/v1/projects/ HTTP/1.1" 201
2025-06-12 16:23:42,180 - uvicorn.access - INFO - 127.0.0.1:51542 - "POST /api/v1/tasks/ HTTP/1.1" 500
2025-06-12 16:23:42,180 - uvicorn.error - ERROR - Exception in ASGI application
Traceback (most recent call last):
  File "E:\tech\trm-os-branches\.venv\Lib\site-packages\uvicorn\protocols\http\httptools_impl.py", line 411, in run_asgi
    result = await app(  # type: ignore[func-returns-value]
             ^^^^^^^^^^^^^^^^^^^^^^^^^^^^^^^^^^^^^^^^^^^^^^
  File "E:\tech\trm-os-branches\.venv\Lib\site-packages\uvicorn\middleware\proxy_headers.py", line 69, in __call__
    return await self.app(scope, receive, send)
           ^^^^^^^^^^^^^^^^^^^^^^^^^^^^^^^^^^^^
  File "E:\tech\trm-os-branches\.venv\Lib\site-packages\fastapi\applications.py", line 1054, in __call__
    await super().__call__(scope, receive, send)
  File "E:\tech\trm-os-branches\.venv\Lib\site-packages\starlette\applications.py", line 123, in __call__
    await self.middleware_stack(scope, receive, send)
  File "E:\tech\trm-os-branches\.venv\Lib\site-packages\starlette\middleware\errors.py", line 186, in __call__
    raise exc
  File "E:\tech\trm-os-branches\.venv\Lib\site-packages\starlette\middleware\errors.py", line 164, in __call__
    await self.app(scope, receive, _send)
  File "E:\tech\trm-os-branches\.venv\Lib\site-packages\starlette\middleware\exceptions.py", line 62, in __call__
    await wrap_app_handling_exceptions(self.app, conn)(scope, receive, send)
  File "E:\tech\trm-os-branches\.venv\Lib\site-packages\starlette\_exception_handler.py", line 64, in wrapped_app
    raise exc
  File "E:\tech\trm-os-branches\.venv\Lib\site-packages\starlette\_exception_handler.py", line 53, in wrapped_app
    await app(scope, receive, sender)
  File "E:\tech\trm-os-branches\.venv\Lib\site-packages\starlette\routing.py", line 758, in __call__
    await self.middleware_stack(scope, receive, send)
  File "E:\tech\trm-os-branches\.venv\Lib\site-packages\starlette\routing.py", line 778, in app
    await route.handle(scope, receive, send)
  File "E:\tech\trm-os-branches\.venv\Lib\site-packages\starlette\routing.py", line 299, in handle
    await self.app(scope, receive, send)
  File "E:\tech\trm-os-branches\.venv\Lib\site-packages\starlette\routing.py", line 79, in app
    await wrap_app_handling_exceptions(app, request)(scope, receive, send)
  File "E:\tech\trm-os-branches\.venv\Lib\site-packages\starlette\_exception_handler.py", line 64, in wrapped_app
    raise exc
  File "E:\tech\trm-os-branches\.venv\Lib\site-packages\starlette\_exception_handler.py", line 53, in wrapped_app
    await app(scope, receive, sender)
  File "E:\tech\trm-os-branches\.venv\Lib\site-packages\starlette\routing.py", line 74, in app
    response = await func(request)
               ^^^^^^^^^^^^^^^^^^^
  File "E:\tech\trm-os-branches\.venv\Lib\site-packages\fastapi\routing.py", line 278, in app
    raw_response = await run_endpoint_function(
                   ^^^^^^^^^^^^^^^^^^^^^^^^^^^^
  File "E:\tech\trm-os-branches\.venv\Lib\site-packages\fastapi\routing.py", line 193, in run_endpoint_function
    return await run_in_threadpool(dependant.call, **values)
           ^^^^^^^^^^^^^^^^^^^^^^^^^^^^^^^^^^^^^^^^^^^^^^^^^
  File "E:\tech\trm-os-branches\.venv\Lib\site-packages\starlette\concurrency.py", line 42, in run_in_threadpool
    return await anyio.to_thread.run_sync(func, *args)
           ^^^^^^^^^^^^^^^^^^^^^^^^^^^^^^^^^^^^^^^^^^^
  File "E:\tech\trm-os-branches\.venv\Lib\site-packages\anyio\to_thread.py", line 56, in run_sync
    return await get_async_backend().run_sync_in_worker_thread(
           ^^^^^^^^^^^^^^^^^^^^^^^^^^^^^^^^^^^^^^^^^^^^^^^^^^^^
  File "E:\tech\trm-os-branches\.venv\Lib\site-packages\anyio\_backends\_asyncio.py", line 2470, in run_sync_in_worker_thread
    return await future
           ^^^^^^^^^^^^
  File "E:\tech\trm-os-branches\.venv\Lib\site-packages\anyio\_backends\_asyncio.py", line 967, in run
    result = context.run(func, *args)
             ^^^^^^^^^^^^^^^^^^^^^^^^
  File "E:\tech\trm-os-branches\trm_api\api\v1\endpoints\task.py", line 36, in create_task
    created_task = repo.create_task(task_data=task_in)
                   ^^^^^^^^^^^^^^^^^^^^^^^^^^^^^^^^^^^
  File "E:\tech\trm-os-branches\.venv\Lib\site-packages\neomodel\sync_\core.py", line 962, in wrapper
    return func(*args, **kwargs)
           ^^^^^^^^^^^^^^^^^^^^^
  File "E:\tech\trm-os-branches\trm_api\repositories\task_repository.py", line 39, in create_task
    project.tasks.connect(new_task)
  File "E:\tech\trm-os-branches\.venv\Lib\site-packages\neomodel\sync_\relationship_manager.py", line 32, in checker
    return fn(self, *args, **kwargs)
           ^^^^^^^^^^^^^^^^^^^^^^^^^
  File "E:\tech\trm-os-branches\.venv\Lib\site-packages\neomodel\sync_\relationship_manager.py", line 106, in connect
    for prop, val in rel_model.deflate(tmp.__properties__).items():
                     ^^^^^^^^^^^^^^^^^^^^^^^^^^^^^^^^^^^^^
  File "E:\tech\trm-os-branches\.venv\Lib\site-packages\neomodel\sync_\property_manager.py", line 93, in deflate
    raise RequiredProperty(name, cls)
neomodel.exceptions.RequiredProperty: property 'relationshipId' on objects of class IsPartOfProjectRel
2025-06-12 16:23:44,469 - uvicorn.access - INFO - 127.0.0.1:51551 - "DELETE /api/v1/projects/1668ebf9ceac4af7b3d7fee09936ea3d HTTP/1.1" 204
2025-06-12 16:23:46,760 - uvicorn.access - INFO - 127.0.0.1:51559 - "DELETE /api/v1/users/1df976e43cee40519ffa9d3e87b3673b HTTP/1.1" 204
2025-06-12 16:27:13,601 - uvicorn.access - INFO - 127.0.0.1:52152 - "GET /api/v1/users HTTP/1.1" 307
2025-06-12 16:27:13,760 - uvicorn.access - INFO - 127.0.0.1:52152 - "GET /api/v1/users/ HTTP/1.1" 200
2025-06-12 16:27:16,336 - uvicorn.access - INFO - 127.0.0.1:52161 - "POST /api/v1/users/ HTTP/1.1" 201
2025-06-12 16:27:18,529 - uvicorn.access - INFO - 127.0.0.1:52170 - "POST /api/v1/projects/ HTTP/1.1" 201
2025-06-12 16:27:20,825 - uvicorn.access - INFO - 127.0.0.1:52177 - "POST /api/v1/tasks/ HTTP/1.1" 500
2025-06-12 16:27:20,825 - uvicorn.error - ERROR - Exception in ASGI application
Traceback (most recent call last):
  File "E:\tech\trm-os-branches\.venv\Lib\site-packages\uvicorn\protocols\http\httptools_impl.py", line 411, in run_asgi
    result = await app(  # type: ignore[func-returns-value]
             ^^^^^^^^^^^^^^^^^^^^^^^^^^^^^^^^^^^^^^^^^^^^^^
  File "E:\tech\trm-os-branches\.venv\Lib\site-packages\uvicorn\middleware\proxy_headers.py", line 69, in __call__
    return await self.app(scope, receive, send)
           ^^^^^^^^^^^^^^^^^^^^^^^^^^^^^^^^^^^^
  File "E:\tech\trm-os-branches\.venv\Lib\site-packages\fastapi\applications.py", line 1054, in __call__
    await super().__call__(scope, receive, send)
  File "E:\tech\trm-os-branches\.venv\Lib\site-packages\starlette\applications.py", line 123, in __call__
    await self.middleware_stack(scope, receive, send)
  File "E:\tech\trm-os-branches\.venv\Lib\site-packages\starlette\middleware\errors.py", line 186, in __call__
    raise exc
  File "E:\tech\trm-os-branches\.venv\Lib\site-packages\starlette\middleware\errors.py", line 164, in __call__
    await self.app(scope, receive, _send)
  File "E:\tech\trm-os-branches\.venv\Lib\site-packages\starlette\middleware\exceptions.py", line 62, in __call__
    await wrap_app_handling_exceptions(self.app, conn)(scope, receive, send)
  File "E:\tech\trm-os-branches\.venv\Lib\site-packages\starlette\_exception_handler.py", line 64, in wrapped_app
    raise exc
  File "E:\tech\trm-os-branches\.venv\Lib\site-packages\starlette\_exception_handler.py", line 53, in wrapped_app
    await app(scope, receive, sender)
  File "E:\tech\trm-os-branches\.venv\Lib\site-packages\starlette\routing.py", line 758, in __call__
    await self.middleware_stack(scope, receive, send)
  File "E:\tech\trm-os-branches\.venv\Lib\site-packages\starlette\routing.py", line 778, in app
    await route.handle(scope, receive, send)
  File "E:\tech\trm-os-branches\.venv\Lib\site-packages\starlette\routing.py", line 299, in handle
    await self.app(scope, receive, send)
  File "E:\tech\trm-os-branches\.venv\Lib\site-packages\starlette\routing.py", line 79, in app
    await wrap_app_handling_exceptions(app, request)(scope, receive, send)
  File "E:\tech\trm-os-branches\.venv\Lib\site-packages\starlette\_exception_handler.py", line 64, in wrapped_app
    raise exc
  File "E:\tech\trm-os-branches\.venv\Lib\site-packages\starlette\_exception_handler.py", line 53, in wrapped_app
    await app(scope, receive, sender)
  File "E:\tech\trm-os-branches\.venv\Lib\site-packages\starlette\routing.py", line 74, in app
    response = await func(request)
               ^^^^^^^^^^^^^^^^^^^
  File "E:\tech\trm-os-branches\.venv\Lib\site-packages\fastapi\routing.py", line 278, in app
    raw_response = await run_endpoint_function(
                   ^^^^^^^^^^^^^^^^^^^^^^^^^^^^
  File "E:\tech\trm-os-branches\.venv\Lib\site-packages\fastapi\routing.py", line 193, in run_endpoint_function
    return await run_in_threadpool(dependant.call, **values)
           ^^^^^^^^^^^^^^^^^^^^^^^^^^^^^^^^^^^^^^^^^^^^^^^^^
  File "E:\tech\trm-os-branches\.venv\Lib\site-packages\starlette\concurrency.py", line 42, in run_in_threadpool
    return await anyio.to_thread.run_sync(func, *args)
           ^^^^^^^^^^^^^^^^^^^^^^^^^^^^^^^^^^^^^^^^^^^
  File "E:\tech\trm-os-branches\.venv\Lib\site-packages\anyio\to_thread.py", line 56, in run_sync
    return await get_async_backend().run_sync_in_worker_thread(
           ^^^^^^^^^^^^^^^^^^^^^^^^^^^^^^^^^^^^^^^^^^^^^^^^^^^^
  File "E:\tech\trm-os-branches\.venv\Lib\site-packages\anyio\_backends\_asyncio.py", line 2470, in run_sync_in_worker_thread
    return await future
           ^^^^^^^^^^^^
  File "E:\tech\trm-os-branches\.venv\Lib\site-packages\anyio\_backends\_asyncio.py", line 967, in run
    result = context.run(func, *args)
             ^^^^^^^^^^^^^^^^^^^^^^^^
  File "E:\tech\trm-os-branches\trm_api\api\v1\endpoints\task.py", line 36, in create_task
    created_task = repo.create_task(task_data=task_in)
                   ^^^^^^^^^^^^^^^^^^^^^^^^^^^^^^^^^^^
  File "E:\tech\trm-os-branches\.venv\Lib\site-packages\neomodel\sync_\core.py", line 962, in wrapper
    return func(*args, **kwargs)
           ^^^^^^^^^^^^^^^^^^^^^
  File "E:\tech\trm-os-branches\trm_api\repositories\task_repository.py", line 39, in create_task
    project.tasks.connect(new_task)
  File "E:\tech\trm-os-branches\.venv\Lib\site-packages\neomodel\sync_\relationship_manager.py", line 32, in checker
    return fn(self, *args, **kwargs)
           ^^^^^^^^^^^^^^^^^^^^^^^^^
  File "E:\tech\trm-os-branches\.venv\Lib\site-packages\neomodel\sync_\relationship_manager.py", line 106, in connect
    for prop, val in rel_model.deflate(tmp.__properties__).items():
                     ^^^^^^^^^^^^^^^^^^^^^^^^^^^^^^^^^^^^^
  File "E:\tech\trm-os-branches\.venv\Lib\site-packages\neomodel\sync_\property_manager.py", line 93, in deflate
    raise RequiredProperty(name, cls)
neomodel.exceptions.RequiredProperty: property 'relationshipId' on objects of class IsPartOfProjectRel
2025-06-12 16:27:23,130 - uvicorn.access - INFO - 127.0.0.1:52183 - "DELETE /api/v1/projects/e4abecbc622c4416a6848b4d29018e30 HTTP/1.1" 204
2025-06-12 16:27:25,438 - uvicorn.access - INFO - 127.0.0.1:52191 - "DELETE /api/v1/users/8ea2ed04206848fca213236f2e321c2f HTTP/1.1" 204
2025-06-12 16:27:31,580 - uvicorn.access - INFO - 127.0.0.1:52223 - "GET /api/v1/users HTTP/1.1" 307
2025-06-12 16:27:31,700 - uvicorn.access - INFO - 127.0.0.1:52223 - "GET /api/v1/users/ HTTP/1.1" 200
2025-06-12 16:27:34,295 - uvicorn.access - INFO - 127.0.0.1:52248 - "POST /api/v1/users/ HTTP/1.1" 201
2025-06-12 16:27:36,467 - uvicorn.access - INFO - 127.0.0.1:52258 - "POST /api/v1/projects/ HTTP/1.1" 201
2025-06-12 16:27:38,774 - uvicorn.access - INFO - 127.0.0.1:52265 - "POST /api/v1/tasks/ HTTP/1.1" 500
2025-06-12 16:27:38,774 - uvicorn.error - ERROR - Exception in ASGI application
Traceback (most recent call last):
  File "E:\tech\trm-os-branches\.venv\Lib\site-packages\uvicorn\protocols\http\httptools_impl.py", line 411, in run_asgi
    result = await app(  # type: ignore[func-returns-value]
             ^^^^^^^^^^^^^^^^^^^^^^^^^^^^^^^^^^^^^^^^^^^^^^
  File "E:\tech\trm-os-branches\.venv\Lib\site-packages\uvicorn\middleware\proxy_headers.py", line 69, in __call__
    return await self.app(scope, receive, send)
           ^^^^^^^^^^^^^^^^^^^^^^^^^^^^^^^^^^^^
  File "E:\tech\trm-os-branches\.venv\Lib\site-packages\fastapi\applications.py", line 1054, in __call__
    await super().__call__(scope, receive, send)
  File "E:\tech\trm-os-branches\.venv\Lib\site-packages\starlette\applications.py", line 123, in __call__
    await self.middleware_stack(scope, receive, send)
  File "E:\tech\trm-os-branches\.venv\Lib\site-packages\starlette\middleware\errors.py", line 186, in __call__
    raise exc
  File "E:\tech\trm-os-branches\.venv\Lib\site-packages\starlette\middleware\errors.py", line 164, in __call__
    await self.app(scope, receive, _send)
  File "E:\tech\trm-os-branches\.venv\Lib\site-packages\starlette\middleware\exceptions.py", line 62, in __call__
    await wrap_app_handling_exceptions(self.app, conn)(scope, receive, send)
  File "E:\tech\trm-os-branches\.venv\Lib\site-packages\starlette\_exception_handler.py", line 64, in wrapped_app
    raise exc
  File "E:\tech\trm-os-branches\.venv\Lib\site-packages\starlette\_exception_handler.py", line 53, in wrapped_app
    await app(scope, receive, sender)
  File "E:\tech\trm-os-branches\.venv\Lib\site-packages\starlette\routing.py", line 758, in __call__
    await self.middleware_stack(scope, receive, send)
  File "E:\tech\trm-os-branches\.venv\Lib\site-packages\starlette\routing.py", line 778, in app
    await route.handle(scope, receive, send)
  File "E:\tech\trm-os-branches\.venv\Lib\site-packages\starlette\routing.py", line 299, in handle
    await self.app(scope, receive, send)
  File "E:\tech\trm-os-branches\.venv\Lib\site-packages\starlette\routing.py", line 79, in app
    await wrap_app_handling_exceptions(app, request)(scope, receive, send)
  File "E:\tech\trm-os-branches\.venv\Lib\site-packages\starlette\_exception_handler.py", line 64, in wrapped_app
    raise exc
  File "E:\tech\trm-os-branches\.venv\Lib\site-packages\starlette\_exception_handler.py", line 53, in wrapped_app
    await app(scope, receive, sender)
  File "E:\tech\trm-os-branches\.venv\Lib\site-packages\starlette\routing.py", line 74, in app
    response = await func(request)
               ^^^^^^^^^^^^^^^^^^^
  File "E:\tech\trm-os-branches\.venv\Lib\site-packages\fastapi\routing.py", line 278, in app
    raw_response = await run_endpoint_function(
                   ^^^^^^^^^^^^^^^^^^^^^^^^^^^^
  File "E:\tech\trm-os-branches\.venv\Lib\site-packages\fastapi\routing.py", line 193, in run_endpoint_function
    return await run_in_threadpool(dependant.call, **values)
           ^^^^^^^^^^^^^^^^^^^^^^^^^^^^^^^^^^^^^^^^^^^^^^^^^
  File "E:\tech\trm-os-branches\.venv\Lib\site-packages\starlette\concurrency.py", line 42, in run_in_threadpool
    return await anyio.to_thread.run_sync(func, *args)
           ^^^^^^^^^^^^^^^^^^^^^^^^^^^^^^^^^^^^^^^^^^^
  File "E:\tech\trm-os-branches\.venv\Lib\site-packages\anyio\to_thread.py", line 56, in run_sync
    return await get_async_backend().run_sync_in_worker_thread(
           ^^^^^^^^^^^^^^^^^^^^^^^^^^^^^^^^^^^^^^^^^^^^^^^^^^^^
  File "E:\tech\trm-os-branches\.venv\Lib\site-packages\anyio\_backends\_asyncio.py", line 2470, in run_sync_in_worker_thread
    return await future
           ^^^^^^^^^^^^
  File "E:\tech\trm-os-branches\.venv\Lib\site-packages\anyio\_backends\_asyncio.py", line 967, in run
    result = context.run(func, *args)
             ^^^^^^^^^^^^^^^^^^^^^^^^
  File "E:\tech\trm-os-branches\trm_api\api\v1\endpoints\task.py", line 36, in create_task
    created_task = repo.create_task(task_data=task_in)
                   ^^^^^^^^^^^^^^^^^^^^^^^^^^^^^^^^^^^
  File "E:\tech\trm-os-branches\.venv\Lib\site-packages\neomodel\sync_\core.py", line 962, in wrapper
    return func(*args, **kwargs)
           ^^^^^^^^^^^^^^^^^^^^^
  File "E:\tech\trm-os-branches\trm_api\repositories\task_repository.py", line 39, in create_task
    project.tasks.connect(new_task)
  File "E:\tech\trm-os-branches\.venv\Lib\site-packages\neomodel\sync_\relationship_manager.py", line 32, in checker
    return fn(self, *args, **kwargs)
           ^^^^^^^^^^^^^^^^^^^^^^^^^
  File "E:\tech\trm-os-branches\.venv\Lib\site-packages\neomodel\sync_\relationship_manager.py", line 106, in connect
    for prop, val in rel_model.deflate(tmp.__properties__).items():
                     ^^^^^^^^^^^^^^^^^^^^^^^^^^^^^^^^^^^^^
  File "E:\tech\trm-os-branches\.venv\Lib\site-packages\neomodel\sync_\property_manager.py", line 93, in deflate
    raise RequiredProperty(name, cls)
neomodel.exceptions.RequiredProperty: property 'relationshipId' on objects of class IsPartOfProjectRel
2025-06-12 16:27:41,056 - uvicorn.access - INFO - 127.0.0.1:52271 - "DELETE /api/v1/projects/4e60ced530d842ba832bb80c07fc6cf5 HTTP/1.1" 204
2025-06-12 16:27:43,336 - uvicorn.access - INFO - 127.0.0.1:52280 - "DELETE /api/v1/users/0b3349b830684336b78e2044562f954c HTTP/1.1" 204
2025-06-12 16:28:11,283 - uvicorn.access - INFO - 127.0.0.1:52352 - "GET /api/v1/users HTTP/1.1" 307
2025-06-12 16:28:11,413 - uvicorn.access - INFO - 127.0.0.1:52352 - "GET /api/v1/users/ HTTP/1.1" 200
2025-06-12 16:28:14,030 - uvicorn.access - INFO - 127.0.0.1:52359 - "POST /api/v1/users/ HTTP/1.1" 201
2025-06-12 16:28:16,246 - uvicorn.access - INFO - 127.0.0.1:52368 - "POST /api/v1/projects/ HTTP/1.1" 201
2025-06-12 16:28:18,555 - uvicorn.access - INFO - 127.0.0.1:52375 - "POST /api/v1/tasks/ HTTP/1.1" 500
2025-06-12 16:28:18,556 - uvicorn.error - ERROR - Exception in ASGI application
Traceback (most recent call last):
  File "E:\tech\trm-os-branches\.venv\Lib\site-packages\uvicorn\protocols\http\httptools_impl.py", line 411, in run_asgi
    result = await app(  # type: ignore[func-returns-value]
             ^^^^^^^^^^^^^^^^^^^^^^^^^^^^^^^^^^^^^^^^^^^^^^
  File "E:\tech\trm-os-branches\.venv\Lib\site-packages\uvicorn\middleware\proxy_headers.py", line 69, in __call__
    return await self.app(scope, receive, send)
           ^^^^^^^^^^^^^^^^^^^^^^^^^^^^^^^^^^^^
  File "E:\tech\trm-os-branches\.venv\Lib\site-packages\fastapi\applications.py", line 1054, in __call__
    await super().__call__(scope, receive, send)
  File "E:\tech\trm-os-branches\.venv\Lib\site-packages\starlette\applications.py", line 123, in __call__
    await self.middleware_stack(scope, receive, send)
  File "E:\tech\trm-os-branches\.venv\Lib\site-packages\starlette\middleware\errors.py", line 186, in __call__
    raise exc
  File "E:\tech\trm-os-branches\.venv\Lib\site-packages\starlette\middleware\errors.py", line 164, in __call__
    await self.app(scope, receive, _send)
  File "E:\tech\trm-os-branches\.venv\Lib\site-packages\starlette\middleware\exceptions.py", line 62, in __call__
    await wrap_app_handling_exceptions(self.app, conn)(scope, receive, send)
  File "E:\tech\trm-os-branches\.venv\Lib\site-packages\starlette\_exception_handler.py", line 64, in wrapped_app
    raise exc
  File "E:\tech\trm-os-branches\.venv\Lib\site-packages\starlette\_exception_handler.py", line 53, in wrapped_app
    await app(scope, receive, sender)
  File "E:\tech\trm-os-branches\.venv\Lib\site-packages\starlette\routing.py", line 758, in __call__
    await self.middleware_stack(scope, receive, send)
  File "E:\tech\trm-os-branches\.venv\Lib\site-packages\starlette\routing.py", line 778, in app
    await route.handle(scope, receive, send)
  File "E:\tech\trm-os-branches\.venv\Lib\site-packages\starlette\routing.py", line 299, in handle
    await self.app(scope, receive, send)
  File "E:\tech\trm-os-branches\.venv\Lib\site-packages\starlette\routing.py", line 79, in app
    await wrap_app_handling_exceptions(app, request)(scope, receive, send)
  File "E:\tech\trm-os-branches\.venv\Lib\site-packages\starlette\_exception_handler.py", line 64, in wrapped_app
    raise exc
  File "E:\tech\trm-os-branches\.venv\Lib\site-packages\starlette\_exception_handler.py", line 53, in wrapped_app
    await app(scope, receive, sender)
  File "E:\tech\trm-os-branches\.venv\Lib\site-packages\starlette\routing.py", line 74, in app
    response = await func(request)
               ^^^^^^^^^^^^^^^^^^^
  File "E:\tech\trm-os-branches\.venv\Lib\site-packages\fastapi\routing.py", line 278, in app
    raw_response = await run_endpoint_function(
                   ^^^^^^^^^^^^^^^^^^^^^^^^^^^^
  File "E:\tech\trm-os-branches\.venv\Lib\site-packages\fastapi\routing.py", line 193, in run_endpoint_function
    return await run_in_threadpool(dependant.call, **values)
           ^^^^^^^^^^^^^^^^^^^^^^^^^^^^^^^^^^^^^^^^^^^^^^^^^
  File "E:\tech\trm-os-branches\.venv\Lib\site-packages\starlette\concurrency.py", line 42, in run_in_threadpool
    return await anyio.to_thread.run_sync(func, *args)
           ^^^^^^^^^^^^^^^^^^^^^^^^^^^^^^^^^^^^^^^^^^^
  File "E:\tech\trm-os-branches\.venv\Lib\site-packages\anyio\to_thread.py", line 56, in run_sync
    return await get_async_backend().run_sync_in_worker_thread(
           ^^^^^^^^^^^^^^^^^^^^^^^^^^^^^^^^^^^^^^^^^^^^^^^^^^^^
  File "E:\tech\trm-os-branches\.venv\Lib\site-packages\anyio\_backends\_asyncio.py", line 2470, in run_sync_in_worker_thread
    return await future
           ^^^^^^^^^^^^
  File "E:\tech\trm-os-branches\.venv\Lib\site-packages\anyio\_backends\_asyncio.py", line 967, in run
    result = context.run(func, *args)
             ^^^^^^^^^^^^^^^^^^^^^^^^
  File "E:\tech\trm-os-branches\trm_api\api\v1\endpoints\task.py", line 36, in create_task
    created_task = repo.create_task(task_data=task_in)
                   ^^^^^^^^^^^^^^^^^^^^^^^^^^^^^^^^^^^
  File "E:\tech\trm-os-branches\.venv\Lib\site-packages\neomodel\sync_\core.py", line 962, in wrapper
    return func(*args, **kwargs)
           ^^^^^^^^^^^^^^^^^^^^^
  File "E:\tech\trm-os-branches\trm_api\repositories\task_repository.py", line 39, in create_task
    project.tasks.connect(new_task)
  File "E:\tech\trm-os-branches\.venv\Lib\site-packages\neomodel\sync_\relationship_manager.py", line 32, in checker
    return fn(self, *args, **kwargs)
           ^^^^^^^^^^^^^^^^^^^^^^^^^
  File "E:\tech\trm-os-branches\.venv\Lib\site-packages\neomodel\sync_\relationship_manager.py", line 106, in connect
    for prop, val in rel_model.deflate(tmp.__properties__).items():
                     ^^^^^^^^^^^^^^^^^^^^^^^^^^^^^^^^^^^^^
  File "E:\tech\trm-os-branches\.venv\Lib\site-packages\neomodel\sync_\property_manager.py", line 93, in deflate
    raise RequiredProperty(name, cls)
neomodel.exceptions.RequiredProperty: property 'relationshipId' on objects of class IsPartOfProjectRel
2025-06-12 16:28:20,846 - uvicorn.access - INFO - 127.0.0.1:52383 - "DELETE /api/v1/projects/80fc91034d314131b30ec71f159b69c6 HTTP/1.1" 204
2025-06-12 16:36:16,799 - uvicorn.access - INFO - 127.0.0.1:53726 - "GET /api/v1/users HTTP/1.1" 307
2025-06-12 16:36:16,955 - uvicorn.access - INFO - 127.0.0.1:53726 - "GET /api/v1/users/ HTTP/1.1" 200
2025-06-12 16:37:10,129 - uvicorn.access - INFO - 127.0.0.1:53863 - "GET /api/v1/users HTTP/1.1" 307
2025-06-12 16:37:10,251 - uvicorn.access - INFO - 127.0.0.1:53863 - "GET /api/v1/users/ HTTP/1.1" 200
2025-06-12 16:37:12,299 - uvicorn.access - INFO - 127.0.0.1:53872 - "POST /api/v1/projects/ HTTP/1.1" 422
2025-06-12 16:37:37,589 - uvicorn.access - INFO - 127.0.0.1:53974 - "GET /api/v1/users HTTP/1.1" 307
2025-06-12 16:37:37,749 - uvicorn.access - INFO - 127.0.0.1:53974 - "GET /api/v1/users/ HTTP/1.1" 200
2025-06-12 16:37:39,803 - uvicorn.access - INFO - 127.0.0.1:53984 - "POST /api/v1/projects/ HTTP/1.1" 422
2025-06-12 16:40:18,193 - uvicorn.access - INFO - 127.0.0.1:54431 - "GET /api/v1/users HTTP/1.1" 307
2025-06-12 16:40:18,353 - uvicorn.access - INFO - 127.0.0.1:54431 - "GET /api/v1/users/ HTTP/1.1" 200
2025-06-12 16:40:20,536 - uvicorn.access - INFO - 127.0.0.1:54438 - "POST /api/v1/projects/ HTTP/1.1" 201
2025-06-12 16:40:56,697 - uvicorn.access - INFO - 127.0.0.1:54552 - "GET /api/v1/users HTTP/1.1" 307
2025-06-12 16:40:56,821 - uvicorn.access - INFO - 127.0.0.1:54552 - "GET /api/v1/users/ HTTP/1.1" 200
2025-06-12 16:40:58,983 - uvicorn.access - INFO - 127.0.0.1:54559 - "POST /api/v1/projects/ HTTP/1.1" 201
2025-06-12 16:45:05,917 - uvicorn.access - INFO - 127.0.0.1:55211 - "GET /api/v1/users HTTP/1.1" 307
2025-06-12 16:45:06,083 - uvicorn.access - INFO - 127.0.0.1:55211 - "GET /api/v1/users/ HTTP/1.1" 200
2025-06-12 16:45:08,263 - uvicorn.access - INFO - 127.0.0.1:55219 - "POST /api/v1/projects/ HTTP/1.1" 201
2025-06-12 16:45:10,297 - uvicorn.access - INFO - 127.0.0.1:55226 - "POST /api/v1/wins/ HTTP/1.1" 404
2025-06-12 16:45:12,612 - uvicorn.access - INFO - 127.0.0.1:55232 - "DELETE /api/v1/projects/2f7810ea1651479cadf2ad4927a3aa13 HTTP/1.1" 204
2025-06-12 16:48:15,457 - uvicorn.access - INFO - 127.0.0.1:55713 - "GET /api/v1/docs HTTP/1.1" 404
2025-06-12 16:48:56,253 - uvicorn.access - INFO - 127.0.0.1:55847 - "GET /api/v1/users HTTP/1.1" 307
2025-06-12 16:48:56,435 - uvicorn.access - INFO - 127.0.0.1:55847 - "GET /api/v1/users/ HTTP/1.1" 200
2025-06-12 16:49:09,170 - uvicorn.access - INFO - 127.0.0.1:55880 - "GET /api/v1/wins HTTP/1.1" 404
2025-06-12 17:15:27,459 - uvicorn.error - INFO - Application startup complete.
2025-06-12 17:15:27,461 - uvicorn.error - INFO - Application startup complete.
2025-06-12 17:15:27,471 - uvicorn.error - INFO - Application startup complete.
2025-06-12 17:15:27,471 - uvicorn.error - INFO - Application startup complete.
2025-06-12 17:16:01,749 - uvicorn.error - INFO - Application startup complete.
2025-06-12 17:17:36,079 - uvicorn.access - INFO - 127.0.0.1:61423 - "GET /api/v1/users HTTP/1.1" 307
2025-06-12 17:17:37,200 - uvicorn.access - INFO - 127.0.0.1:61423 - "GET /api/v1/users/ HTTP/1.1" 200
2025-06-12 17:17:39,381 - uvicorn.access - INFO - 127.0.0.1:61433 - "POST /api/v1/projects/ HTTP/1.1" 201
2025-06-12 17:17:42,311 - uvicorn.access - INFO - 127.0.0.1:61439 - "POST /api/v1/wins/ HTTP/1.1" 500
2025-06-12 17:17:42,311 - uvicorn.error - ERROR - Exception in ASGI application
Traceback (most recent call last):
  File "e:\tech\trm-os-branches\.venv\Lib\site-packages\uvicorn\protocols\http\httptools_impl.py", line 411, in run_asgi
    result = await app(  # type: ignore[func-returns-value]
             ^^^^^^^^^^^^^^^^^^^^^^^^^^^^^^^^^^^^^^^^^^^^^^
  File "e:\tech\trm-os-branches\.venv\Lib\site-packages\uvicorn\middleware\proxy_headers.py", line 69, in __call__
    return await self.app(scope, receive, send)
           ^^^^^^^^^^^^^^^^^^^^^^^^^^^^^^^^^^^^
  File "e:\tech\trm-os-branches\.venv\Lib\site-packages\fastapi\applications.py", line 1054, in __call__
    await super().__call__(scope, receive, send)
  File "e:\tech\trm-os-branches\.venv\Lib\site-packages\starlette\applications.py", line 123, in __call__
    await self.middleware_stack(scope, receive, send)
  File "e:\tech\trm-os-branches\.venv\Lib\site-packages\starlette\middleware\errors.py", line 186, in __call__
    raise exc
  File "e:\tech\trm-os-branches\.venv\Lib\site-packages\starlette\middleware\errors.py", line 164, in __call__
    await self.app(scope, receive, _send)
  File "e:\tech\trm-os-branches\.venv\Lib\site-packages\starlette\middleware\exceptions.py", line 62, in __call__
    await wrap_app_handling_exceptions(self.app, conn)(scope, receive, send)
  File "e:\tech\trm-os-branches\.venv\Lib\site-packages\starlette\_exception_handler.py", line 64, in wrapped_app
    raise exc
  File "e:\tech\trm-os-branches\.venv\Lib\site-packages\starlette\_exception_handler.py", line 53, in wrapped_app
    await app(scope, receive, sender)
  File "e:\tech\trm-os-branches\.venv\Lib\site-packages\starlette\routing.py", line 758, in __call__
    await self.middleware_stack(scope, receive, send)
  File "e:\tech\trm-os-branches\.venv\Lib\site-packages\starlette\routing.py", line 778, in app
    await route.handle(scope, receive, send)
  File "e:\tech\trm-os-branches\.venv\Lib\site-packages\starlette\routing.py", line 299, in handle
    await self.app(scope, receive, send)
  File "e:\tech\trm-os-branches\.venv\Lib\site-packages\starlette\routing.py", line 79, in app
    await wrap_app_handling_exceptions(app, request)(scope, receive, send)
  File "e:\tech\trm-os-branches\.venv\Lib\site-packages\starlette\_exception_handler.py", line 64, in wrapped_app
    raise exc
  File "e:\tech\trm-os-branches\.venv\Lib\site-packages\starlette\_exception_handler.py", line 53, in wrapped_app
    await app(scope, receive, sender)
  File "e:\tech\trm-os-branches\.venv\Lib\site-packages\starlette\routing.py", line 74, in app
    response = await func(request)
               ^^^^^^^^^^^^^^^^^^^
  File "e:\tech\trm-os-branches\.venv\Lib\site-packages\fastapi\routing.py", line 278, in app
    raw_response = await run_endpoint_function(
                   ^^^^^^^^^^^^^^^^^^^^^^^^^^^^
  File "e:\tech\trm-os-branches\.venv\Lib\site-packages\fastapi\routing.py", line 193, in run_endpoint_function
    return await run_in_threadpool(dependant.call, **values)
           ^^^^^^^^^^^^^^^^^^^^^^^^^^^^^^^^^^^^^^^^^^^^^^^^^
  File "e:\tech\trm-os-branches\.venv\Lib\site-packages\starlette\concurrency.py", line 42, in run_in_threadpool
    return await anyio.to_thread.run_sync(func, *args)
           ^^^^^^^^^^^^^^^^^^^^^^^^^^^^^^^^^^^^^^^^^^^
  File "e:\tech\trm-os-branches\.venv\Lib\site-packages\anyio\to_thread.py", line 56, in run_sync
    return await get_async_backend().run_sync_in_worker_thread(
           ^^^^^^^^^^^^^^^^^^^^^^^^^^^^^^^^^^^^^^^^^^^^^^^^^^^^
  File "e:\tech\trm-os-branches\.venv\Lib\site-packages\anyio\_backends\_asyncio.py", line 2470, in run_sync_in_worker_thread
    return await future
           ^^^^^^^^^^^^
  File "e:\tech\trm-os-branches\.venv\Lib\site-packages\anyio\_backends\_asyncio.py", line 967, in run
    result = context.run(func, *args)
             ^^^^^^^^^^^^^^^^^^^^^^^^
  File "E:\tech\trm-os-branches\trm_api\api\v1\endpoints\win.py", line 19, in create_win
    return service.create_win(win_create=win_in)
           ^^^^^^^^^^^^^^^^^^^^^^^^^^^^^^^^^^^^^
  File "E:\tech\trm-os-branches\trm_api\services\win_service.py", line 23, in create_win
    return Win(**result)
           ^^^^^^^^^^^^^
  File "e:\tech\trm-os-branches\.venv\Lib\site-packages\pydantic\main.py", line 253, in __init__
    validated_self = self.__pydantic_validator__.validate_python(data, self_instance=self)
                     ^^^^^^^^^^^^^^^^^^^^^^^^^^^^^^^^^^^^^^^^^^^^^^^^^^^^^^^^^^^^^^^^^^^^^
pydantic_core._pydantic_core.ValidationError: 1 validation error for Win
createdAt
  Input should be a valid datetime [type=datetime_type, input_value=neo4j.time.DateTime(2025,...421894000, tzinfo=<UTC>), input_type=DateTime]
    For further information visit https://errors.pydantic.dev/2.11/v/datetime_type
2025-06-12 17:17:44,613 - uvicorn.access - INFO - 127.0.0.1:61449 - "DELETE /api/v1/projects/80d60043e81241bda53c518ca34421ff HTTP/1.1" 204
2025-06-12 17:20:04,638 - uvicorn.access - INFO - 127.0.0.1:61797 - "POST /api/v1/wins/ HTTP/1.1" 500
2025-06-12 17:20:04,638 - uvicorn.error - ERROR - Exception in ASGI application
Traceback (most recent call last):
  File "e:\tech\trm-os-branches\.venv\Lib\site-packages\uvicorn\protocols\http\httptools_impl.py", line 411, in run_asgi
    result = await app(  # type: ignore[func-returns-value]
             ^^^^^^^^^^^^^^^^^^^^^^^^^^^^^^^^^^^^^^^^^^^^^^
  File "e:\tech\trm-os-branches\.venv\Lib\site-packages\uvicorn\middleware\proxy_headers.py", line 69, in __call__
    return await self.app(scope, receive, send)
           ^^^^^^^^^^^^^^^^^^^^^^^^^^^^^^^^^^^^
  File "e:\tech\trm-os-branches\.venv\Lib\site-packages\fastapi\applications.py", line 1054, in __call__
    await super().__call__(scope, receive, send)
  File "e:\tech\trm-os-branches\.venv\Lib\site-packages\starlette\applications.py", line 123, in __call__
    await self.middleware_stack(scope, receive, send)
  File "e:\tech\trm-os-branches\.venv\Lib\site-packages\starlette\middleware\errors.py", line 186, in __call__
    raise exc
  File "e:\tech\trm-os-branches\.venv\Lib\site-packages\starlette\middleware\errors.py", line 164, in __call__
    await self.app(scope, receive, _send)
  File "e:\tech\trm-os-branches\.venv\Lib\site-packages\starlette\middleware\exceptions.py", line 62, in __call__
    await wrap_app_handling_exceptions(self.app, conn)(scope, receive, send)
  File "e:\tech\trm-os-branches\.venv\Lib\site-packages\starlette\_exception_handler.py", line 64, in wrapped_app
    raise exc
  File "e:\tech\trm-os-branches\.venv\Lib\site-packages\starlette\_exception_handler.py", line 53, in wrapped_app
    await app(scope, receive, sender)
  File "e:\tech\trm-os-branches\.venv\Lib\site-packages\starlette\routing.py", line 758, in __call__
    await self.middleware_stack(scope, receive, send)
  File "e:\tech\trm-os-branches\.venv\Lib\site-packages\starlette\routing.py", line 778, in app
    await route.handle(scope, receive, send)
  File "e:\tech\trm-os-branches\.venv\Lib\site-packages\starlette\routing.py", line 299, in handle
    await self.app(scope, receive, send)
  File "e:\tech\trm-os-branches\.venv\Lib\site-packages\starlette\routing.py", line 79, in app
    await wrap_app_handling_exceptions(app, request)(scope, receive, send)
  File "e:\tech\trm-os-branches\.venv\Lib\site-packages\starlette\_exception_handler.py", line 64, in wrapped_app
    raise exc
  File "e:\tech\trm-os-branches\.venv\Lib\site-packages\starlette\_exception_handler.py", line 53, in wrapped_app
    await app(scope, receive, sender)
  File "e:\tech\trm-os-branches\.venv\Lib\site-packages\starlette\routing.py", line 74, in app
    response = await func(request)
               ^^^^^^^^^^^^^^^^^^^
  File "e:\tech\trm-os-branches\.venv\Lib\site-packages\fastapi\routing.py", line 278, in app
    raw_response = await run_endpoint_function(
                   ^^^^^^^^^^^^^^^^^^^^^^^^^^^^
  File "e:\tech\trm-os-branches\.venv\Lib\site-packages\fastapi\routing.py", line 193, in run_endpoint_function
    return await run_in_threadpool(dependant.call, **values)
           ^^^^^^^^^^^^^^^^^^^^^^^^^^^^^^^^^^^^^^^^^^^^^^^^^
  File "e:\tech\trm-os-branches\.venv\Lib\site-packages\starlette\concurrency.py", line 42, in run_in_threadpool
    return await anyio.to_thread.run_sync(func, *args)
           ^^^^^^^^^^^^^^^^^^^^^^^^^^^^^^^^^^^^^^^^^^^
  File "e:\tech\trm-os-branches\.venv\Lib\site-packages\anyio\to_thread.py", line 56, in run_sync
    return await get_async_backend().run_sync_in_worker_thread(
           ^^^^^^^^^^^^^^^^^^^^^^^^^^^^^^^^^^^^^^^^^^^^^^^^^^^^
  File "e:\tech\trm-os-branches\.venv\Lib\site-packages\anyio\_backends\_asyncio.py", line 2470, in run_sync_in_worker_thread
    return await future
           ^^^^^^^^^^^^
  File "e:\tech\trm-os-branches\.venv\Lib\site-packages\anyio\_backends\_asyncio.py", line 967, in run
    result = context.run(func, *args)
             ^^^^^^^^^^^^^^^^^^^^^^^^
  File "E:\tech\trm-os-branches\trm_api\api\v1\endpoints\win.py", line 19, in create_win
    return service.create_win(win_create=win_in)
           ^^^^^^^^^^^^^^^^^^^^^^^^^^^^^^^^^^^^^
  File "E:\tech\trm-os-branches\trm_api\services\win_service.py", line 23, in create_win
    return Win(**result)
           ^^^^^^^^^^^^^
  File "e:\tech\trm-os-branches\.venv\Lib\site-packages\pydantic\main.py", line 253, in __init__
    validated_self = self.__pydantic_validator__.validate_python(data, self_instance=self)
                     ^^^^^^^^^^^^^^^^^^^^^^^^^^^^^^^^^^^^^^^^^^^^^^^^^^^^^^^^^^^^^^^^^^^^^
pydantic_core._pydantic_core.ValidationError: 1 validation error for Win
createdAt
  Input should be a valid datetime [type=datetime_type, input_value=neo4j.time.DateTime(2025,...301353000, tzinfo=<UTC>), input_type=DateTime]
    For further information visit https://errors.pydantic.dev/2.11/v/datetime_type
2025-06-12 17:23:28,270 - uvicorn.error - INFO - Shutting down
2025-06-12 17:23:28,378 - uvicorn.error - INFO - Waiting for application shutdown.
2025-06-12 17:23:28,379 - uvicorn.error - INFO - Application shutdown complete.
2025-06-12 17:23:28,379 - uvicorn.error - INFO - Finished server process [33108]
2025-06-12 17:23:29,106 - uvicorn.error - INFO - Application startup complete.
2025-06-12 17:23:50,728 - uvicorn.error - INFO - Shutting down
2025-06-12 17:23:50,791 - uvicorn.error - INFO - Shutting down
2025-06-12 17:23:50,791 - uvicorn.error - INFO - Shutting down
2025-06-12 17:23:50,806 - uvicorn.error - INFO - Shutting down
2025-06-12 17:23:50,837 - uvicorn.error - INFO - Waiting for application shutdown.
2025-06-12 17:23:50,839 - uvicorn.error - INFO - Application shutdown complete.
2025-06-12 17:23:50,840 - uvicorn.error - INFO - Finished server process [33696]
2025-06-12 17:23:50,898 - uvicorn.error - INFO - Waiting for application shutdown.
2025-06-12 17:23:50,898 - uvicorn.error - INFO - Waiting for application shutdown.
2025-06-12 17:23:50,900 - uvicorn.error - INFO - Application shutdown complete.
2025-06-12 17:23:50,900 - uvicorn.error - INFO - Application shutdown complete.
2025-06-12 17:23:50,900 - uvicorn.error - INFO - Finished server process [19616]
2025-06-12 17:23:50,901 - uvicorn.error - INFO - Finished server process [24344]
2025-06-12 17:23:50,914 - uvicorn.error - INFO - Waiting for application shutdown.
2025-06-12 17:23:50,918 - uvicorn.error - INFO - Application shutdown complete.
2025-06-12 17:23:50,919 - uvicorn.error - INFO - Finished server process [33768]
2025-06-12 17:23:50,936 - neo4j.io - ERROR - Failed to write data to connection ResolvedIPv4Address(('34.142.144.246', 7687)) (ResolvedIPv4Address(('34.142.144.246', 7687)))
2025-06-12 17:23:50,939 - neo4j.io - ERROR - Failed to write data to connection IPv4Address(('p-66abf65c-68bb-0003.production-orch-0337.neo4j.io', 7687)) (ResolvedIPv4Address(('34.142.144.246', 7687)))
2025-06-12 17:24:11,892 - uvicorn.error - INFO - Application startup complete.
2025-06-12 17:25:14,339 - uvicorn.error - INFO - Shutting down
2025-06-12 17:25:14,447 - uvicorn.error - INFO - Waiting for application shutdown.
2025-06-12 17:25:14,447 - uvicorn.error - INFO - Application shutdown complete.
2025-06-12 17:25:14,447 - uvicorn.error - INFO - Finished server process [33076]
2025-06-12 17:28:35,916 - uvicorn.access - INFO - 127.0.0.1:63059 - "GET /api/v1/users HTTP/1.1" 307
2025-06-12 17:28:37,184 - uvicorn.access - INFO - 127.0.0.1:63059 - "GET /api/v1/users/ HTTP/1.1" 200
2025-06-12 17:28:39,336 - uvicorn.access - INFO - 127.0.0.1:63072 - "POST /api/v1/projects/ HTTP/1.1" 201
2025-06-12 17:28:42,415 - uvicorn.access - INFO - 127.0.0.1:63078 - "POST /api/v1/wins/ HTTP/1.1" 500
2025-06-12 17:28:42,416 - uvicorn.error - ERROR - Exception in ASGI application
Traceback (most recent call last):
  File "e:\tech\trm-os-branches\.venv\Lib\site-packages\uvicorn\protocols\http\httptools_impl.py", line 411, in run_asgi
    result = await app(  # type: ignore[func-returns-value]
             ^^^^^^^^^^^^^^^^^^^^^^^^^^^^^^^^^^^^^^^^^^^^^^
  File "e:\tech\trm-os-branches\.venv\Lib\site-packages\uvicorn\middleware\proxy_headers.py", line 69, in __call__
    return await self.app(scope, receive, send)
           ^^^^^^^^^^^^^^^^^^^^^^^^^^^^^^^^^^^^
  File "e:\tech\trm-os-branches\.venv\Lib\site-packages\fastapi\applications.py", line 1054, in __call__
    await super().__call__(scope, receive, send)
  File "e:\tech\trm-os-branches\.venv\Lib\site-packages\starlette\applications.py", line 123, in __call__
    await self.middleware_stack(scope, receive, send)
  File "e:\tech\trm-os-branches\.venv\Lib\site-packages\starlette\middleware\errors.py", line 186, in __call__
    raise exc
  File "e:\tech\trm-os-branches\.venv\Lib\site-packages\starlette\middleware\errors.py", line 164, in __call__
    await self.app(scope, receive, _send)
  File "e:\tech\trm-os-branches\.venv\Lib\site-packages\starlette\middleware\exceptions.py", line 62, in __call__
    await wrap_app_handling_exceptions(self.app, conn)(scope, receive, send)
  File "e:\tech\trm-os-branches\.venv\Lib\site-packages\starlette\_exception_handler.py", line 64, in wrapped_app
    raise exc
  File "e:\tech\trm-os-branches\.venv\Lib\site-packages\starlette\_exception_handler.py", line 53, in wrapped_app
    await app(scope, receive, sender)
  File "e:\tech\trm-os-branches\.venv\Lib\site-packages\starlette\routing.py", line 758, in __call__
    await self.middleware_stack(scope, receive, send)
  File "e:\tech\trm-os-branches\.venv\Lib\site-packages\starlette\routing.py", line 778, in app
    await route.handle(scope, receive, send)
  File "e:\tech\trm-os-branches\.venv\Lib\site-packages\starlette\routing.py", line 299, in handle
    await self.app(scope, receive, send)
  File "e:\tech\trm-os-branches\.venv\Lib\site-packages\starlette\routing.py", line 79, in app
    await wrap_app_handling_exceptions(app, request)(scope, receive, send)
  File "e:\tech\trm-os-branches\.venv\Lib\site-packages\starlette\_exception_handler.py", line 64, in wrapped_app
    raise exc
  File "e:\tech\trm-os-branches\.venv\Lib\site-packages\starlette\_exception_handler.py", line 53, in wrapped_app
    await app(scope, receive, sender)
  File "e:\tech\trm-os-branches\.venv\Lib\site-packages\starlette\routing.py", line 74, in app
    response = await func(request)
               ^^^^^^^^^^^^^^^^^^^
  File "e:\tech\trm-os-branches\.venv\Lib\site-packages\fastapi\routing.py", line 278, in app
    raw_response = await run_endpoint_function(
                   ^^^^^^^^^^^^^^^^^^^^^^^^^^^^
  File "e:\tech\trm-os-branches\.venv\Lib\site-packages\fastapi\routing.py", line 193, in run_endpoint_function
    return await run_in_threadpool(dependant.call, **values)
           ^^^^^^^^^^^^^^^^^^^^^^^^^^^^^^^^^^^^^^^^^^^^^^^^^
  File "e:\tech\trm-os-branches\.venv\Lib\site-packages\starlette\concurrency.py", line 42, in run_in_threadpool
    return await anyio.to_thread.run_sync(func, *args)
           ^^^^^^^^^^^^^^^^^^^^^^^^^^^^^^^^^^^^^^^^^^^
  File "e:\tech\trm-os-branches\.venv\Lib\site-packages\anyio\to_thread.py", line 56, in run_sync
    return await get_async_backend().run_sync_in_worker_thread(
           ^^^^^^^^^^^^^^^^^^^^^^^^^^^^^^^^^^^^^^^^^^^^^^^^^^^^
  File "e:\tech\trm-os-branches\.venv\Lib\site-packages\anyio\_backends\_asyncio.py", line 2470, in run_sync_in_worker_thread
    return await future
           ^^^^^^^^^^^^
  File "e:\tech\trm-os-branches\.venv\Lib\site-packages\anyio\_backends\_asyncio.py", line 967, in run
    result = context.run(func, *args)
             ^^^^^^^^^^^^^^^^^^^^^^^^
  File "E:\tech\trm-os-branches\trm_api\api\v1\endpoints\win.py", line 19, in create_win
    return service.create_win(win_create=win_in)
           ^^^^^^^^^^^^^^^^^^^^^^^^^^^^^^^^^^^^^
  File "E:\tech\trm-os-branches\trm_api\services\win_service.py", line 23, in create_win
    return Win(**result)
           ^^^^^^^^^^^^^
  File "e:\tech\trm-os-branches\.venv\Lib\site-packages\pydantic\main.py", line 253, in __init__
    validated_self = self.__pydantic_validator__.validate_python(data, self_instance=self)
                     ^^^^^^^^^^^^^^^^^^^^^^^^^^^^^^^^^^^^^^^^^^^^^^^^^^^^^^^^^^^^^^^^^^^^^
pydantic_core._pydantic_core.ValidationError: 1 validation error for Win
createdAt
  Input should be a valid datetime [type=datetime_type, input_value=neo4j.time.DateTime(2025,...391036000, tzinfo=<UTC>), input_type=DateTime]
    For further information visit https://errors.pydantic.dev/2.11/v/datetime_type
2025-06-12 17:28:44,695 - uvicorn.access - INFO - 127.0.0.1:63088 - "DELETE /api/v1/projects/570b91d01e74413bae59d74dec4ddc8c HTTP/1.1" 204
2025-06-12 17:32:52,315 - uvicorn.error - INFO - Application startup complete.
2025-06-12 17:34:47,369 - uvicorn.access - INFO - 127.0.0.1:64073 - "GET /api/v1/users HTTP/1.1" 307
2025-06-12 17:34:47,515 - uvicorn.access - INFO - 127.0.0.1:64073 - "GET /api/v1/users/ HTTP/1.1" 200
2025-06-12 17:34:49,687 - uvicorn.access - INFO - 127.0.0.1:64079 - "POST /api/v1/projects/ HTTP/1.1" 201
2025-06-12 17:34:51,989 - uvicorn.access - INFO - 127.0.0.1:64087 - "POST /api/v1/wins/ HTTP/1.1" 500
2025-06-12 17:34:54,256 - uvicorn.access - INFO - 127.0.0.1:64093 - "DELETE /api/v1/projects/c46fa48fab124d719aaf626936efdbe0 HTTP/1.1" 204
2025-06-12 17:38:21,955 - uvicorn.error - INFO - Application startup complete.
2025-06-12 17:39:29,053 - uvicorn.error - INFO - Application startup complete.
2025-06-12 17:44:10,167 - uvicorn.access - INFO - 127.0.0.1:65457 - "GET /api/v1/users HTTP/1.1" 307
2025-06-12 17:44:10,327 - uvicorn.access - INFO - 127.0.0.1:65457 - "GET /api/v1/users/ HTTP/1.1" 200
2025-06-12 17:44:12,477 - uvicorn.access - INFO - 127.0.0.1:65464 - "POST /api/v1/projects/ HTTP/1.1" 201
2025-06-12 17:44:14,778 - uvicorn.access - INFO - 127.0.0.1:65472 - "POST /api/v1/wins/ HTTP/1.1" 500
2025-06-12 17:44:14,778 - uvicorn.error - ERROR - Exception in ASGI application
Traceback (most recent call last):
  File "e:\tech\trm-os-branches\.venv\Lib\site-packages\uvicorn\protocols\http\httptools_impl.py", line 411, in run_asgi
    result = await app(  # type: ignore[func-returns-value]
             ^^^^^^^^^^^^^^^^^^^^^^^^^^^^^^^^^^^^^^^^^^^^^^
  File "e:\tech\trm-os-branches\.venv\Lib\site-packages\uvicorn\middleware\proxy_headers.py", line 69, in __call__
    return await self.app(scope, receive, send)
           ^^^^^^^^^^^^^^^^^^^^^^^^^^^^^^^^^^^^
  File "e:\tech\trm-os-branches\.venv\Lib\site-packages\fastapi\applications.py", line 1054, in __call__
    await super().__call__(scope, receive, send)
  File "e:\tech\trm-os-branches\.venv\Lib\site-packages\starlette\applications.py", line 123, in __call__
    await self.middleware_stack(scope, receive, send)
  File "e:\tech\trm-os-branches\.venv\Lib\site-packages\starlette\middleware\errors.py", line 186, in __call__
    raise exc
  File "e:\tech\trm-os-branches\.venv\Lib\site-packages\starlette\middleware\errors.py", line 164, in __call__
    await self.app(scope, receive, _send)
  File "e:\tech\trm-os-branches\.venv\Lib\site-packages\starlette\middleware\exceptions.py", line 62, in __call__
    await wrap_app_handling_exceptions(self.app, conn)(scope, receive, send)
  File "e:\tech\trm-os-branches\.venv\Lib\site-packages\starlette\_exception_handler.py", line 64, in wrapped_app
    raise exc
  File "e:\tech\trm-os-branches\.venv\Lib\site-packages\starlette\_exception_handler.py", line 53, in wrapped_app
    await app(scope, receive, sender)
  File "e:\tech\trm-os-branches\.venv\Lib\site-packages\starlette\routing.py", line 758, in __call__
    await self.middleware_stack(scope, receive, send)
  File "e:\tech\trm-os-branches\.venv\Lib\site-packages\starlette\routing.py", line 778, in app
    await route.handle(scope, receive, send)
  File "e:\tech\trm-os-branches\.venv\Lib\site-packages\starlette\routing.py", line 299, in handle
    await self.app(scope, receive, send)
  File "e:\tech\trm-os-branches\.venv\Lib\site-packages\starlette\routing.py", line 79, in app
    await wrap_app_handling_exceptions(app, request)(scope, receive, send)
  File "e:\tech\trm-os-branches\.venv\Lib\site-packages\starlette\_exception_handler.py", line 64, in wrapped_app
    raise exc
  File "e:\tech\trm-os-branches\.venv\Lib\site-packages\starlette\_exception_handler.py", line 53, in wrapped_app
    await app(scope, receive, sender)
  File "e:\tech\trm-os-branches\.venv\Lib\site-packages\starlette\routing.py", line 74, in app
    response = await func(request)
               ^^^^^^^^^^^^^^^^^^^
  File "e:\tech\trm-os-branches\.venv\Lib\site-packages\fastapi\routing.py", line 278, in app
    raw_response = await run_endpoint_function(
                   ^^^^^^^^^^^^^^^^^^^^^^^^^^^^
  File "e:\tech\trm-os-branches\.venv\Lib\site-packages\fastapi\routing.py", line 193, in run_endpoint_function
    return await run_in_threadpool(dependant.call, **values)
           ^^^^^^^^^^^^^^^^^^^^^^^^^^^^^^^^^^^^^^^^^^^^^^^^^
  File "e:\tech\trm-os-branches\.venv\Lib\site-packages\starlette\concurrency.py", line 42, in run_in_threadpool
    return await anyio.to_thread.run_sync(func, *args)
           ^^^^^^^^^^^^^^^^^^^^^^^^^^^^^^^^^^^^^^^^^^^
  File "e:\tech\trm-os-branches\.venv\Lib\site-packages\anyio\to_thread.py", line 56, in run_sync
    return await get_async_backend().run_sync_in_worker_thread(
           ^^^^^^^^^^^^^^^^^^^^^^^^^^^^^^^^^^^^^^^^^^^^^^^^^^^^
  File "e:\tech\trm-os-branches\.venv\Lib\site-packages\anyio\_backends\_asyncio.py", line 2470, in run_sync_in_worker_thread
    return await future
           ^^^^^^^^^^^^
  File "e:\tech\trm-os-branches\.venv\Lib\site-packages\anyio\_backends\_asyncio.py", line 967, in run
    result = context.run(func, *args)
             ^^^^^^^^^^^^^^^^^^^^^^^^
  File "E:\tech\trm-os-branches\trm_api\api\v1\endpoints\win.py", line 19, in create_win
    return service.create_win(win_create=win_in)
           ^^^^^^^^^^^^^^^^^^^^^^^^^^^^^^^^^^^^^
  File "E:\tech\trm-os-branches\trm_api\services\win_service.py", line 23, in create_win
    # Convert datetime fields from neo4j.time.DateTime to Python datetime
           ^^^^^^^^^^^^^
  File "e:\tech\trm-os-branches\.venv\Lib\site-packages\pydantic\main.py", line 253, in __init__
    validated_self = self.__pydantic_validator__.validate_python(data, self_instance=self)
                     ^^^^^^^^^^^^^^^^^^^^^^^^^^^^^^^^^^^^^^^^^^^^^^^^^^^^^^^^^^^^^^^^^^^^^
pydantic_core._pydantic_core.ValidationError: 1 validation error for Win
createdAt
  Input should be a valid datetime [type=datetime_type, input_value=neo4j.time.DateTime(2025,...510776000, tzinfo=<UTC>), input_type=DateTime]
    For further information visit https://errors.pydantic.dev/2.11/v/datetime_type
2025-06-12 17:44:17,045 - uvicorn.access - INFO - 127.0.0.1:65478 - "DELETE /api/v1/projects/5c10b7538de1451d8a6d5d8af4c3d852 HTTP/1.1" 204
2025-06-12 17:46:54,385 - uvicorn.access - INFO - 127.0.0.1:49483 - "GET /api/v1/users HTTP/1.1" 307
2025-06-12 17:46:54,588 - uvicorn.access - INFO - 127.0.0.1:49483 - "GET /api/v1/users/ HTTP/1.1" 200
2025-06-12 17:46:56,757 - uvicorn.access - INFO - 127.0.0.1:49490 - "POST /api/v1/projects/ HTTP/1.1" 201
2025-06-12 17:46:59,073 - uvicorn.access - INFO - 127.0.0.1:49499 - "POST /api/v1/wins/ HTTP/1.1" 500
2025-06-12 17:46:59,073 - uvicorn.error - ERROR - Exception in ASGI application
Traceback (most recent call last):
  File "e:\tech\trm-os-branches\.venv\Lib\site-packages\uvicorn\protocols\http\httptools_impl.py", line 411, in run_asgi
    result = await app(  # type: ignore[func-returns-value]
             ^^^^^^^^^^^^^^^^^^^^^^^^^^^^^^^^^^^^^^^^^^^^^^
  File "e:\tech\trm-os-branches\.venv\Lib\site-packages\uvicorn\middleware\proxy_headers.py", line 69, in __call__
    return await self.app(scope, receive, send)
           ^^^^^^^^^^^^^^^^^^^^^^^^^^^^^^^^^^^^
  File "e:\tech\trm-os-branches\.venv\Lib\site-packages\fastapi\applications.py", line 1054, in __call__
    await super().__call__(scope, receive, send)
  File "e:\tech\trm-os-branches\.venv\Lib\site-packages\starlette\applications.py", line 123, in __call__
    await self.middleware_stack(scope, receive, send)
  File "e:\tech\trm-os-branches\.venv\Lib\site-packages\starlette\middleware\errors.py", line 186, in __call__
    raise exc
  File "e:\tech\trm-os-branches\.venv\Lib\site-packages\starlette\middleware\errors.py", line 164, in __call__
    await self.app(scope, receive, _send)
  File "e:\tech\trm-os-branches\.venv\Lib\site-packages\starlette\middleware\exceptions.py", line 62, in __call__
    await wrap_app_handling_exceptions(self.app, conn)(scope, receive, send)
  File "e:\tech\trm-os-branches\.venv\Lib\site-packages\starlette\_exception_handler.py", line 64, in wrapped_app
    raise exc
  File "e:\tech\trm-os-branches\.venv\Lib\site-packages\starlette\_exception_handler.py", line 53, in wrapped_app
    await app(scope, receive, sender)
  File "e:\tech\trm-os-branches\.venv\Lib\site-packages\starlette\routing.py", line 758, in __call__
    await self.middleware_stack(scope, receive, send)
  File "e:\tech\trm-os-branches\.venv\Lib\site-packages\starlette\routing.py", line 778, in app
    await route.handle(scope, receive, send)
  File "e:\tech\trm-os-branches\.venv\Lib\site-packages\starlette\routing.py", line 299, in handle
    await self.app(scope, receive, send)
  File "e:\tech\trm-os-branches\.venv\Lib\site-packages\starlette\routing.py", line 79, in app
    await wrap_app_handling_exceptions(app, request)(scope, receive, send)
  File "e:\tech\trm-os-branches\.venv\Lib\site-packages\starlette\_exception_handler.py", line 64, in wrapped_app
    raise exc
  File "e:\tech\trm-os-branches\.venv\Lib\site-packages\starlette\_exception_handler.py", line 53, in wrapped_app
    await app(scope, receive, sender)
  File "e:\tech\trm-os-branches\.venv\Lib\site-packages\starlette\routing.py", line 74, in app
    response = await func(request)
               ^^^^^^^^^^^^^^^^^^^
  File "e:\tech\trm-os-branches\.venv\Lib\site-packages\fastapi\routing.py", line 278, in app
    raw_response = await run_endpoint_function(
                   ^^^^^^^^^^^^^^^^^^^^^^^^^^^^
  File "e:\tech\trm-os-branches\.venv\Lib\site-packages\fastapi\routing.py", line 193, in run_endpoint_function
    return await run_in_threadpool(dependant.call, **values)
           ^^^^^^^^^^^^^^^^^^^^^^^^^^^^^^^^^^^^^^^^^^^^^^^^^
  File "e:\tech\trm-os-branches\.venv\Lib\site-packages\starlette\concurrency.py", line 42, in run_in_threadpool
    return await anyio.to_thread.run_sync(func, *args)
           ^^^^^^^^^^^^^^^^^^^^^^^^^^^^^^^^^^^^^^^^^^^
  File "e:\tech\trm-os-branches\.venv\Lib\site-packages\anyio\to_thread.py", line 56, in run_sync
    return await get_async_backend().run_sync_in_worker_thread(
           ^^^^^^^^^^^^^^^^^^^^^^^^^^^^^^^^^^^^^^^^^^^^^^^^^^^^
  File "e:\tech\trm-os-branches\.venv\Lib\site-packages\anyio\_backends\_asyncio.py", line 2470, in run_sync_in_worker_thread
    return await future
           ^^^^^^^^^^^^
  File "e:\tech\trm-os-branches\.venv\Lib\site-packages\anyio\_backends\_asyncio.py", line 967, in run
    result = context.run(func, *args)
             ^^^^^^^^^^^^^^^^^^^^^^^^
  File "E:\tech\trm-os-branches\trm_api\api\v1\endpoints\win.py", line 19, in create_win
    return service.create_win(win_create=win_in)
           ^^^^^^^^^^^^^^^^^^^^^^^^^^^^^^^^^^^^^
  File "E:\tech\trm-os-branches\trm_api\services\win_service.py", line 23, in create_win
    # Convert datetime fields from neo4j.time.DateTime to Python datetime
           ^^^^^^^^^^^^^
  File "e:\tech\trm-os-branches\.venv\Lib\site-packages\pydantic\main.py", line 253, in __init__
    validated_self = self.__pydantic_validator__.validate_python(data, self_instance=self)
                     ^^^^^^^^^^^^^^^^^^^^^^^^^^^^^^^^^^^^^^^^^^^^^^^^^^^^^^^^^^^^^^^^^^^^^
pydantic_core._pydantic_core.ValidationError: 1 validation error for Win
createdAt
  Input should be a valid datetime [type=datetime_type, input_value=neo4j.time.DateTime(2025,...805118000, tzinfo=<UTC>), input_type=DateTime]
    For further information visit https://errors.pydantic.dev/2.11/v/datetime_type
2025-06-12 17:47:01,356 - uvicorn.access - INFO - 127.0.0.1:49507 - "DELETE /api/v1/projects/ce4168cd2fcb49c0a39b274052c5a301 HTTP/1.1" 204
2025-06-12 17:51:24,116 - uvicorn.error - INFO - Application startup complete.
2025-06-12 17:51:37,382 - uvicorn.error - INFO - Application startup complete.
2025-06-12 17:52:17,214 - uvicorn.error - INFO - Shutting down
2025-06-12 17:52:17,323 - uvicorn.error - INFO - Waiting for application shutdown.
2025-06-12 17:52:17,323 - uvicorn.error - INFO - Application shutdown complete.
2025-06-12 17:52:17,324 - uvicorn.error - INFO - Finished server process [34232]
2025-06-12 17:52:33,098 - uvicorn.error - INFO - Shutting down
2025-06-12 17:52:33,208 - uvicorn.error - INFO - Waiting for application shutdown.
2025-06-12 17:52:33,209 - uvicorn.error - INFO - Application shutdown complete.
2025-06-12 17:52:33,209 - uvicorn.error - INFO - Finished server process [27604]
2025-06-12 17:52:33,829 - uvicorn.error - INFO - Application startup complete.
2025-06-12 17:56:27,426 - uvicorn.access - INFO - 127.0.0.1:50991 - "GET /api/v1/users HTTP/1.1" 307
2025-06-12 17:56:27,595 - uvicorn.access - INFO - 127.0.0.1:50991 - "GET /api/v1/users/ HTTP/1.1" 200
2025-06-12 17:56:29,766 - uvicorn.access - INFO - 127.0.0.1:50999 - "POST /api/v1/projects/ HTTP/1.1" 201
2025-06-12 17:56:32,100 - uvicorn.access - INFO - 127.0.0.1:51005 - "POST /api/v1/wins/ HTTP/1.1" 500
2025-06-12 17:56:32,103 - uvicorn.error - ERROR - Exception in ASGI application
Traceback (most recent call last):
  File "e:\tech\trm-os-branches\.venv\Lib\site-packages\uvicorn\protocols\http\httptools_impl.py", line 411, in run_asgi
    result = await app(  # type: ignore[func-returns-value]
             ^^^^^^^^^^^^^^^^^^^^^^^^^^^^^^^^^^^^^^^^^^^^^^
  File "e:\tech\trm-os-branches\.venv\Lib\site-packages\uvicorn\middleware\proxy_headers.py", line 69, in __call__
    return await self.app(scope, receive, send)
           ^^^^^^^^^^^^^^^^^^^^^^^^^^^^^^^^^^^^
  File "e:\tech\trm-os-branches\.venv\Lib\site-packages\fastapi\applications.py", line 1054, in __call__
    await super().__call__(scope, receive, send)
  File "e:\tech\trm-os-branches\.venv\Lib\site-packages\starlette\applications.py", line 123, in __call__
    await self.middleware_stack(scope, receive, send)
  File "e:\tech\trm-os-branches\.venv\Lib\site-packages\starlette\middleware\errors.py", line 186, in __call__
    raise exc
  File "e:\tech\trm-os-branches\.venv\Lib\site-packages\starlette\middleware\errors.py", line 164, in __call__
    await self.app(scope, receive, _send)
  File "e:\tech\trm-os-branches\.venv\Lib\site-packages\starlette\middleware\exceptions.py", line 62, in __call__
    await wrap_app_handling_exceptions(self.app, conn)(scope, receive, send)
  File "e:\tech\trm-os-branches\.venv\Lib\site-packages\starlette\_exception_handler.py", line 64, in wrapped_app
    raise exc
  File "e:\tech\trm-os-branches\.venv\Lib\site-packages\starlette\_exception_handler.py", line 53, in wrapped_app
    await app(scope, receive, sender)
  File "e:\tech\trm-os-branches\.venv\Lib\site-packages\starlette\routing.py", line 758, in __call__
    await self.middleware_stack(scope, receive, send)
  File "e:\tech\trm-os-branches\.venv\Lib\site-packages\starlette\routing.py", line 778, in app
    await route.handle(scope, receive, send)
  File "e:\tech\trm-os-branches\.venv\Lib\site-packages\starlette\routing.py", line 299, in handle
    await self.app(scope, receive, send)
  File "e:\tech\trm-os-branches\.venv\Lib\site-packages\starlette\routing.py", line 79, in app
    await wrap_app_handling_exceptions(app, request)(scope, receive, send)
  File "e:\tech\trm-os-branches\.venv\Lib\site-packages\starlette\_exception_handler.py", line 64, in wrapped_app
    raise exc
  File "e:\tech\trm-os-branches\.venv\Lib\site-packages\starlette\_exception_handler.py", line 53, in wrapped_app
    await app(scope, receive, sender)
  File "e:\tech\trm-os-branches\.venv\Lib\site-packages\starlette\routing.py", line 74, in app
    response = await func(request)
               ^^^^^^^^^^^^^^^^^^^
  File "e:\tech\trm-os-branches\.venv\Lib\site-packages\fastapi\routing.py", line 278, in app
    raw_response = await run_endpoint_function(
                   ^^^^^^^^^^^^^^^^^^^^^^^^^^^^
  File "e:\tech\trm-os-branches\.venv\Lib\site-packages\fastapi\routing.py", line 193, in run_endpoint_function
    return await run_in_threadpool(dependant.call, **values)
           ^^^^^^^^^^^^^^^^^^^^^^^^^^^^^^^^^^^^^^^^^^^^^^^^^
  File "e:\tech\trm-os-branches\.venv\Lib\site-packages\starlette\concurrency.py", line 42, in run_in_threadpool
    return await anyio.to_thread.run_sync(func, *args)
           ^^^^^^^^^^^^^^^^^^^^^^^^^^^^^^^^^^^^^^^^^^^
  File "e:\tech\trm-os-branches\.venv\Lib\site-packages\anyio\to_thread.py", line 56, in run_sync
    return await get_async_backend().run_sync_in_worker_thread(
           ^^^^^^^^^^^^^^^^^^^^^^^^^^^^^^^^^^^^^^^^^^^^^^^^^^^^
  File "e:\tech\trm-os-branches\.venv\Lib\site-packages\anyio\_backends\_asyncio.py", line 2470, in run_sync_in_worker_thread
    return await future
           ^^^^^^^^^^^^
  File "e:\tech\trm-os-branches\.venv\Lib\site-packages\anyio\_backends\_asyncio.py", line 967, in run
    result = context.run(func, *args)
             ^^^^^^^^^^^^^^^^^^^^^^^^
  File "E:\tech\trm-os-branches\trm_api\api\v1\endpoints\win.py", line 19, in create_win
    return service.create_win(win_create=win_in)
           ^^^^^^^^^^^^^^^^^^^^^^^^^^^^^^^^^^^^^
  File "E:\tech\trm-os-branches\trm_api\services\win_service.py", line 23, in create_win
    # Ensure result exists
           ^^^^^^^^^^^^^
  File "e:\tech\trm-os-branches\.venv\Lib\site-packages\pydantic\main.py", line 253, in __init__
    validated_self = self.__pydantic_validator__.validate_python(data, self_instance=self)
                     ^^^^^^^^^^^^^^^^^^^^^^^^^^^^^^^^^^^^^^^^^^^^^^^^^^^^^^^^^^^^^^^^^^^^^
pydantic_core._pydantic_core.ValidationError: 1 validation error for Win
createdAt
  Input should be a valid datetime [type=datetime_type, input_value=neo4j.time.DateTime(2025,...821468000, tzinfo=<UTC>), input_type=DateTime]
    For further information visit https://errors.pydantic.dev/2.11/v/datetime_type
2025-06-12 17:56:34,372 - uvicorn.access - INFO - 127.0.0.1:51015 - "DELETE /api/v1/projects/b66e02bf0d7f42aba4b06394b6b3e4f9 HTTP/1.1" 204
2025-06-12 18:00:06,198 - uvicorn.access - INFO - 127.0.0.1:51570 - "GET /api/v1/users HTTP/1.1" 307
2025-06-12 18:00:06,346 - uvicorn.access - INFO - 127.0.0.1:51570 - "GET /api/v1/users/ HTTP/1.1" 200
2025-06-12 18:00:08,506 - uvicorn.access - INFO - 127.0.0.1:51577 - "POST /api/v1/projects/ HTTP/1.1" 201
2025-06-12 18:00:10,810 - uvicorn.access - INFO - 127.0.0.1:51583 - "POST /api/v1/wins/ HTTP/1.1" 500
2025-06-12 18:00:10,810 - uvicorn.error - ERROR - Exception in ASGI application
Traceback (most recent call last):
  File "e:\tech\trm-os-branches\.venv\Lib\site-packages\uvicorn\protocols\http\httptools_impl.py", line 411, in run_asgi
    result = await app(  # type: ignore[func-returns-value]
             ^^^^^^^^^^^^^^^^^^^^^^^^^^^^^^^^^^^^^^^^^^^^^^
  File "e:\tech\trm-os-branches\.venv\Lib\site-packages\uvicorn\middleware\proxy_headers.py", line 69, in __call__
    return await self.app(scope, receive, send)
           ^^^^^^^^^^^^^^^^^^^^^^^^^^^^^^^^^^^^
  File "e:\tech\trm-os-branches\.venv\Lib\site-packages\fastapi\applications.py", line 1054, in __call__
    await super().__call__(scope, receive, send)
  File "e:\tech\trm-os-branches\.venv\Lib\site-packages\starlette\applications.py", line 123, in __call__
    await self.middleware_stack(scope, receive, send)
  File "e:\tech\trm-os-branches\.venv\Lib\site-packages\starlette\middleware\errors.py", line 186, in __call__
    raise exc
  File "e:\tech\trm-os-branches\.venv\Lib\site-packages\starlette\middleware\errors.py", line 164, in __call__
    await self.app(scope, receive, _send)
  File "e:\tech\trm-os-branches\.venv\Lib\site-packages\starlette\middleware\exceptions.py", line 62, in __call__
    await wrap_app_handling_exceptions(self.app, conn)(scope, receive, send)
  File "e:\tech\trm-os-branches\.venv\Lib\site-packages\starlette\_exception_handler.py", line 64, in wrapped_app
    raise exc
  File "e:\tech\trm-os-branches\.venv\Lib\site-packages\starlette\_exception_handler.py", line 53, in wrapped_app
    await app(scope, receive, sender)
  File "e:\tech\trm-os-branches\.venv\Lib\site-packages\starlette\routing.py", line 758, in __call__
    await self.middleware_stack(scope, receive, send)
  File "e:\tech\trm-os-branches\.venv\Lib\site-packages\starlette\routing.py", line 778, in app
    await route.handle(scope, receive, send)
  File "e:\tech\trm-os-branches\.venv\Lib\site-packages\starlette\routing.py", line 299, in handle
    await self.app(scope, receive, send)
  File "e:\tech\trm-os-branches\.venv\Lib\site-packages\starlette\routing.py", line 79, in app
    await wrap_app_handling_exceptions(app, request)(scope, receive, send)
  File "e:\tech\trm-os-branches\.venv\Lib\site-packages\starlette\_exception_handler.py", line 64, in wrapped_app
    raise exc
  File "e:\tech\trm-os-branches\.venv\Lib\site-packages\starlette\_exception_handler.py", line 53, in wrapped_app
    await app(scope, receive, sender)
  File "e:\tech\trm-os-branches\.venv\Lib\site-packages\starlette\routing.py", line 74, in app
    response = await func(request)
               ^^^^^^^^^^^^^^^^^^^
  File "e:\tech\trm-os-branches\.venv\Lib\site-packages\fastapi\routing.py", line 278, in app
    raw_response = await run_endpoint_function(
                   ^^^^^^^^^^^^^^^^^^^^^^^^^^^^
  File "e:\tech\trm-os-branches\.venv\Lib\site-packages\fastapi\routing.py", line 193, in run_endpoint_function
    return await run_in_threadpool(dependant.call, **values)
           ^^^^^^^^^^^^^^^^^^^^^^^^^^^^^^^^^^^^^^^^^^^^^^^^^
  File "e:\tech\trm-os-branches\.venv\Lib\site-packages\starlette\concurrency.py", line 42, in run_in_threadpool
    return await anyio.to_thread.run_sync(func, *args)
           ^^^^^^^^^^^^^^^^^^^^^^^^^^^^^^^^^^^^^^^^^^^
  File "e:\tech\trm-os-branches\.venv\Lib\site-packages\anyio\to_thread.py", line 56, in run_sync
    return await get_async_backend().run_sync_in_worker_thread(
           ^^^^^^^^^^^^^^^^^^^^^^^^^^^^^^^^^^^^^^^^^^^^^^^^^^^^
  File "e:\tech\trm-os-branches\.venv\Lib\site-packages\anyio\_backends\_asyncio.py", line 2470, in run_sync_in_worker_thread
    return await future
           ^^^^^^^^^^^^
  File "e:\tech\trm-os-branches\.venv\Lib\site-packages\anyio\_backends\_asyncio.py", line 967, in run
    result = context.run(func, *args)
             ^^^^^^^^^^^^^^^^^^^^^^^^
  File "E:\tech\trm-os-branches\trm_api\api\v1\endpoints\win.py", line 19, in create_win
    return service.create_win(win_create=win_in)
           ^^^^^^^^^^^^^^^^^^^^^^^^^^^^^^^^^^^^^
  File "E:\tech\trm-os-branches\trm_api\services\win_service.py", line 23, in create_win
    # Debug output - log the call stack and original data
               ^^^^^^^^^^^^^
  File "e:\tech\trm-os-branches\.venv\Lib\site-packages\pydantic\main.py", line 253, in __init__
    validated_self = self.__pydantic_validator__.validate_python(data, self_instance=self)
                     ^^^^^^^^^^^^^^^^^^^^^^^^^^^^^^^^^^^^^^^^^^^^^^^^^^^^^^^^^^^^^^^^^^^^^
pydantic_core._pydantic_core.ValidationError: 1 validation error for Win
createdAt
  Input should be a valid datetime [type=datetime_type, input_value=neo4j.time.DateTime(2025,...538624000, tzinfo=<UTC>), input_type=DateTime]
    For further information visit https://errors.pydantic.dev/2.11/v/datetime_type
2025-06-12 18:00:13,082 - uvicorn.access - INFO - 127.0.0.1:51590 - "DELETE /api/v1/projects/a643b031c3ae437c85d39968c1123aa9 HTTP/1.1" 204
2025-06-12 18:01:18,374 - uvicorn.access - INFO - 127.0.0.1:51771 - "GET /api/v1/users HTTP/1.1" 307
2025-06-12 18:01:18,519 - uvicorn.access - INFO - 127.0.0.1:51771 - "GET /api/v1/users/ HTTP/1.1" 200
2025-06-12 18:01:20,671 - uvicorn.access - INFO - 127.0.0.1:51777 - "POST /api/v1/projects/ HTTP/1.1" 201
2025-06-12 18:01:22,986 - uvicorn.access - INFO - 127.0.0.1:51785 - "POST /api/v1/wins/ HTTP/1.1" 500
2025-06-12 18:01:22,986 - uvicorn.error - ERROR - Exception in ASGI application
Traceback (most recent call last):
  File "e:\tech\trm-os-branches\.venv\Lib\site-packages\uvicorn\protocols\http\httptools_impl.py", line 411, in run_asgi
    result = await app(  # type: ignore[func-returns-value]
             ^^^^^^^^^^^^^^^^^^^^^^^^^^^^^^^^^^^^^^^^^^^^^^
  File "e:\tech\trm-os-branches\.venv\Lib\site-packages\uvicorn\middleware\proxy_headers.py", line 69, in __call__
    return await self.app(scope, receive, send)
           ^^^^^^^^^^^^^^^^^^^^^^^^^^^^^^^^^^^^
  File "e:\tech\trm-os-branches\.venv\Lib\site-packages\fastapi\applications.py", line 1054, in __call__
    await super().__call__(scope, receive, send)
  File "e:\tech\trm-os-branches\.venv\Lib\site-packages\starlette\applications.py", line 123, in __call__
    await self.middleware_stack(scope, receive, send)
  File "e:\tech\trm-os-branches\.venv\Lib\site-packages\starlette\middleware\errors.py", line 186, in __call__
    raise exc
  File "e:\tech\trm-os-branches\.venv\Lib\site-packages\starlette\middleware\errors.py", line 164, in __call__
    await self.app(scope, receive, _send)
  File "e:\tech\trm-os-branches\.venv\Lib\site-packages\starlette\middleware\exceptions.py", line 62, in __call__
    await wrap_app_handling_exceptions(self.app, conn)(scope, receive, send)
  File "e:\tech\trm-os-branches\.venv\Lib\site-packages\starlette\_exception_handler.py", line 64, in wrapped_app
    raise exc
  File "e:\tech\trm-os-branches\.venv\Lib\site-packages\starlette\_exception_handler.py", line 53, in wrapped_app
    await app(scope, receive, sender)
  File "e:\tech\trm-os-branches\.venv\Lib\site-packages\starlette\routing.py", line 758, in __call__
    await self.middleware_stack(scope, receive, send)
  File "e:\tech\trm-os-branches\.venv\Lib\site-packages\starlette\routing.py", line 778, in app
    await route.handle(scope, receive, send)
  File "e:\tech\trm-os-branches\.venv\Lib\site-packages\starlette\routing.py", line 299, in handle
    await self.app(scope, receive, send)
  File "e:\tech\trm-os-branches\.venv\Lib\site-packages\starlette\routing.py", line 79, in app
    await wrap_app_handling_exceptions(app, request)(scope, receive, send)
  File "e:\tech\trm-os-branches\.venv\Lib\site-packages\starlette\_exception_handler.py", line 64, in wrapped_app
    raise exc
  File "e:\tech\trm-os-branches\.venv\Lib\site-packages\starlette\_exception_handler.py", line 53, in wrapped_app
    await app(scope, receive, sender)
  File "e:\tech\trm-os-branches\.venv\Lib\site-packages\starlette\routing.py", line 74, in app
    response = await func(request)
               ^^^^^^^^^^^^^^^^^^^
  File "e:\tech\trm-os-branches\.venv\Lib\site-packages\fastapi\routing.py", line 278, in app
    raw_response = await run_endpoint_function(
                   ^^^^^^^^^^^^^^^^^^^^^^^^^^^^
  File "e:\tech\trm-os-branches\.venv\Lib\site-packages\fastapi\routing.py", line 193, in run_endpoint_function
    return await run_in_threadpool(dependant.call, **values)
           ^^^^^^^^^^^^^^^^^^^^^^^^^^^^^^^^^^^^^^^^^^^^^^^^^
  File "e:\tech\trm-os-branches\.venv\Lib\site-packages\starlette\concurrency.py", line 42, in run_in_threadpool
    return await anyio.to_thread.run_sync(func, *args)
           ^^^^^^^^^^^^^^^^^^^^^^^^^^^^^^^^^^^^^^^^^^^
  File "e:\tech\trm-os-branches\.venv\Lib\site-packages\anyio\to_thread.py", line 56, in run_sync
    return await get_async_backend().run_sync_in_worker_thread(
           ^^^^^^^^^^^^^^^^^^^^^^^^^^^^^^^^^^^^^^^^^^^^^^^^^^^^
  File "e:\tech\trm-os-branches\.venv\Lib\site-packages\anyio\_backends\_asyncio.py", line 2470, in run_sync_in_worker_thread
    return await future
           ^^^^^^^^^^^^
  File "e:\tech\trm-os-branches\.venv\Lib\site-packages\anyio\_backends\_asyncio.py", line 967, in run
    result = context.run(func, *args)
             ^^^^^^^^^^^^^^^^^^^^^^^^
  File "E:\tech\trm-os-branches\trm_api\api\v1\endpoints\win.py", line 19, in create_win
    return service.create_win(win_create=win_in)
           ^^^^^^^^^^^^^^^^^^^^^^^^^^^^^^^^^^^^^
  File "E:\tech\trm-os-branches\trm_api\services\win_service.py", line 23, in create_win
    # Debug output - log the call stack and original data
               ^^^^^^^^^^^^^
  File "e:\tech\trm-os-branches\.venv\Lib\site-packages\pydantic\main.py", line 253, in __init__
    validated_self = self.__pydantic_validator__.validate_python(data, self_instance=self)
                     ^^^^^^^^^^^^^^^^^^^^^^^^^^^^^^^^^^^^^^^^^^^^^^^^^^^^^^^^^^^^^^^^^^^^^
pydantic_core._pydantic_core.ValidationError: 1 validation error for Win
createdAt
  Input should be a valid datetime [type=datetime_type, input_value=neo4j.time.DateTime(2025,...714134000, tzinfo=<UTC>), input_type=DateTime]
    For further information visit https://errors.pydantic.dev/2.11/v/datetime_type
2025-06-12 18:01:23,471 - uvicorn.error - INFO - Shutting down
2025-06-12 18:01:23,580 - uvicorn.error - INFO - Waiting for application shutdown.
2025-06-12 18:01:23,581 - uvicorn.error - INFO - Application shutdown complete.
2025-06-12 18:01:23,581 - uvicorn.error - INFO - Finished server process [9180]
2025-06-12 18:01:24,376 - uvicorn.error - INFO - Application startup complete.
2025-06-12 18:01:25,285 - uvicorn.access - INFO - 127.0.0.1:51795 - "DELETE /api/v1/projects/130182e2bcb248d3a984c4b3632c4b9d HTTP/1.1" 204
2025-06-12 18:02:33,305 - uvicorn.error - INFO - Shutting down
2025-06-12 18:02:33,414 - uvicorn.error - INFO - Waiting for application shutdown.
2025-06-12 18:02:33,415 - uvicorn.error - INFO - Application shutdown complete.
2025-06-12 18:02:33,416 - uvicorn.error - INFO - Finished server process [34584]
2025-06-12 18:02:34,074 - uvicorn.error - INFO - Application startup complete.
2025-06-12 18:09:55,740 - uvicorn.error - INFO - Application startup complete.
2025-06-12 18:10:41,008 - uvicorn.error - INFO - Shutting down
2025-06-12 18:10:41,119 - uvicorn.error - INFO - Waiting for application shutdown.
2025-06-12 18:10:41,120 - uvicorn.error - INFO - Application shutdown complete.
2025-06-12 18:10:41,121 - uvicorn.error - INFO - Finished server process [7908]
2025-06-12 18:11:25,162 - uvicorn.access - INFO - 127.0.0.1:53279 - "GET /api/v1/users HTTP/1.1" 307
2025-06-12 18:11:25,307 - uvicorn.access - INFO - 127.0.0.1:53279 - "GET /api/v1/users/ HTTP/1.1" 200
2025-06-12 18:11:27,474 - uvicorn.access - INFO - 127.0.0.1:53285 - "POST /api/v1/projects/ HTTP/1.1" 201
2025-06-12 18:11:29,823 - uvicorn.access - INFO - 127.0.0.1:53292 - "POST /api/v1/wins/ HTTP/1.1" 500
2025-06-12 18:11:29,823 - uvicorn.error - ERROR - Exception in ASGI application
Traceback (most recent call last):
  File "e:\tech\trm-os-branches\.venv\Lib\site-packages\uvicorn\protocols\http\httptools_impl.py", line 411, in run_asgi
    result = await app(  # type: ignore[func-returns-value]
             ^^^^^^^^^^^^^^^^^^^^^^^^^^^^^^^^^^^^^^^^^^^^^^
  File "e:\tech\trm-os-branches\.venv\Lib\site-packages\uvicorn\middleware\proxy_headers.py", line 69, in __call__
    return await self.app(scope, receive, send)
           ^^^^^^^^^^^^^^^^^^^^^^^^^^^^^^^^^^^^
  File "e:\tech\trm-os-branches\.venv\Lib\site-packages\fastapi\applications.py", line 1054, in __call__
    await super().__call__(scope, receive, send)
  File "e:\tech\trm-os-branches\.venv\Lib\site-packages\starlette\applications.py", line 123, in __call__
    await self.middleware_stack(scope, receive, send)
  File "e:\tech\trm-os-branches\.venv\Lib\site-packages\starlette\middleware\errors.py", line 186, in __call__
    raise exc
  File "e:\tech\trm-os-branches\.venv\Lib\site-packages\starlette\middleware\errors.py", line 164, in __call__
    await self.app(scope, receive, _send)
  File "e:\tech\trm-os-branches\.venv\Lib\site-packages\starlette\middleware\exceptions.py", line 62, in __call__
    await wrap_app_handling_exceptions(self.app, conn)(scope, receive, send)
  File "e:\tech\trm-os-branches\.venv\Lib\site-packages\starlette\_exception_handler.py", line 64, in wrapped_app
    raise exc
  File "e:\tech\trm-os-branches\.venv\Lib\site-packages\starlette\_exception_handler.py", line 53, in wrapped_app
    await app(scope, receive, sender)
  File "e:\tech\trm-os-branches\.venv\Lib\site-packages\starlette\routing.py", line 758, in __call__
    await self.middleware_stack(scope, receive, send)
  File "e:\tech\trm-os-branches\.venv\Lib\site-packages\starlette\routing.py", line 778, in app
    await route.handle(scope, receive, send)
  File "e:\tech\trm-os-branches\.venv\Lib\site-packages\starlette\routing.py", line 299, in handle
    await self.app(scope, receive, send)
  File "e:\tech\trm-os-branches\.venv\Lib\site-packages\starlette\routing.py", line 79, in app
    await wrap_app_handling_exceptions(app, request)(scope, receive, send)
  File "e:\tech\trm-os-branches\.venv\Lib\site-packages\starlette\_exception_handler.py", line 64, in wrapped_app
    raise exc
  File "e:\tech\trm-os-branches\.venv\Lib\site-packages\starlette\_exception_handler.py", line 53, in wrapped_app
    await app(scope, receive, sender)
  File "e:\tech\trm-os-branches\.venv\Lib\site-packages\starlette\routing.py", line 74, in app
    response = await func(request)
               ^^^^^^^^^^^^^^^^^^^
  File "e:\tech\trm-os-branches\.venv\Lib\site-packages\fastapi\routing.py", line 278, in app
    raw_response = await run_endpoint_function(
                   ^^^^^^^^^^^^^^^^^^^^^^^^^^^^
  File "e:\tech\trm-os-branches\.venv\Lib\site-packages\fastapi\routing.py", line 193, in run_endpoint_function
    return await run_in_threadpool(dependant.call, **values)
           ^^^^^^^^^^^^^^^^^^^^^^^^^^^^^^^^^^^^^^^^^^^^^^^^^
  File "e:\tech\trm-os-branches\.venv\Lib\site-packages\starlette\concurrency.py", line 42, in run_in_threadpool
    return await anyio.to_thread.run_sync(func, *args)
           ^^^^^^^^^^^^^^^^^^^^^^^^^^^^^^^^^^^^^^^^^^^
  File "e:\tech\trm-os-branches\.venv\Lib\site-packages\anyio\to_thread.py", line 56, in run_sync
    return await get_async_backend().run_sync_in_worker_thread(
           ^^^^^^^^^^^^^^^^^^^^^^^^^^^^^^^^^^^^^^^^^^^^^^^^^^^^
  File "e:\tech\trm-os-branches\.venv\Lib\site-packages\anyio\_backends\_asyncio.py", line 2470, in run_sync_in_worker_thread
    return await future
           ^^^^^^^^^^^^
  File "e:\tech\trm-os-branches\.venv\Lib\site-packages\anyio\_backends\_asyncio.py", line 967, in run
    result = context.run(func, *args)
             ^^^^^^^^^^^^^^^^^^^^^^^^
  File "E:\tech\trm-os-branches\trm_api\api\v1\endpoints\win.py", line 19, in create_win
    return service.create_win(win_create=win_in)
           ^^^^^^^^^^^^^^^^^^^^^^^^^^^^^^^^^^^^^
  File "E:\tech\trm-os-branches\trm_api\services\win_service.py", line 23, in create_win
    # Debug output - log the call stack and original data
               ^^^^^^^^^^^^^
  File "e:\tech\trm-os-branches\.venv\Lib\site-packages\pydantic\main.py", line 253, in __init__
    validated_self = self.__pydantic_validator__.validate_python(data, self_instance=self)
                     ^^^^^^^^^^^^^^^^^^^^^^^^^^^^^^^^^^^^^^^^^^^^^^^^^^^^^^^^^^^^^^^^^^^^^
pydantic_core._pydantic_core.ValidationError: 1 validation error for Win
createdAt
  Input should be a valid datetime [type=datetime_type, input_value=neo4j.time.DateTime(2025,...520947000, tzinfo=<UTC>), input_type=DateTime]
    For further information visit https://errors.pydantic.dev/2.11/v/datetime_type
2025-06-12 18:11:32,089 - uvicorn.access - INFO - 127.0.0.1:53299 - "DELETE /api/v1/projects/ae880ab9b8304ce1b1931a5ad2b3b80d HTTP/1.1" 204
2025-06-12 18:14:16,715 - uvicorn.error - INFO - Shutting down
2025-06-12 18:14:16,825 - uvicorn.error - INFO - Waiting for application shutdown.
2025-06-12 18:14:16,825 - uvicorn.error - INFO - Application shutdown complete.
2025-06-12 18:14:16,826 - uvicorn.error - INFO - Finished server process [33652]
2025-06-12 18:16:55,769 - uvicorn.error - INFO - Application startup complete.
2025-06-12 18:17:15,676 - uvicorn.error - INFO - Shutting down
2025-06-12 18:17:15,786 - uvicorn.error - INFO - Waiting for application shutdown.
2025-06-12 18:17:15,787 - uvicorn.error - INFO - Application shutdown complete.
2025-06-12 18:17:15,787 - uvicorn.error - INFO - Finished server process [340]
2025-06-12 18:24:53,747 - uvicorn.error - INFO - Application startup complete.
2025-06-12 18:28:21,986 - uvicorn.access - INFO - 127.0.0.1:55894 - "GET /api/v1/users HTTP/1.1" 307
2025-06-12 18:28:22,132 - uvicorn.access - INFO - 127.0.0.1:55894 - "GET /api/v1/users/ HTTP/1.1" 200
2025-06-12 18:28:24,296 - uvicorn.access - INFO - 127.0.0.1:55902 - "POST /api/v1/projects/ HTTP/1.1" 201
2025-06-12 18:28:26,666 - uvicorn.access - INFO - 127.0.0.1:55909 - "POST /api/v1/wins/ HTTP/1.1" 500
2025-06-12 18:28:26,666 - uvicorn.error - ERROR - Exception in ASGI application
Traceback (most recent call last):
  File "e:\tech\trm-os-branches\.venv\Lib\site-packages\uvicorn\protocols\http\httptools_impl.py", line 411, in run_asgi
    result = await app(  # type: ignore[func-returns-value]
             ^^^^^^^^^^^^^^^^^^^^^^^^^^^^^^^^^^^^^^^^^^^^^^
  File "e:\tech\trm-os-branches\.venv\Lib\site-packages\uvicorn\middleware\proxy_headers.py", line 69, in __call__
    return await self.app(scope, receive, send)
           ^^^^^^^^^^^^^^^^^^^^^^^^^^^^^^^^^^^^
  File "e:\tech\trm-os-branches\.venv\Lib\site-packages\fastapi\applications.py", line 1054, in __call__
    await super().__call__(scope, receive, send)
  File "e:\tech\trm-os-branches\.venv\Lib\site-packages\starlette\applications.py", line 123, in __call__
    await self.middleware_stack(scope, receive, send)
  File "e:\tech\trm-os-branches\.venv\Lib\site-packages\starlette\middleware\errors.py", line 186, in __call__
    raise exc
  File "e:\tech\trm-os-branches\.venv\Lib\site-packages\starlette\middleware\errors.py", line 164, in __call__
    await self.app(scope, receive, _send)
  File "e:\tech\trm-os-branches\.venv\Lib\site-packages\starlette\middleware\exceptions.py", line 62, in __call__
    await wrap_app_handling_exceptions(self.app, conn)(scope, receive, send)
  File "e:\tech\trm-os-branches\.venv\Lib\site-packages\starlette\_exception_handler.py", line 64, in wrapped_app
    raise exc
  File "e:\tech\trm-os-branches\.venv\Lib\site-packages\starlette\_exception_handler.py", line 53, in wrapped_app
    await app(scope, receive, sender)
  File "e:\tech\trm-os-branches\.venv\Lib\site-packages\starlette\routing.py", line 758, in __call__
    await self.middleware_stack(scope, receive, send)
  File "e:\tech\trm-os-branches\.venv\Lib\site-packages\starlette\routing.py", line 778, in app
    await route.handle(scope, receive, send)
  File "e:\tech\trm-os-branches\.venv\Lib\site-packages\starlette\routing.py", line 299, in handle
    await self.app(scope, receive, send)
  File "e:\tech\trm-os-branches\.venv\Lib\site-packages\starlette\routing.py", line 79, in app
    await wrap_app_handling_exceptions(app, request)(scope, receive, send)
  File "e:\tech\trm-os-branches\.venv\Lib\site-packages\starlette\_exception_handler.py", line 64, in wrapped_app
    raise exc
  File "e:\tech\trm-os-branches\.venv\Lib\site-packages\starlette\_exception_handler.py", line 53, in wrapped_app
    await app(scope, receive, sender)
  File "e:\tech\trm-os-branches\.venv\Lib\site-packages\starlette\routing.py", line 74, in app
    response = await func(request)
               ^^^^^^^^^^^^^^^^^^^
  File "e:\tech\trm-os-branches\.venv\Lib\site-packages\fastapi\routing.py", line 278, in app
    raw_response = await run_endpoint_function(
                   ^^^^^^^^^^^^^^^^^^^^^^^^^^^^
  File "e:\tech\trm-os-branches\.venv\Lib\site-packages\fastapi\routing.py", line 193, in run_endpoint_function
    return await run_in_threadpool(dependant.call, **values)
           ^^^^^^^^^^^^^^^^^^^^^^^^^^^^^^^^^^^^^^^^^^^^^^^^^
  File "e:\tech\trm-os-branches\.venv\Lib\site-packages\starlette\concurrency.py", line 42, in run_in_threadpool
    return await anyio.to_thread.run_sync(func, *args)
           ^^^^^^^^^^^^^^^^^^^^^^^^^^^^^^^^^^^^^^^^^^^
  File "e:\tech\trm-os-branches\.venv\Lib\site-packages\anyio\to_thread.py", line 56, in run_sync
    return await get_async_backend().run_sync_in_worker_thread(
           ^^^^^^^^^^^^^^^^^^^^^^^^^^^^^^^^^^^^^^^^^^^^^^^^^^^^
  File "e:\tech\trm-os-branches\.venv\Lib\site-packages\anyio\_backends\_asyncio.py", line 2470, in run_sync_in_worker_thread
    return await future
           ^^^^^^^^^^^^
  File "e:\tech\trm-os-branches\.venv\Lib\site-packages\anyio\_backends\_asyncio.py", line 967, in run
    result = context.run(func, *args)
             ^^^^^^^^^^^^^^^^^^^^^^^^
  File "E:\tech\trm-os-branches\trm_api\api\v1\endpoints\win.py", line 19, in create_win
    return service.create_win(win_create=win_in)
           ^^^^^^^^^^^^^^^^^^^^^^^^^^^^^^^^^^^^^
  File "E:\tech\trm-os-branches\trm_api\services\win_service.py", line 23, in create_win
    # Debug output - log the call stack and original data
               ^^^^^^^^^^^^^
  File "e:\tech\trm-os-branches\.venv\Lib\site-packages\pydantic\main.py", line 253, in __init__
    validated_self = self.__pydantic_validator__.validate_python(data, self_instance=self)
                     ^^^^^^^^^^^^^^^^^^^^^^^^^^^^^^^^^^^^^^^^^^^^^^^^^^^^^^^^^^^^^^^^^^^^^
pydantic_core._pydantic_core.ValidationError: 1 validation error for Win
createdAt
  Input should be a valid datetime [type=datetime_type, input_value=neo4j.time.DateTime(2025,...343127000, tzinfo=<UTC>), input_type=DateTime]
    For further information visit https://errors.pydantic.dev/2.11/v/datetime_type
2025-06-12 18:28:28,923 - uvicorn.access - INFO - 127.0.0.1:55916 - "DELETE /api/v1/projects/c349516bba7046b68f54bb337986ea4a HTTP/1.1" 204
2025-06-12 18:33:30,628 - uvicorn.error - INFO - Application startup complete.
2025-06-12 18:33:54,091 - uvicorn.error - INFO - Shutting down
2025-06-12 18:33:54,201 - uvicorn.error - INFO - Waiting for application shutdown.
2025-06-12 18:33:54,201 - uvicorn.error - INFO - Application shutdown complete.
2025-06-12 18:33:54,201 - uvicorn.error - INFO - Finished server process [32084]
2025-06-12 19:25:20,309 - uvicorn.error - INFO - Application startup complete.
2025-06-12 19:26:09,775 - uvicorn.error - INFO - Shutting down
2025-06-12 19:26:09,883 - uvicorn.error - INFO - Waiting for application shutdown.
2025-06-12 19:26:09,883 - uvicorn.error - INFO - Application shutdown complete.
2025-06-12 19:26:09,883 - uvicorn.error - INFO - Finished server process [34996]
2025-06-12 19:26:48,877 - uvicorn.access - INFO - 127.0.0.1:50117 - "GET /api/v1/users HTTP/1.1" 307
2025-06-12 19:26:50,132 - uvicorn.access - INFO - 127.0.0.1:50117 - "GET /api/v1/users/ HTTP/1.1" 200
2025-06-12 19:26:52,338 - uvicorn.access - INFO - 127.0.0.1:50130 - "POST /api/v1/projects/ HTTP/1.1" 201
2025-06-12 19:26:55,211 - uvicorn.access - INFO - 127.0.0.1:50136 - "POST /api/v1/wins/ HTTP/1.1" 500
2025-06-12 19:26:55,211 - uvicorn.error - ERROR - Exception in ASGI application
Traceback (most recent call last):
  File "e:\tech\trm-os-branches\.venv\Lib\site-packages\uvicorn\protocols\http\httptools_impl.py", line 411, in run_asgi
    result = await app(  # type: ignore[func-returns-value]
             ^^^^^^^^^^^^^^^^^^^^^^^^^^^^^^^^^^^^^^^^^^^^^^
  File "e:\tech\trm-os-branches\.venv\Lib\site-packages\uvicorn\middleware\proxy_headers.py", line 69, in __call__
    return await self.app(scope, receive, send)
           ^^^^^^^^^^^^^^^^^^^^^^^^^^^^^^^^^^^^
  File "e:\tech\trm-os-branches\.venv\Lib\site-packages\fastapi\applications.py", line 1054, in __call__
    await super().__call__(scope, receive, send)
  File "e:\tech\trm-os-branches\.venv\Lib\site-packages\starlette\applications.py", line 123, in __call__
    await self.middleware_stack(scope, receive, send)
  File "e:\tech\trm-os-branches\.venv\Lib\site-packages\starlette\middleware\errors.py", line 186, in __call__
    raise exc
  File "e:\tech\trm-os-branches\.venv\Lib\site-packages\starlette\middleware\errors.py", line 164, in __call__
    await self.app(scope, receive, _send)
  File "e:\tech\trm-os-branches\.venv\Lib\site-packages\starlette\middleware\exceptions.py", line 62, in __call__
    await wrap_app_handling_exceptions(self.app, conn)(scope, receive, send)
  File "e:\tech\trm-os-branches\.venv\Lib\site-packages\starlette\_exception_handler.py", line 64, in wrapped_app
    raise exc
  File "e:\tech\trm-os-branches\.venv\Lib\site-packages\starlette\_exception_handler.py", line 53, in wrapped_app
    await app(scope, receive, sender)
  File "e:\tech\trm-os-branches\.venv\Lib\site-packages\starlette\routing.py", line 758, in __call__
    await self.middleware_stack(scope, receive, send)
  File "e:\tech\trm-os-branches\.venv\Lib\site-packages\starlette\routing.py", line 778, in app
    await route.handle(scope, receive, send)
  File "e:\tech\trm-os-branches\.venv\Lib\site-packages\starlette\routing.py", line 299, in handle
    await self.app(scope, receive, send)
  File "e:\tech\trm-os-branches\.venv\Lib\site-packages\starlette\routing.py", line 79, in app
    await wrap_app_handling_exceptions(app, request)(scope, receive, send)
  File "e:\tech\trm-os-branches\.venv\Lib\site-packages\starlette\_exception_handler.py", line 64, in wrapped_app
    raise exc
  File "e:\tech\trm-os-branches\.venv\Lib\site-packages\starlette\_exception_handler.py", line 53, in wrapped_app
    await app(scope, receive, sender)
  File "e:\tech\trm-os-branches\.venv\Lib\site-packages\starlette\routing.py", line 74, in app
    response = await func(request)
               ^^^^^^^^^^^^^^^^^^^
  File "e:\tech\trm-os-branches\.venv\Lib\site-packages\fastapi\routing.py", line 278, in app
    raw_response = await run_endpoint_function(
                   ^^^^^^^^^^^^^^^^^^^^^^^^^^^^
  File "e:\tech\trm-os-branches\.venv\Lib\site-packages\fastapi\routing.py", line 193, in run_endpoint_function
    return await run_in_threadpool(dependant.call, **values)
           ^^^^^^^^^^^^^^^^^^^^^^^^^^^^^^^^^^^^^^^^^^^^^^^^^
  File "e:\tech\trm-os-branches\.venv\Lib\site-packages\starlette\concurrency.py", line 42, in run_in_threadpool
    return await anyio.to_thread.run_sync(func, *args)
           ^^^^^^^^^^^^^^^^^^^^^^^^^^^^^^^^^^^^^^^^^^^
  File "e:\tech\trm-os-branches\.venv\Lib\site-packages\anyio\to_thread.py", line 56, in run_sync
    return await get_async_backend().run_sync_in_worker_thread(
           ^^^^^^^^^^^^^^^^^^^^^^^^^^^^^^^^^^^^^^^^^^^^^^^^^^^^
  File "e:\tech\trm-os-branches\.venv\Lib\site-packages\anyio\_backends\_asyncio.py", line 2470, in run_sync_in_worker_thread
    return await future
           ^^^^^^^^^^^^
  File "e:\tech\trm-os-branches\.venv\Lib\site-packages\anyio\_backends\_asyncio.py", line 967, in run
    result = context.run(func, *args)
             ^^^^^^^^^^^^^^^^^^^^^^^^
  File "E:\tech\trm-os-branches\trm_api\api\v1\endpoints\win.py", line 19, in create_win
    return service.create_win(win_create=win_in)
           ^^^^^^^^^^^^^^^^^^^^^^^^^^^^^^^^^^^^^
  File "E:\tech\trm-os-branches\trm_api\services\win_service.py", line 23, in create_win
    # Handle None
               ^^
  File "e:\tech\trm-os-branches\.venv\Lib\site-packages\pydantic\main.py", line 253, in __init__
    validated_self = self.__pydantic_validator__.validate_python(data, self_instance=self)
                     ^^^^^^^^^^^^^^^^^^^^^^^^^^^^^^^^^^^^^^^^^^^^^^^^^^^^^^^^^^^^^^^^^^^^^
pydantic_core._pydantic_core.ValidationError: 1 validation error for Win
createdAt
  Input should be a valid datetime [type=datetime_type, input_value=neo4j.time.DateTime(2025,...385144000, tzinfo=<UTC>), input_type=DateTime]
    For further information visit https://errors.pydantic.dev/2.11/v/datetime_type
2025-06-12 19:26:57,577 - uvicorn.access - INFO - 127.0.0.1:50154 - "DELETE /api/v1/projects/5e0101554bb240d5bb8ec09e6af4b6b8 HTTP/1.1" 204
2025-06-12 19:27:33,046 - uvicorn.access - INFO - 127.0.0.1:50272 - "GET /api/v1/users HTTP/1.1" 307
2025-06-12 19:27:33,209 - uvicorn.access - INFO - 127.0.0.1:50272 - "GET /api/v1/users/ HTTP/1.1" 200
2025-06-12 19:27:35,428 - uvicorn.access - INFO - 127.0.0.1:50279 - "POST /api/v1/projects/ HTTP/1.1" 201
2025-06-12 19:27:37,698 - uvicorn.access - INFO - 127.0.0.1:50288 - "POST /api/v1/wins/ HTTP/1.1" 500
2025-06-12 19:27:37,699 - uvicorn.error - ERROR - Exception in ASGI application
Traceback (most recent call last):
  File "e:\tech\trm-os-branches\.venv\Lib\site-packages\uvicorn\protocols\http\httptools_impl.py", line 411, in run_asgi
    result = await app(  # type: ignore[func-returns-value]
             ^^^^^^^^^^^^^^^^^^^^^^^^^^^^^^^^^^^^^^^^^^^^^^
  File "e:\tech\trm-os-branches\.venv\Lib\site-packages\uvicorn\middleware\proxy_headers.py", line 69, in __call__
    return await self.app(scope, receive, send)
           ^^^^^^^^^^^^^^^^^^^^^^^^^^^^^^^^^^^^
  File "e:\tech\trm-os-branches\.venv\Lib\site-packages\fastapi\applications.py", line 1054, in __call__
    await super().__call__(scope, receive, send)
  File "e:\tech\trm-os-branches\.venv\Lib\site-packages\starlette\applications.py", line 123, in __call__
    await self.middleware_stack(scope, receive, send)
  File "e:\tech\trm-os-branches\.venv\Lib\site-packages\starlette\middleware\errors.py", line 186, in __call__
    raise exc
  File "e:\tech\trm-os-branches\.venv\Lib\site-packages\starlette\middleware\errors.py", line 164, in __call__
    await self.app(scope, receive, _send)
  File "e:\tech\trm-os-branches\.venv\Lib\site-packages\starlette\middleware\exceptions.py", line 62, in __call__
    await wrap_app_handling_exceptions(self.app, conn)(scope, receive, send)
  File "e:\tech\trm-os-branches\.venv\Lib\site-packages\starlette\_exception_handler.py", line 64, in wrapped_app
    raise exc
  File "e:\tech\trm-os-branches\.venv\Lib\site-packages\starlette\_exception_handler.py", line 53, in wrapped_app
    await app(scope, receive, sender)
  File "e:\tech\trm-os-branches\.venv\Lib\site-packages\starlette\routing.py", line 758, in __call__
    await self.middleware_stack(scope, receive, send)
  File "e:\tech\trm-os-branches\.venv\Lib\site-packages\starlette\routing.py", line 778, in app
    await route.handle(scope, receive, send)
  File "e:\tech\trm-os-branches\.venv\Lib\site-packages\starlette\routing.py", line 299, in handle
    await self.app(scope, receive, send)
  File "e:\tech\trm-os-branches\.venv\Lib\site-packages\starlette\routing.py", line 79, in app
    await wrap_app_handling_exceptions(app, request)(scope, receive, send)
  File "e:\tech\trm-os-branches\.venv\Lib\site-packages\starlette\_exception_handler.py", line 64, in wrapped_app
    raise exc
  File "e:\tech\trm-os-branches\.venv\Lib\site-packages\starlette\_exception_handler.py", line 53, in wrapped_app
    await app(scope, receive, sender)
  File "e:\tech\trm-os-branches\.venv\Lib\site-packages\starlette\routing.py", line 74, in app
    response = await func(request)
               ^^^^^^^^^^^^^^^^^^^
  File "e:\tech\trm-os-branches\.venv\Lib\site-packages\fastapi\routing.py", line 278, in app
    raw_response = await run_endpoint_function(
                   ^^^^^^^^^^^^^^^^^^^^^^^^^^^^
  File "e:\tech\trm-os-branches\.venv\Lib\site-packages\fastapi\routing.py", line 193, in run_endpoint_function
    return await run_in_threadpool(dependant.call, **values)
           ^^^^^^^^^^^^^^^^^^^^^^^^^^^^^^^^^^^^^^^^^^^^^^^^^
  File "e:\tech\trm-os-branches\.venv\Lib\site-packages\starlette\concurrency.py", line 42, in run_in_threadpool
    return await anyio.to_thread.run_sync(func, *args)
           ^^^^^^^^^^^^^^^^^^^^^^^^^^^^^^^^^^^^^^^^^^^
  File "e:\tech\trm-os-branches\.venv\Lib\site-packages\anyio\to_thread.py", line 56, in run_sync
    return await get_async_backend().run_sync_in_worker_thread(
           ^^^^^^^^^^^^^^^^^^^^^^^^^^^^^^^^^^^^^^^^^^^^^^^^^^^^
  File "e:\tech\trm-os-branches\.venv\Lib\site-packages\anyio\_backends\_asyncio.py", line 2470, in run_sync_in_worker_thread
    return await future
           ^^^^^^^^^^^^
  File "e:\tech\trm-os-branches\.venv\Lib\site-packages\anyio\_backends\_asyncio.py", line 967, in run
    result = context.run(func, *args)
             ^^^^^^^^^^^^^^^^^^^^^^^^
  File "E:\tech\trm-os-branches\trm_api\api\v1\endpoints\win.py", line 19, in create_win
    return service.create_win(win_create=win_in)
           ^^^^^^^^^^^^^^^^^^^^^^^^^^^^^^^^^^^^^
  File "E:\tech\trm-os-branches\trm_api\services\win_service.py", line 23, in create_win
    # Handle None
               ^^
  File "e:\tech\trm-os-branches\.venv\Lib\site-packages\pydantic\main.py", line 253, in __init__
    validated_self = self.__pydantic_validator__.validate_python(data, self_instance=self)
                     ^^^^^^^^^^^^^^^^^^^^^^^^^^^^^^^^^^^^^^^^^^^^^^^^^^^^^^^^^^^^^^^^^^^^^
pydantic_core._pydantic_core.ValidationError: 1 validation error for Win
createdAt
  Input should be a valid datetime [type=datetime_type, input_value=neo4j.time.DateTime(2025,...483274000, tzinfo=<UTC>), input_type=DateTime]
    For further information visit https://errors.pydantic.dev/2.11/v/datetime_type
2025-06-12 19:27:40,065 - uvicorn.access - INFO - 127.0.0.1:50294 - "DELETE /api/v1/projects/940e3a712615498d85d8ce036b7dc094 HTTP/1.1" 204
2025-06-12 19:28:59,814 - uvicorn.access - INFO - 127.0.0.1:50503 - "GET /api/v1/users HTTP/1.1" 307
2025-06-12 19:29:00,104 - uvicorn.access - INFO - 127.0.0.1:50503 - "GET /api/v1/users/ HTTP/1.1" 200
2025-06-12 19:29:02,323 - uvicorn.access - INFO - 127.0.0.1:50510 - "POST /api/v1/projects/ HTTP/1.1" 201
2025-06-12 19:29:04,590 - uvicorn.access - INFO - 127.0.0.1:50517 - "POST /api/v1/wins/ HTTP/1.1" 500
2025-06-12 19:29:04,590 - uvicorn.error - ERROR - Exception in ASGI application
Traceback (most recent call last):
  File "e:\tech\trm-os-branches\.venv\Lib\site-packages\uvicorn\protocols\http\httptools_impl.py", line 411, in run_asgi
    result = await app(  # type: ignore[func-returns-value]
             ^^^^^^^^^^^^^^^^^^^^^^^^^^^^^^^^^^^^^^^^^^^^^^
  File "e:\tech\trm-os-branches\.venv\Lib\site-packages\uvicorn\middleware\proxy_headers.py", line 69, in __call__
    return await self.app(scope, receive, send)
           ^^^^^^^^^^^^^^^^^^^^^^^^^^^^^^^^^^^^
  File "e:\tech\trm-os-branches\.venv\Lib\site-packages\fastapi\applications.py", line 1054, in __call__
    await super().__call__(scope, receive, send)
  File "e:\tech\trm-os-branches\.venv\Lib\site-packages\starlette\applications.py", line 123, in __call__
    await self.middleware_stack(scope, receive, send)
  File "e:\tech\trm-os-branches\.venv\Lib\site-packages\starlette\middleware\errors.py", line 186, in __call__
    raise exc
  File "e:\tech\trm-os-branches\.venv\Lib\site-packages\starlette\middleware\errors.py", line 164, in __call__
    await self.app(scope, receive, _send)
  File "e:\tech\trm-os-branches\.venv\Lib\site-packages\starlette\middleware\exceptions.py", line 62, in __call__
    await wrap_app_handling_exceptions(self.app, conn)(scope, receive, send)
  File "e:\tech\trm-os-branches\.venv\Lib\site-packages\starlette\_exception_handler.py", line 64, in wrapped_app
    raise exc
  File "e:\tech\trm-os-branches\.venv\Lib\site-packages\starlette\_exception_handler.py", line 53, in wrapped_app
    await app(scope, receive, sender)
  File "e:\tech\trm-os-branches\.venv\Lib\site-packages\starlette\routing.py", line 758, in __call__
    await self.middleware_stack(scope, receive, send)
  File "e:\tech\trm-os-branches\.venv\Lib\site-packages\starlette\routing.py", line 778, in app
    await route.handle(scope, receive, send)
  File "e:\tech\trm-os-branches\.venv\Lib\site-packages\starlette\routing.py", line 299, in handle
    await self.app(scope, receive, send)
  File "e:\tech\trm-os-branches\.venv\Lib\site-packages\starlette\routing.py", line 79, in app
    await wrap_app_handling_exceptions(app, request)(scope, receive, send)
  File "e:\tech\trm-os-branches\.venv\Lib\site-packages\starlette\_exception_handler.py", line 64, in wrapped_app
    raise exc
  File "e:\tech\trm-os-branches\.venv\Lib\site-packages\starlette\_exception_handler.py", line 53, in wrapped_app
    await app(scope, receive, sender)
  File "e:\tech\trm-os-branches\.venv\Lib\site-packages\starlette\routing.py", line 74, in app
    response = await func(request)
               ^^^^^^^^^^^^^^^^^^^
  File "e:\tech\trm-os-branches\.venv\Lib\site-packages\fastapi\routing.py", line 278, in app
    raw_response = await run_endpoint_function(
                   ^^^^^^^^^^^^^^^^^^^^^^^^^^^^
  File "e:\tech\trm-os-branches\.venv\Lib\site-packages\fastapi\routing.py", line 193, in run_endpoint_function
    return await run_in_threadpool(dependant.call, **values)
           ^^^^^^^^^^^^^^^^^^^^^^^^^^^^^^^^^^^^^^^^^^^^^^^^^
  File "e:\tech\trm-os-branches\.venv\Lib\site-packages\starlette\concurrency.py", line 42, in run_in_threadpool
    return await anyio.to_thread.run_sync(func, *args)
           ^^^^^^^^^^^^^^^^^^^^^^^^^^^^^^^^^^^^^^^^^^^
  File "e:\tech\trm-os-branches\.venv\Lib\site-packages\anyio\to_thread.py", line 56, in run_sync
    return await get_async_backend().run_sync_in_worker_thread(
           ^^^^^^^^^^^^^^^^^^^^^^^^^^^^^^^^^^^^^^^^^^^^^^^^^^^^
  File "e:\tech\trm-os-branches\.venv\Lib\site-packages\anyio\_backends\_asyncio.py", line 2470, in run_sync_in_worker_thread
    return await future
           ^^^^^^^^^^^^
  File "e:\tech\trm-os-branches\.venv\Lib\site-packages\anyio\_backends\_asyncio.py", line 967, in run
    result = context.run(func, *args)
             ^^^^^^^^^^^^^^^^^^^^^^^^
  File "E:\tech\trm-os-branches\trm_api\api\v1\endpoints\win.py", line 19, in create_win
    return service.create_win(win_create=win_in)
           ^^^^^^^^^^^^^^^^^^^^^^^^^^^^^^^^^^^^^
  File "E:\tech\trm-os-branches\trm_api\services\win_service.py", line 23, in create_win
    # Handle None
               ^^
  File "e:\tech\trm-os-branches\.venv\Lib\site-packages\pydantic\main.py", line 253, in __init__
    validated_self = self.__pydantic_validator__.validate_python(data, self_instance=self)
                     ^^^^^^^^^^^^^^^^^^^^^^^^^^^^^^^^^^^^^^^^^^^^^^^^^^^^^^^^^^^^^^^^^^^^^
pydantic_core._pydantic_core.ValidationError: 1 validation error for Win
createdAt
  Input should be a valid datetime [type=datetime_type, input_value=neo4j.time.DateTime(2025,...377483000, tzinfo=<UTC>), input_type=DateTime]
    For further information visit https://errors.pydantic.dev/2.11/v/datetime_type
2025-06-12 19:29:06,977 - uvicorn.access - INFO - 127.0.0.1:50524 - "DELETE /api/v1/projects/0dad911c4233438f861350f4fa4cd194 HTTP/1.1" 204
2025-06-12 19:32:13,120 - uvicorn.access - INFO - 127.0.0.1:51075 - "GET /api/v1/ HTTP/1.1" 404
2025-06-12 19:32:15,357 - uvicorn.access - INFO - 127.0.0.1:51084 - "POST /api/v1/projects/ HTTP/1.1" 201
2025-06-12 19:32:17,397 - uvicorn.access - INFO - 127.0.0.1:51092 - "POST /api/v1/tensions/ HTTP/1.1" 422
2025-06-12 19:32:19,763 - uvicorn.access - INFO - 127.0.0.1:51098 - "DELETE /api/v1/projects/d819d236713e4b9abcfc9dec76526b28 HTTP/1.1" 204
2025-06-12 19:34:47,380 - uvicorn.access - INFO - 127.0.0.1:51346 - "GET /api/v1/users HTTP/1.1" 307
2025-06-12 19:34:47,541 - uvicorn.access - INFO - 127.0.0.1:51346 - "GET /api/v1/users/ HTTP/1.1" 200
2025-06-12 19:34:50,267 - uvicorn.access - INFO - 127.0.0.1:51350 - "POST /api/v1/users/ HTTP/1.1" 201
2025-06-12 19:34:52,482 - uvicorn.access - INFO - 127.0.0.1:51354 - "POST /api/v1/projects/ HTTP/1.1" 201
2025-06-12 19:34:54,930 - uvicorn.access - INFO - 127.0.0.1:51359 - "POST /api/v1/tasks/ HTTP/1.1" 500
2025-06-12 19:34:54,931 - uvicorn.error - ERROR - Exception in ASGI application
Traceback (most recent call last):
  File "e:\tech\trm-os-branches\.venv\Lib\site-packages\uvicorn\protocols\http\httptools_impl.py", line 411, in run_asgi
    result = await app(  # type: ignore[func-returns-value]
             ^^^^^^^^^^^^^^^^^^^^^^^^^^^^^^^^^^^^^^^^^^^^^^
  File "e:\tech\trm-os-branches\.venv\Lib\site-packages\uvicorn\middleware\proxy_headers.py", line 69, in __call__
    return await self.app(scope, receive, send)
           ^^^^^^^^^^^^^^^^^^^^^^^^^^^^^^^^^^^^
  File "e:\tech\trm-os-branches\.venv\Lib\site-packages\fastapi\applications.py", line 1054, in __call__
    await super().__call__(scope, receive, send)
  File "e:\tech\trm-os-branches\.venv\Lib\site-packages\starlette\applications.py", line 123, in __call__
    await self.middleware_stack(scope, receive, send)
  File "e:\tech\trm-os-branches\.venv\Lib\site-packages\starlette\middleware\errors.py", line 186, in __call__
    raise exc
  File "e:\tech\trm-os-branches\.venv\Lib\site-packages\starlette\middleware\errors.py", line 164, in __call__
    await self.app(scope, receive, _send)
  File "e:\tech\trm-os-branches\.venv\Lib\site-packages\starlette\middleware\exceptions.py", line 62, in __call__
    await wrap_app_handling_exceptions(self.app, conn)(scope, receive, send)
  File "e:\tech\trm-os-branches\.venv\Lib\site-packages\starlette\_exception_handler.py", line 64, in wrapped_app
    raise exc
  File "e:\tech\trm-os-branches\.venv\Lib\site-packages\starlette\_exception_handler.py", line 53, in wrapped_app
    await app(scope, receive, sender)
  File "e:\tech\trm-os-branches\.venv\Lib\site-packages\starlette\routing.py", line 758, in __call__
    await self.middleware_stack(scope, receive, send)
  File "e:\tech\trm-os-branches\.venv\Lib\site-packages\starlette\routing.py", line 778, in app
    await route.handle(scope, receive, send)
  File "e:\tech\trm-os-branches\.venv\Lib\site-packages\starlette\routing.py", line 299, in handle
    await self.app(scope, receive, send)
  File "e:\tech\trm-os-branches\.venv\Lib\site-packages\starlette\routing.py", line 79, in app
    await wrap_app_handling_exceptions(app, request)(scope, receive, send)
  File "e:\tech\trm-os-branches\.venv\Lib\site-packages\starlette\_exception_handler.py", line 64, in wrapped_app
    raise exc
  File "e:\tech\trm-os-branches\.venv\Lib\site-packages\starlette\_exception_handler.py", line 53, in wrapped_app
    await app(scope, receive, sender)
  File "e:\tech\trm-os-branches\.venv\Lib\site-packages\starlette\routing.py", line 74, in app
    response = await func(request)
               ^^^^^^^^^^^^^^^^^^^
  File "e:\tech\trm-os-branches\.venv\Lib\site-packages\fastapi\routing.py", line 278, in app
    raw_response = await run_endpoint_function(
                   ^^^^^^^^^^^^^^^^^^^^^^^^^^^^
  File "e:\tech\trm-os-branches\.venv\Lib\site-packages\fastapi\routing.py", line 193, in run_endpoint_function
    return await run_in_threadpool(dependant.call, **values)
           ^^^^^^^^^^^^^^^^^^^^^^^^^^^^^^^^^^^^^^^^^^^^^^^^^
  File "e:\tech\trm-os-branches\.venv\Lib\site-packages\starlette\concurrency.py", line 42, in run_in_threadpool
    return await anyio.to_thread.run_sync(func, *args)
           ^^^^^^^^^^^^^^^^^^^^^^^^^^^^^^^^^^^^^^^^^^^
  File "e:\tech\trm-os-branches\.venv\Lib\site-packages\anyio\to_thread.py", line 56, in run_sync
    return await get_async_backend().run_sync_in_worker_thread(
           ^^^^^^^^^^^^^^^^^^^^^^^^^^^^^^^^^^^^^^^^^^^^^^^^^^^^
  File "e:\tech\trm-os-branches\.venv\Lib\site-packages\anyio\_backends\_asyncio.py", line 2470, in run_sync_in_worker_thread
    return await future
           ^^^^^^^^^^^^
  File "e:\tech\trm-os-branches\.venv\Lib\site-packages\anyio\_backends\_asyncio.py", line 967, in run
    result = context.run(func, *args)
             ^^^^^^^^^^^^^^^^^^^^^^^^
  File "E:\tech\trm-os-branches\trm_api\api\v1\endpoints\task.py", line 36, in create_task
    created_task = repo.create_task(task_data=task_in)
                   ^^^^^^^^^^^^^^^^^^^^^^^^^^^^^^^^^^^
  File "e:\tech\trm-os-branches\.venv\Lib\site-packages\neomodel\sync_\core.py", line 962, in wrapper
    return func(*args, **kwargs)
           ^^^^^^^^^^^^^^^^^^^^^
  File "E:\tech\trm-os-branches\trm_api\repositories\task_repository.py", line 39, in create_task
    project.tasks.connect(new_task)
  File "e:\tech\trm-os-branches\.venv\Lib\site-packages\neomodel\sync_\relationship_manager.py", line 32, in checker
    return fn(self, *args, **kwargs)
           ^^^^^^^^^^^^^^^^^^^^^^^^^
  File "e:\tech\trm-os-branches\.venv\Lib\site-packages\neomodel\sync_\relationship_manager.py", line 106, in connect
    for prop, val in rel_model.deflate(tmp.__properties__).items():
                     ^^^^^^^^^^^^^^^^^^^^^^^^^^^^^^^^^^^^^
  File "e:\tech\trm-os-branches\.venv\Lib\site-packages\neomodel\sync_\property_manager.py", line 93, in deflate
    raise RequiredProperty(name, cls)
neomodel.exceptions.RequiredProperty: property 'relationshipId' on objects of class IsPartOfProjectRel
2025-06-12 19:34:57,310 - uvicorn.access - INFO - 127.0.0.1:51364 - "DELETE /api/v1/projects/1fd8a40526a74ebab58a092bfcc608c1 HTTP/1.1" 204
2025-06-12 19:34:59,691 - uvicorn.access - INFO - 127.0.0.1:51369 - "DELETE /api/v1/users/5ab110e475674977a3d5f5a811c99c96 HTTP/1.1" 204
