2025-07-03 22:39:19,765 - uvicorn.error - INFO - Application startup complete.
2025-07-03 22:39:19,765 - uvicorn.error - INFO - Uvicorn running on http://127.0.0.1:8001 (Press CTRL+C to quit)
2025-07-03 22:39:23,185 - uvicorn.access - INFO - 127.0.0.1:57121 - "GET /docs HTTP/1.1" 200
2025-07-03 22:39:23,673 - uvicorn.access - INFO - 127.0.0.1:57121 - "GET /api/v1/openapi.json HTTP/1.1" 200
2025-07-03 22:39:25,583 - uvicorn.access - INFO - 127.0.0.1:57121 - "GET /api/v1/openapi.json HTTP/1.1" 200
2025-07-03 22:39:25,823 - uvicorn.access - INFO - 127.0.0.1:57121 - "GET /favicon.ico HTTP/1.1" 404
2025-07-03 23:02:17,264 - uvicorn.access - INFO - 127.0.0.1:63143 - "GET /docs HTTP/1.1" 200
2025-07-03 23:02:17,407 - uvicorn.access - INFO - 127.0.0.1:63143 - "GET /api/v1/openapi.json HTTP/1.1" 200
2025-07-03 23:06:32,107 - uvicorn.access - INFO - 127.0.0.1:63800 - "GET /docs HTTP/1.1" 200
2025-07-03 23:06:32,113 - uvicorn.access - INFO - 127.0.0.1:63798 - "GET /docs HTTP/1.1" 200
2025-07-03 23:06:33,713 - uvicorn.access - INFO - 127.0.0.1:63798 - "GET /api/v1/openapi.json HTTP/1.1" 200
2025-07-03 23:07:20,467 - uvicorn.error - INFO - Application startup complete.
2025-07-03 23:07:20,468 - uvicorn.error - ERROR - [Errno 10048] error while attempting to bind on address ('127.0.0.1', 8001): only one usage of each socket address (protocol/network address/port) is normally permitted
2025-07-03 23:07:20,468 - uvicorn.error - INFO - Waiting for application shutdown.
2025-07-03 23:07:20,468 - uvicorn.error - INFO - Application shutdown complete.
2025-07-03 23:07:35,014 - uvicorn.error - INFO - Application startup complete.
2025-07-03 23:07:35,015 - uvicorn.error - ERROR - [Errno 10048] error while attempting to bind on address ('127.0.0.1', 8001): only one usage of each socket address (protocol/network address/port) is normally permitted
2025-07-03 23:07:35,015 - uvicorn.error - INFO - Waiting for application shutdown.
2025-07-03 23:07:35,016 - uvicorn.error - INFO - Application shutdown complete.
2025-07-03 23:07:43,352 - uvicorn.error - INFO - Application startup complete.
2025-07-03 23:07:43,353 - uvicorn.error - ERROR - [Errno 10048] error while attempting to bind on address ('127.0.0.1', 8001): only one usage of each socket address (protocol/network address/port) is normally permitted
2025-07-03 23:07:43,353 - uvicorn.error - INFO - Waiting for application shutdown.
2025-07-03 23:07:43,353 - uvicorn.error - INFO - Application shutdown complete.
2025-07-03 23:08:36,169 - uvicorn.error - INFO - Application startup complete.
2025-07-03 23:08:36,169 - uvicorn.error - ERROR - [Errno 10048] error while attempting to bind on address ('127.0.0.1', 8001): only one usage of each socket address (protocol/network address/port) is normally permitted
2025-07-03 23:08:36,170 - uvicorn.error - INFO - Waiting for application shutdown.
2025-07-03 23:08:36,170 - uvicorn.error - INFO - Application shutdown complete.
2025-07-03 23:10:33,512 - uvicorn.error - INFO - Application startup complete.
2025-07-03 23:10:33,514 - uvicorn.error - ERROR - [Errno 10048] error while attempting to bind on address ('127.0.0.1', 8001): only one usage of each socket address (protocol/network address/port) is normally permitted
2025-07-03 23:10:33,514 - uvicorn.error - INFO - Waiting for application shutdown.
2025-07-03 23:10:33,515 - uvicorn.error - INFO - Application shutdown complete.
2025-07-03 23:17:58,466 - uvicorn.access - INFO - 127.0.0.1:49331 - "GET /docs HTTP/1.1" 200
2025-07-03 23:17:58,563 - uvicorn.access - INFO - 127.0.0.1:49331 - "GET /api/v1/openapi.json HTTP/1.1" 200
2025-07-03 23:18:37,386 - uvicorn.error - INFO - Application startup complete.
2025-07-03 23:18:37,386 - uvicorn.error - ERROR - [Errno 10048] error while attempting to bind on address ('127.0.0.1', 8001): only one usage of each socket address (protocol/network address/port) is normally permitted
2025-07-03 23:18:37,386 - uvicorn.error - INFO - Waiting for application shutdown.
2025-07-03 23:18:37,388 - uvicorn.error - INFO - Application shutdown complete.
2025-07-03 23:19:34,788 - uvicorn.access - INFO - 127.0.0.1:49568 - "GET /docs HTTP/1.1" 200
2025-07-03 23:19:34,877 - uvicorn.access - INFO - 127.0.0.1:49568 - "GET /api/v1/openapi.json HTTP/1.1" 200
2025-07-03 23:19:40,088 - uvicorn.error - INFO - Application startup complete.
2025-07-03 23:19:40,088 - uvicorn.error - ERROR - [Errno 10048] error while attempting to bind on address ('127.0.0.1', 8001): only one usage of each socket address (protocol/network address/port) is normally permitted
2025-07-03 23:19:40,088 - uvicorn.error - INFO - Waiting for application shutdown.
2025-07-03 23:19:40,088 - uvicorn.error - INFO - Application shutdown complete.
2025-07-03 23:20:30,863 - uvicorn.access - INFO - 127.0.0.1:49569 - "GET /docs HTTP/1.1" 200
2025-07-03 23:20:30,917 - uvicorn.access - INFO - 127.0.0.1:49569 - "GET /api/v1/openapi.json HTTP/1.1" 200
2025-07-03 23:20:33,433 - uvicorn.access - INFO - 127.0.0.1:49569 - "GET /api/v1/openapi.json HTTP/1.1" 200
2025-07-03 23:22:44,293 - uvicorn.error - INFO - Application startup complete.
2025-07-03 23:22:44,293 - uvicorn.error - INFO - Uvicorn running on http://127.0.0.1:8001 (Press CTRL+C to quit)
2025-07-03 23:22:52,317 - uvicorn.access - INFO - 127.0.0.1:50275 - "GET /docs HTTP/1.1" 200
2025-07-03 23:22:52,482 - uvicorn.access - INFO - 127.0.0.1:50275 - "GET /api/v1/openapi.json HTTP/1.1" 200
2025-07-03 23:24:05,375 - uvicorn.access - INFO - 127.0.0.1:50463 - "GET /docs HTTP/1.1" 200
2025-07-03 23:24:05,378 - uvicorn.access - INFO - 127.0.0.1:50461 - "GET /docs HTTP/1.1" 200
2025-07-03 23:24:06,863 - uvicorn.access - INFO - 127.0.0.1:50461 - "GET /api/v1/openapi.json HTTP/1.1" 200
2025-07-03 23:25:04,477 - uvicorn.access - INFO - 127.0.0.1:50608 - "GET /docs HTTP/1.1" 200
2025-07-03 23:25:04,480 - uvicorn.access - INFO - 127.0.0.1:50462 - "GET /docs HTTP/1.1" 200
2025-07-03 23:25:04,959 - uvicorn.access - INFO - 127.0.0.1:50462 - "GET /api/v1/openapi.json HTTP/1.1" 200
2025-07-03 23:26:29,686 - root - WARNING - No specialized adapter found for entity type: agent. Using base adapter.
2025-07-03 23:26:29,686 - uvicorn.access - INFO - 127.0.0.1:50917 - "GET /api/v1/agents/ HTTP/1.1" 500
2025-07-03 23:26:29,688 - uvicorn.error - ERROR - Exception in ASGI application
  + Exception Group Traceback (most recent call last):
  |   File "C:\Users\devpc\AppData\Roaming\Python\Python311\site-packages\starlette\_utils.py", line 87, in collapse_excgroups
  |     yield
  |   File "C:\Users\devpc\AppData\Roaming\Python\Python311\site-packages\starlette\middleware\base.py", line 190, in __call__
  |     async with anyio.create_task_group() as task_group:
  |   File "C:\Users\devpc\AppData\Roaming\Python\Python311\site-packages\anyio\_backends\_asyncio.py", line 772, in __aexit__
  |     raise BaseExceptionGroup(
  | ExceptionGroup: unhandled errors in a TaskGroup (1 sub-exception)
  +-+---------------- 1 ----------------
    | Traceback (most recent call last):
    |   File "C:\Users\devpc\AppData\Roaming\Python\Python311\site-packages\uvicorn\protocols\http\httptools_impl.py", line 411, in run_asgi
    |     result = await app(  # type: ignore[func-returns-value]
    |              ^^^^^^^^^^^^^^^^^^^^^^^^^^^^^^^^^^^^^^^^^^^^^^
    |   File "C:\Users\devpc\AppData\Roaming\Python\Python311\site-packages\uvicorn\middleware\proxy_headers.py", line 69, in __call__
    |     return await self.app(scope, receive, send)
    |            ^^^^^^^^^^^^^^^^^^^^^^^^^^^^^^^^^^^^
    |   File "C:\Users\devpc\AppData\Roaming\Python\Python311\site-packages\fastapi\applications.py", line 1054, in __call__
    |     await super().__call__(scope, receive, send)
    |   File "C:\Users\devpc\AppData\Roaming\Python\Python311\site-packages\starlette\applications.py", line 123, in __call__
    |     await self.middleware_stack(scope, receive, send)
    |   File "C:\Users\devpc\AppData\Roaming\Python\Python311\site-packages\starlette\middleware\errors.py", line 186, in __call__
    |     raise exc
    |   File "C:\Users\devpc\AppData\Roaming\Python\Python311\site-packages\starlette\middleware\errors.py", line 164, in __call__
    |     await self.app(scope, receive, _send)
    |   File "C:\Users\devpc\AppData\Roaming\Python\Python311\site-packages\starlette\middleware\base.py", line 189, in __call__
    |     with collapse_excgroups():
    |   File "C:\Program Files\Python311\Lib\contextlib.py", line 155, in __exit__
    |     self.gen.throw(typ, value, traceback)
    |   File "C:\Users\devpc\AppData\Roaming\Python\Python311\site-packages\starlette\_utils.py", line 93, in collapse_excgroups
    |     raise exc
    |   File "C:\Users\devpc\AppData\Roaming\Python\Python311\site-packages\starlette\middleware\base.py", line 191, in __call__
    |     response = await self.dispatch_func(request, call_next)
    |                ^^^^^^^^^^^^^^^^^^^^^^^^^^^^^^^^^^^^^^^^^^^^
    |   File "E:\tech\trm-os-branches\trm_api\middleware\ontology_logging.py", line 48, in dispatch
    |     return await call_next(request)
    |            ^^^^^^^^^^^^^^^^^^^^^^^^
    |   File "C:\Users\devpc\AppData\Roaming\Python\Python311\site-packages\starlette\middleware\base.py", line 165, in call_next
    |     raise app_exc
    |   File "C:\Users\devpc\AppData\Roaming\Python\Python311\site-packages\starlette\middleware\base.py", line 151, in coro
    |     await self.app(scope, receive_or_disconnect, send_no_error)
    |   File "C:\Users\devpc\AppData\Roaming\Python\Python311\site-packages\starlette\middleware\exceptions.py", line 62, in __call__
    |     await wrap_app_handling_exceptions(self.app, conn)(scope, receive, send)
    |   File "C:\Users\devpc\AppData\Roaming\Python\Python311\site-packages\starlette\_exception_handler.py", line 64, in wrapped_app
    |     raise exc
    |   File "C:\Users\devpc\AppData\Roaming\Python\Python311\site-packages\starlette\_exception_handler.py", line 53, in wrapped_app
    |     await app(scope, receive, sender)
    |   File "C:\Users\devpc\AppData\Roaming\Python\Python311\site-packages\starlette\routing.py", line 758, in __call__
    |     await self.middleware_stack(scope, receive, send)
    |   File "C:\Users\devpc\AppData\Roaming\Python\Python311\site-packages\starlette\routing.py", line 778, in app
    |     await route.handle(scope, receive, send)
    |   File "C:\Users\devpc\AppData\Roaming\Python\Python311\site-packages\starlette\routing.py", line 299, in handle
    |     await self.app(scope, receive, send)
    |   File "C:\Users\devpc\AppData\Roaming\Python\Python311\site-packages\starlette\routing.py", line 79, in app
    |     await wrap_app_handling_exceptions(app, request)(scope, receive, send)
    |   File "C:\Users\devpc\AppData\Roaming\Python\Python311\site-packages\starlette\_exception_handler.py", line 64, in wrapped_app
    |     raise exc
    |   File "C:\Users\devpc\AppData\Roaming\Python\Python311\site-packages\starlette\_exception_handler.py", line 53, in wrapped_app
    |     await app(scope, receive, sender)
    |   File "C:\Users\devpc\AppData\Roaming\Python\Python311\site-packages\starlette\routing.py", line 74, in app
    |     response = await func(request)
    |                ^^^^^^^^^^^^^^^^^^^
    |   File "C:\Users\devpc\AppData\Roaming\Python\Python311\site-packages\fastapi\routing.py", line 296, in app
    |     content = await serialize_response(
    |               ^^^^^^^^^^^^^^^^^^^^^^^^^
    |   File "C:\Users\devpc\AppData\Roaming\Python\Python311\site-packages\fastapi\routing.py", line 155, in serialize_response
    |     raise ResponseValidationError(
    | fastapi.exceptions.ResponseValidationError: 1 validation errors:
    |   {'type': 'list_type', 'loc': ('response',), 'msg': 'Input should be a valid list', 'input': {'items': [<Agent: AIAgent: System Agent>, <Agent: AIAgent: System Agent>, <Agent: AIAgent: System Agent>, <Agent: AIAgent: System Agent>, <Agent: AIAgent: System Agent>, <Agent: AIAgent: System Agent>, <Agent: AIAgent: System Agent>, <Agent: InternalAgent: Test Agent test_age>, <Agent: InternalAgent: Test Agent test_age>, <Agent: InternalAgent: Test Agent test_age>, <Agent: InternalAgent: Test Agent test_age>, <Agent: InternalAgent: Test Agent test_age>, <Agent: InternalAgent: Test Agent test_age>, <Agent: InternalAgent: Test Agent test_age>, <Agent: InternalAgent: Test Agent test_age>, <Agent: InternalAgent: Test Agent test_age>, <Agent: InternalAgent: Test Agent test_age>, <Agent: InternalAgent: Test Agent test_age>, <Agent: InternalAgent: Test Agent test_age>, <Agent: InternalAgent: Test Agent test_age>, <Agent: InternalAgent: Test Agent test_age>, <Agent: InternalAgent: Test Agent test_age>, <Agent: InternalAgent: Test Agent test_age>], 'total': 23, 'skip': 0, 'limit': 100}, 'url': 'https://errors.pydantic.dev/2.11/v/list_type'}
    | 
    +------------------------------------

During handling of the above exception, another exception occurred:

Traceback (most recent call last):
  File "C:\Users\devpc\AppData\Roaming\Python\Python311\site-packages\uvicorn\protocols\http\httptools_impl.py", line 411, in run_asgi
    result = await app(  # type: ignore[func-returns-value]
             ^^^^^^^^^^^^^^^^^^^^^^^^^^^^^^^^^^^^^^^^^^^^^^
  File "C:\Users\devpc\AppData\Roaming\Python\Python311\site-packages\uvicorn\middleware\proxy_headers.py", line 69, in __call__
    return await self.app(scope, receive, send)
           ^^^^^^^^^^^^^^^^^^^^^^^^^^^^^^^^^^^^
  File "C:\Users\devpc\AppData\Roaming\Python\Python311\site-packages\fastapi\applications.py", line 1054, in __call__
    await super().__call__(scope, receive, send)
  File "C:\Users\devpc\AppData\Roaming\Python\Python311\site-packages\starlette\applications.py", line 123, in __call__
    await self.middleware_stack(scope, receive, send)
  File "C:\Users\devpc\AppData\Roaming\Python\Python311\site-packages\starlette\middleware\errors.py", line 186, in __call__
    raise exc
  File "C:\Users\devpc\AppData\Roaming\Python\Python311\site-packages\starlette\middleware\errors.py", line 164, in __call__
    await self.app(scope, receive, _send)
  File "C:\Users\devpc\AppData\Roaming\Python\Python311\site-packages\starlette\middleware\base.py", line 189, in __call__
    with collapse_excgroups():
  File "C:\Program Files\Python311\Lib\contextlib.py", line 155, in __exit__
    self.gen.throw(typ, value, traceback)
  File "C:\Users\devpc\AppData\Roaming\Python\Python311\site-packages\starlette\_utils.py", line 93, in collapse_excgroups
    raise exc
  File "C:\Users\devpc\AppData\Roaming\Python\Python311\site-packages\starlette\middleware\base.py", line 191, in __call__
    response = await self.dispatch_func(request, call_next)
               ^^^^^^^^^^^^^^^^^^^^^^^^^^^^^^^^^^^^^^^^^^^^
  File "E:\tech\trm-os-branches\trm_api\middleware\ontology_logging.py", line 48, in dispatch
    return await call_next(request)
           ^^^^^^^^^^^^^^^^^^^^^^^^
  File "C:\Users\devpc\AppData\Roaming\Python\Python311\site-packages\starlette\middleware\base.py", line 165, in call_next
    raise app_exc
  File "C:\Users\devpc\AppData\Roaming\Python\Python311\site-packages\starlette\middleware\base.py", line 151, in coro
    await self.app(scope, receive_or_disconnect, send_no_error)
  File "C:\Users\devpc\AppData\Roaming\Python\Python311\site-packages\starlette\middleware\exceptions.py", line 62, in __call__
    await wrap_app_handling_exceptions(self.app, conn)(scope, receive, send)
  File "C:\Users\devpc\AppData\Roaming\Python\Python311\site-packages\starlette\_exception_handler.py", line 64, in wrapped_app
    raise exc
  File "C:\Users\devpc\AppData\Roaming\Python\Python311\site-packages\starlette\_exception_handler.py", line 53, in wrapped_app
    await app(scope, receive, sender)
  File "C:\Users\devpc\AppData\Roaming\Python\Python311\site-packages\starlette\routing.py", line 758, in __call__
    await self.middleware_stack(scope, receive, send)
  File "C:\Users\devpc\AppData\Roaming\Python\Python311\site-packages\starlette\routing.py", line 778, in app
    await route.handle(scope, receive, send)
  File "C:\Users\devpc\AppData\Roaming\Python\Python311\site-packages\starlette\routing.py", line 299, in handle
    await self.app(scope, receive, send)
  File "C:\Users\devpc\AppData\Roaming\Python\Python311\site-packages\starlette\routing.py", line 79, in app
    await wrap_app_handling_exceptions(app, request)(scope, receive, send)
  File "C:\Users\devpc\AppData\Roaming\Python\Python311\site-packages\starlette\_exception_handler.py", line 64, in wrapped_app
    raise exc
  File "C:\Users\devpc\AppData\Roaming\Python\Python311\site-packages\starlette\_exception_handler.py", line 53, in wrapped_app
    await app(scope, receive, sender)
  File "C:\Users\devpc\AppData\Roaming\Python\Python311\site-packages\starlette\routing.py", line 74, in app
    response = await func(request)
               ^^^^^^^^^^^^^^^^^^^
  File "C:\Users\devpc\AppData\Roaming\Python\Python311\site-packages\fastapi\routing.py", line 296, in app
    content = await serialize_response(
              ^^^^^^^^^^^^^^^^^^^^^^^^^
  File "C:\Users\devpc\AppData\Roaming\Python\Python311\site-packages\fastapi\routing.py", line 155, in serialize_response
    raise ResponseValidationError(
fastapi.exceptions.ResponseValidationError: 1 validation errors:
  {'type': 'list_type', 'loc': ('response',), 'msg': 'Input should be a valid list', 'input': {'items': [<Agent: AIAgent: System Agent>, <Agent: AIAgent: System Agent>, <Agent: AIAgent: System Agent>, <Agent: AIAgent: System Agent>, <Agent: AIAgent: System Agent>, <Agent: AIAgent: System Agent>, <Agent: AIAgent: System Agent>, <Agent: InternalAgent: Test Agent test_age>, <Agent: InternalAgent: Test Agent test_age>, <Agent: InternalAgent: Test Agent test_age>, <Agent: InternalAgent: Test Agent test_age>, <Agent: InternalAgent: Test Agent test_age>, <Agent: InternalAgent: Test Agent test_age>, <Agent: InternalAgent: Test Agent test_age>, <Agent: InternalAgent: Test Agent test_age>, <Agent: InternalAgent: Test Agent test_age>, <Agent: InternalAgent: Test Agent test_age>, <Agent: InternalAgent: Test Agent test_age>, <Agent: InternalAgent: Test Agent test_age>, <Agent: InternalAgent: Test Agent test_age>, <Agent: InternalAgent: Test Agent test_age>, <Agent: InternalAgent: Test Agent test_age>, <Agent: InternalAgent: Test Agent test_age>], 'total': 23, 'skip': 0, 'limit': 100}, 'url': 'https://errors.pydantic.dev/2.11/v/list_type'}

2025-07-03 23:26:49,228 - uvicorn.access - INFO - 127.0.0.1:50955 - "GET /docs HTTP/1.1" 200
2025-07-03 23:26:49,231 - uvicorn.access - INFO - 127.0.0.1:50953 - "GET /docs HTTP/1.1" 200
2025-07-03 23:26:49,779 - uvicorn.access - INFO - 127.0.0.1:50953 - "GET /api/v1/openapi.json HTTP/1.1" 200
2025-07-03 23:28:19,990 - uvicorn.access - INFO - 127.0.0.1:51291 - "GET /test HTTP/1.1" 404
2025-07-03 23:30:12,401 - uvicorn.access - INFO - 127.0.0.1:51534 - "GET /api/v1/openapi.json HTTP/1.1" 200
2025-07-03 23:30:26,598 - uvicorn.access - INFO - 127.0.0.1:51574 - "GET /api/v1/openapi.json HTTP/1.1" 200
2025-07-03 23:30:38,370 - uvicorn.access - INFO - 127.0.0.1:51612 - "GET /api/v1/openapi.json HTTP/1.1" 200
2025-07-03 23:32:33,725 - uvicorn.access - INFO - 127.0.0.1:51965 - "GET /docs HTTP/1.1" 200
2025-07-03 23:32:33,727 - uvicorn.access - INFO - 127.0.0.1:51963 - "GET /docs HTTP/1.1" 200
2025-07-03 23:32:34,240 - uvicorn.access - INFO - 127.0.0.1:51963 - "GET /api/v1/openapi.json HTTP/1.1" 200
2025-07-03 23:33:16,297 - uvicorn.access - INFO - 127.0.0.1:52047 - "GET /docs HTTP/1.1" 200
2025-07-03 23:33:42,189 - uvicorn.access - INFO - 127.0.0.1:52100 - "POST /agents/test-agent-id/skills/test-skill-id HTTP/1.1" 404
2025-07-03 23:33:54,837 - uvicorn.access - INFO - 127.0.0.1:52125 - "GET /openapi.json HTTP/1.1" 404
2025-07-03 23:35:26,624 - uvicorn.error - INFO - Application startup complete.
2025-07-03 23:35:28,276 - uvicorn.access - INFO - 127.0.0.1:52377 - "GET /docs HTTP/1.1" 200
2025-07-03 23:35:28,279 - uvicorn.access - INFO - 127.0.0.1:52375 - "GET /docs HTTP/1.1" 200
2025-07-03 23:35:28,948 - uvicorn.access - INFO - 127.0.0.1:52375 - "GET /api/v1/openapi.json HTTP/1.1" 200
2025-07-03 23:35:40,720 - uvicorn.error - INFO - Shutting down
2025-07-03 23:35:40,829 - uvicorn.error - INFO - Waiting for application shutdown.
2025-07-03 23:35:40,831 - uvicorn.error - INFO - Application shutdown complete.
2025-07-03 23:35:40,831 - uvicorn.error - INFO - Finished server process [33764]
2025-07-03 23:37:00,905 - uvicorn.error - INFO - Application startup complete.
2025-07-03 23:37:00,906 - uvicorn.error - INFO - Uvicorn running on http://127.0.0.1:8001 (Press CTRL+C to quit)
2025-07-03 23:37:25,902 - uvicorn.error - INFO - Shutting down
2025-07-03 23:37:26,012 - uvicorn.error - INFO - Waiting for application shutdown.
2025-07-03 23:37:26,012 - uvicorn.error - INFO - Application shutdown complete.
2025-07-03 23:37:26,012 - uvicorn.error - INFO - Finished server process [24336]
2025-07-03 23:45:21,433 - uvicorn.error - INFO - Application startup complete.
2025-07-03 23:45:33,340 - uvicorn.access - INFO - 127.0.0.1:54413 - "GET /docs HTTP/1.1" 200
2025-07-03 23:45:33,344 - uvicorn.access - INFO - 127.0.0.1:54411 - "GET /docs HTTP/1.1" 200
2025-07-03 23:45:33,825 - uvicorn.access - INFO - 127.0.0.1:54411 - "GET /api/v1/openapi.json HTTP/1.1" 200
2025-07-03 23:45:40,037 - uvicorn.error - INFO - Shutting down
2025-07-03 23:45:40,146 - uvicorn.error - INFO - Waiting for application shutdown.
2025-07-03 23:45:40,146 - uvicorn.error - INFO - Application shutdown complete.
2025-07-03 23:45:40,146 - uvicorn.error - INFO - Finished server process [39520]
2025-07-03 23:45:47,672 - uvicorn.error - INFO - Application startup complete.
2025-07-03 23:45:52,544 - uvicorn.access - INFO - 127.0.0.1:54489 - "GET /docs HTTP/1.1" 200
2025-07-03 23:45:59,501 - uvicorn.access - INFO - 127.0.0.1:54514 - "GET /docs HTTP/1.1" 200
2025-07-03 23:46:32,004 - uvicorn.access - INFO - 127.0.0.1:54731 - "POST /api/v1/skills HTTP/1.1" 307
2025-07-03 23:46:32,006 - uvicorn.access - INFO - 127.0.0.1:54731 - "POST /api/v1/skills/ HTTP/1.1" 400
2025-07-03 23:46:47,758 - uvicorn.access - INFO - 127.0.0.1:54758 - "POST /api/v1/skills HTTP/1.1" 307
2025-07-03 23:46:48,981 - uvicorn.access - INFO - 127.0.0.1:54758 - "POST /api/v1/skills/ HTTP/1.1" 201
2025-07-03 23:46:59,495 - uvicorn.access - INFO - 127.0.0.1:54782 - "POST /api/v1/agents HTTP/1.1" 307
2025-07-03 23:46:59,496 - uvicorn.access - INFO - 127.0.0.1:54782 - "POST /api/v1/agents/ HTTP/1.1" 400
2025-07-03 23:47:17,279 - uvicorn.access - INFO - 127.0.0.1:54820 - "POST /api/v1/agents HTTP/1.1" 307
2025-07-03 23:47:17,280 - uvicorn.access - INFO - 127.0.0.1:54820 - "POST /api/v1/agents/ HTTP/1.1" 422
2025-07-03 23:47:30,682 - uvicorn.access - INFO - 127.0.0.1:54856 - "POST /api/v1/agents HTTP/1.1" 307
2025-07-03 23:47:30,685 - root - ERROR - Error in adapt_ontology_response: Attempting to deflate property 'agent_type' on <unsaved node> of class 'Agent': Invalid choice: technical
2025-07-03 23:47:30,685 - uvicorn.access - INFO - 127.0.0.1:54856 - "POST /api/v1/agents/ HTTP/1.1" 500
2025-07-03 23:47:44,286 - uvicorn.access - INFO - 127.0.0.1:54882 - "GET /api/v1/agents/test-agent HTTP/1.1" 404
2025-07-03 23:47:54,501 - uvicorn.access - INFO - 127.0.0.1:54907 - "GET /api/v1/agents HTTP/1.1" 307
2025-07-03 23:47:54,647 - root - WARNING - No specialized adapter found for entity type: agent. Using base adapter.
2025-07-03 23:47:54,648 - uvicorn.access - INFO - 127.0.0.1:54907 - "GET /api/v1/agents/ HTTP/1.1" 500
2025-07-03 23:47:54,649 - uvicorn.error - ERROR - Exception in ASGI application
  + Exception Group Traceback (most recent call last):
  |   File "C:\Users\devpc\AppData\Roaming\Python\Python311\site-packages\starlette\_utils.py", line 87, in collapse_excgroups
  |     yield
  |   File "C:\Users\devpc\AppData\Roaming\Python\Python311\site-packages\starlette\middleware\base.py", line 190, in __call__
  |     async with anyio.create_task_group() as task_group:
  |   File "C:\Users\devpc\AppData\Roaming\Python\Python311\site-packages\anyio\_backends\_asyncio.py", line 772, in __aexit__
  |     raise BaseExceptionGroup(
  | ExceptionGroup: unhandled errors in a TaskGroup (1 sub-exception)
  +-+---------------- 1 ----------------
    | Traceback (most recent call last):
    |   File "C:\Users\devpc\AppData\Roaming\Python\Python311\site-packages\uvicorn\protocols\http\httptools_impl.py", line 411, in run_asgi
    |     result = await app(  # type: ignore[func-returns-value]
    |              ^^^^^^^^^^^^^^^^^^^^^^^^^^^^^^^^^^^^^^^^^^^^^^
    |   File "C:\Users\devpc\AppData\Roaming\Python\Python311\site-packages\uvicorn\middleware\proxy_headers.py", line 69, in __call__
    |     return await self.app(scope, receive, send)
    |            ^^^^^^^^^^^^^^^^^^^^^^^^^^^^^^^^^^^^
    |   File "C:\Users\devpc\AppData\Roaming\Python\Python311\site-packages\fastapi\applications.py", line 1054, in __call__
    |     await super().__call__(scope, receive, send)
    |   File "C:\Users\devpc\AppData\Roaming\Python\Python311\site-packages\starlette\applications.py", line 123, in __call__
    |     await self.middleware_stack(scope, receive, send)
    |   File "C:\Users\devpc\AppData\Roaming\Python\Python311\site-packages\starlette\middleware\errors.py", line 186, in __call__
    |     raise exc
    |   File "C:\Users\devpc\AppData\Roaming\Python\Python311\site-packages\starlette\middleware\errors.py", line 164, in __call__
    |     await self.app(scope, receive, _send)
    |   File "C:\Users\devpc\AppData\Roaming\Python\Python311\site-packages\starlette\middleware\base.py", line 189, in __call__
    |     with collapse_excgroups():
    |   File "C:\Program Files\Python311\Lib\contextlib.py", line 155, in __exit__
    |     self.gen.throw(typ, value, traceback)
    |   File "C:\Users\devpc\AppData\Roaming\Python\Python311\site-packages\starlette\_utils.py", line 93, in collapse_excgroups
    |     raise exc
    |   File "C:\Users\devpc\AppData\Roaming\Python\Python311\site-packages\starlette\middleware\base.py", line 191, in __call__
    |     response = await self.dispatch_func(request, call_next)
    |                ^^^^^^^^^^^^^^^^^^^^^^^^^^^^^^^^^^^^^^^^^^^^
    |   File "E:\tech\trm-os-branches\trm_api\middleware\ontology_logging.py", line 48, in dispatch
    |     return await call_next(request)
    |            ^^^^^^^^^^^^^^^^^^^^^^^^
    |   File "C:\Users\devpc\AppData\Roaming\Python\Python311\site-packages\starlette\middleware\base.py", line 165, in call_next
    |     raise app_exc
    |   File "C:\Users\devpc\AppData\Roaming\Python\Python311\site-packages\starlette\middleware\base.py", line 151, in coro
    |     await self.app(scope, receive_or_disconnect, send_no_error)
    |   File "C:\Users\devpc\AppData\Roaming\Python\Python311\site-packages\starlette\middleware\exceptions.py", line 62, in __call__
    |     await wrap_app_handling_exceptions(self.app, conn)(scope, receive, send)
    |   File "C:\Users\devpc\AppData\Roaming\Python\Python311\site-packages\starlette\_exception_handler.py", line 64, in wrapped_app
    |     raise exc
    |   File "C:\Users\devpc\AppData\Roaming\Python\Python311\site-packages\starlette\_exception_handler.py", line 53, in wrapped_app
    |     await app(scope, receive, sender)
    |   File "C:\Users\devpc\AppData\Roaming\Python\Python311\site-packages\starlette\routing.py", line 758, in __call__
    |     await self.middleware_stack(scope, receive, send)
    |   File "C:\Users\devpc\AppData\Roaming\Python\Python311\site-packages\starlette\routing.py", line 778, in app
    |     await route.handle(scope, receive, send)
    |   File "C:\Users\devpc\AppData\Roaming\Python\Python311\site-packages\starlette\routing.py", line 299, in handle
    |     await self.app(scope, receive, send)
    |   File "C:\Users\devpc\AppData\Roaming\Python\Python311\site-packages\starlette\routing.py", line 79, in app
    |     await wrap_app_handling_exceptions(app, request)(scope, receive, send)
    |   File "C:\Users\devpc\AppData\Roaming\Python\Python311\site-packages\starlette\_exception_handler.py", line 64, in wrapped_app
    |     raise exc
    |   File "C:\Users\devpc\AppData\Roaming\Python\Python311\site-packages\starlette\_exception_handler.py", line 53, in wrapped_app
    |     await app(scope, receive, sender)
    |   File "C:\Users\devpc\AppData\Roaming\Python\Python311\site-packages\starlette\routing.py", line 74, in app
    |     response = await func(request)
    |                ^^^^^^^^^^^^^^^^^^^
    |   File "C:\Users\devpc\AppData\Roaming\Python\Python311\site-packages\fastapi\routing.py", line 296, in app
    |     content = await serialize_response(
    |               ^^^^^^^^^^^^^^^^^^^^^^^^^
    |   File "C:\Users\devpc\AppData\Roaming\Python\Python311\site-packages\fastapi\routing.py", line 155, in serialize_response
    |     raise ResponseValidationError(
    | fastapi.exceptions.ResponseValidationError: 1 validation errors:
    |   {'type': 'list_type', 'loc': ('response',), 'msg': 'Input should be a valid list', 'input': {'items': [<Agent: AIAgent: System Agent>, <Agent: AIAgent: System Agent>, <Agent: AIAgent: System Agent>, <Agent: AIAgent: System Agent>, <Agent: AIAgent: System Agent>, <Agent: AIAgent: System Agent>, <Agent: AIAgent: System Agent>, <Agent: InternalAgent: Test Agent test_age>, <Agent: InternalAgent: Test Agent test_age>, <Agent: InternalAgent: Test Agent test_age>, <Agent: InternalAgent: Test Agent test_age>, <Agent: InternalAgent: Test Agent test_age>, <Agent: InternalAgent: Test Agent test_age>, <Agent: InternalAgent: Test Agent test_age>, <Agent: InternalAgent: Test Agent test_age>, <Agent: InternalAgent: Test Agent test_age>, <Agent: InternalAgent: Test Agent test_age>, <Agent: InternalAgent: Test Agent test_age>, <Agent: InternalAgent: Test Agent test_age>, <Agent: InternalAgent: Test Agent test_age>, <Agent: InternalAgent: Test Agent test_age>, <Agent: InternalAgent: Test Agent test_age>, <Agent: InternalAgent: Test Agent test_age>], 'total': 23, 'skip': 0, 'limit': 100}, 'url': 'https://errors.pydantic.dev/2.11/v/list_type'}
    | 
    +------------------------------------

During handling of the above exception, another exception occurred:

Traceback (most recent call last):
  File "C:\Users\devpc\AppData\Roaming\Python\Python311\site-packages\uvicorn\protocols\http\httptools_impl.py", line 411, in run_asgi
    result = await app(  # type: ignore[func-returns-value]
             ^^^^^^^^^^^^^^^^^^^^^^^^^^^^^^^^^^^^^^^^^^^^^^
  File "C:\Users\devpc\AppData\Roaming\Python\Python311\site-packages\uvicorn\middleware\proxy_headers.py", line 69, in __call__
    return await self.app(scope, receive, send)
           ^^^^^^^^^^^^^^^^^^^^^^^^^^^^^^^^^^^^
  File "C:\Users\devpc\AppData\Roaming\Python\Python311\site-packages\fastapi\applications.py", line 1054, in __call__
    await super().__call__(scope, receive, send)
  File "C:\Users\devpc\AppData\Roaming\Python\Python311\site-packages\starlette\applications.py", line 123, in __call__
    await self.middleware_stack(scope, receive, send)
  File "C:\Users\devpc\AppData\Roaming\Python\Python311\site-packages\starlette\middleware\errors.py", line 186, in __call__
    raise exc
  File "C:\Users\devpc\AppData\Roaming\Python\Python311\site-packages\starlette\middleware\errors.py", line 164, in __call__
    await self.app(scope, receive, _send)
  File "C:\Users\devpc\AppData\Roaming\Python\Python311\site-packages\starlette\middleware\base.py", line 189, in __call__
    with collapse_excgroups():
  File "C:\Program Files\Python311\Lib\contextlib.py", line 155, in __exit__
    self.gen.throw(typ, value, traceback)
  File "C:\Users\devpc\AppData\Roaming\Python\Python311\site-packages\starlette\_utils.py", line 93, in collapse_excgroups
    raise exc
  File "C:\Users\devpc\AppData\Roaming\Python\Python311\site-packages\starlette\middleware\base.py", line 191, in __call__
    response = await self.dispatch_func(request, call_next)
               ^^^^^^^^^^^^^^^^^^^^^^^^^^^^^^^^^^^^^^^^^^^^
  File "E:\tech\trm-os-branches\trm_api\middleware\ontology_logging.py", line 48, in dispatch
    return await call_next(request)
           ^^^^^^^^^^^^^^^^^^^^^^^^
  File "C:\Users\devpc\AppData\Roaming\Python\Python311\site-packages\starlette\middleware\base.py", line 165, in call_next
    raise app_exc
  File "C:\Users\devpc\AppData\Roaming\Python\Python311\site-packages\starlette\middleware\base.py", line 151, in coro
    await self.app(scope, receive_or_disconnect, send_no_error)
  File "C:\Users\devpc\AppData\Roaming\Python\Python311\site-packages\starlette\middleware\exceptions.py", line 62, in __call__
    await wrap_app_handling_exceptions(self.app, conn)(scope, receive, send)
  File "C:\Users\devpc\AppData\Roaming\Python\Python311\site-packages\starlette\_exception_handler.py", line 64, in wrapped_app
    raise exc
  File "C:\Users\devpc\AppData\Roaming\Python\Python311\site-packages\starlette\_exception_handler.py", line 53, in wrapped_app
    await app(scope, receive, sender)
  File "C:\Users\devpc\AppData\Roaming\Python\Python311\site-packages\starlette\routing.py", line 758, in __call__
    await self.middleware_stack(scope, receive, send)
  File "C:\Users\devpc\AppData\Roaming\Python\Python311\site-packages\starlette\routing.py", line 778, in app
    await route.handle(scope, receive, send)
  File "C:\Users\devpc\AppData\Roaming\Python\Python311\site-packages\starlette\routing.py", line 299, in handle
    await self.app(scope, receive, send)
  File "C:\Users\devpc\AppData\Roaming\Python\Python311\site-packages\starlette\routing.py", line 79, in app
    await wrap_app_handling_exceptions(app, request)(scope, receive, send)
  File "C:\Users\devpc\AppData\Roaming\Python\Python311\site-packages\starlette\_exception_handler.py", line 64, in wrapped_app
    raise exc
  File "C:\Users\devpc\AppData\Roaming\Python\Python311\site-packages\starlette\_exception_handler.py", line 53, in wrapped_app
    await app(scope, receive, sender)
  File "C:\Users\devpc\AppData\Roaming\Python\Python311\site-packages\starlette\routing.py", line 74, in app
    response = await func(request)
               ^^^^^^^^^^^^^^^^^^^
  File "C:\Users\devpc\AppData\Roaming\Python\Python311\site-packages\fastapi\routing.py", line 296, in app
    content = await serialize_response(
              ^^^^^^^^^^^^^^^^^^^^^^^^^
  File "C:\Users\devpc\AppData\Roaming\Python\Python311\site-packages\fastapi\routing.py", line 155, in serialize_response
    raise ResponseValidationError(
fastapi.exceptions.ResponseValidationError: 1 validation errors:
  {'type': 'list_type', 'loc': ('response',), 'msg': 'Input should be a valid list', 'input': {'items': [<Agent: AIAgent: System Agent>, <Agent: AIAgent: System Agent>, <Agent: AIAgent: System Agent>, <Agent: AIAgent: System Agent>, <Agent: AIAgent: System Agent>, <Agent: AIAgent: System Agent>, <Agent: AIAgent: System Agent>, <Agent: InternalAgent: Test Agent test_age>, <Agent: InternalAgent: Test Agent test_age>, <Agent: InternalAgent: Test Agent test_age>, <Agent: InternalAgent: Test Agent test_age>, <Agent: InternalAgent: Test Agent test_age>, <Agent: InternalAgent: Test Agent test_age>, <Agent: InternalAgent: Test Agent test_age>, <Agent: InternalAgent: Test Agent test_age>, <Agent: InternalAgent: Test Agent test_age>, <Agent: InternalAgent: Test Agent test_age>, <Agent: InternalAgent: Test Agent test_age>, <Agent: InternalAgent: Test Agent test_age>, <Agent: InternalAgent: Test Agent test_age>, <Agent: InternalAgent: Test Agent test_age>, <Agent: InternalAgent: Test Agent test_age>, <Agent: InternalAgent: Test Agent test_age>], 'total': 23, 'skip': 0, 'limit': 100}, 'url': 'https://errors.pydantic.dev/2.11/v/list_type'}

2025-07-03 23:53:52,633 - uvicorn.error - INFO - Shutting down
2025-07-03 23:53:52,742 - uvicorn.error - INFO - Waiting for application shutdown.
2025-07-03 23:53:52,743 - uvicorn.error - INFO - Application shutdown complete.
2025-07-03 23:53:52,743 - uvicorn.error - INFO - Finished server process [39352]
2025-07-03 23:53:54,263 - uvicorn.error - INFO - Application startup complete.
2025-07-03 23:53:54,285 - uvicorn.error - ERROR - Traceback (most recent call last):
  File "C:\Program Files\Python311\Lib\asyncio\runners.py", line 118, in run
    return self._loop.run_until_complete(task)
           ^^^^^^^^^^^^^^^^^^^^^^^^^^^^^^^^^^^
  File "C:\Program Files\Python311\Lib\asyncio\base_events.py", line 650, in run_until_complete
    return future.result()
           ^^^^^^^^^^^^^^^
asyncio.exceptions.CancelledError

During handling of the above exception, another exception occurred:

Traceback (most recent call last):
  File "C:\Program Files\Python311\Lib\asyncio\runners.py", line 190, in run
    return runner.run(main)
           ^^^^^^^^^^^^^^^^
  File "C:\Program Files\Python311\Lib\asyncio\runners.py", line 123, in run
    raise KeyboardInterrupt()
KeyboardInterrupt

During handling of the above exception, another exception occurred:

Traceback (most recent call last):
  File "C:\Program Files\Python311\Lib\contextlib.py", line 222, in __aexit__
    await self.gen.athrow(typ, value, traceback)
  File "E:\tech\trm-os-branches\trm_api\main.py", line 31, in lifespan
    yield
  File "C:\Users\devpc\AppData\Roaming\Python\Python311\site-packages\starlette\routing.py", line 743, in lifespan
    await receive()
  File "C:\Users\devpc\AppData\Roaming\Python\Python311\site-packages\uvicorn\lifespan\on.py", line 137, in receive
    return await self.receive_queue.get()
           ^^^^^^^^^^^^^^^^^^^^^^^^^^^^^^
  File "C:\Program Files\Python311\Lib\asyncio\queues.py", line 158, in get
    await getter
asyncio.exceptions.CancelledError

2025-07-03 23:53:55,628 - uvicorn.error - INFO - Application startup complete.
2025-07-03 23:55:45,707 - uvicorn.error - INFO - Shutting down
2025-07-03 23:55:45,817 - uvicorn.error - INFO - Waiting for application shutdown.
2025-07-03 23:55:45,819 - uvicorn.error - INFO - Application shutdown complete.
2025-07-03 23:55:45,819 - uvicorn.error - INFO - Finished server process [39052]
2025-07-03 23:55:47,293 - uvicorn.error - INFO - Application startup complete.
2025-07-04 00:00:46,101 - uvicorn.error - INFO - Shutting down
2025-07-04 00:00:46,210 - uvicorn.error - INFO - Waiting for application shutdown.
2025-07-04 00:00:46,211 - uvicorn.error - INFO - Application shutdown complete.
2025-07-04 00:00:46,213 - uvicorn.error - INFO - Finished server process [35952]
2025-07-04 00:00:47,710 - uvicorn.error - INFO - Application startup complete.
2025-07-04 00:00:47,712 - uvicorn.error - ERROR - Traceback (most recent call last):
  File "C:\Program Files\Python311\Lib\asyncio\runners.py", line 118, in run
    return self._loop.run_until_complete(task)
           ^^^^^^^^^^^^^^^^^^^^^^^^^^^^^^^^^^^
  File "C:\Program Files\Python311\Lib\asyncio\base_events.py", line 650, in run_until_complete
    return future.result()
           ^^^^^^^^^^^^^^^
asyncio.exceptions.CancelledError

During handling of the above exception, another exception occurred:

Traceback (most recent call last):
  File "C:\Program Files\Python311\Lib\asyncio\runners.py", line 190, in run
    return runner.run(main)
           ^^^^^^^^^^^^^^^^
  File "C:\Program Files\Python311\Lib\asyncio\runners.py", line 123, in run
    raise KeyboardInterrupt()
KeyboardInterrupt

During handling of the above exception, another exception occurred:

Traceback (most recent call last):
  File "C:\Program Files\Python311\Lib\contextlib.py", line 222, in __aexit__
    await self.gen.athrow(typ, value, traceback)
  File "E:\tech\trm-os-branches\trm_api\main.py", line 31, in lifespan
    yield
  File "C:\Users\devpc\AppData\Roaming\Python\Python311\site-packages\starlette\routing.py", line 743, in lifespan
    await receive()
  File "C:\Users\devpc\AppData\Roaming\Python\Python311\site-packages\uvicorn\lifespan\on.py", line 137, in receive
    return await self.receive_queue.get()
           ^^^^^^^^^^^^^^^^^^^^^^^^^^^^^^
  File "C:\Program Files\Python311\Lib\asyncio\queues.py", line 158, in get
    await getter
asyncio.exceptions.CancelledError

2025-07-04 00:00:49,185 - uvicorn.error - INFO - Application startup complete.
2025-07-04 00:05:46,526 - uvicorn.error - INFO - Shutting down
2025-07-04 00:05:46,634 - uvicorn.error - INFO - Waiting for application shutdown.
2025-07-04 00:05:46,635 - uvicorn.error - INFO - Application shutdown complete.
2025-07-04 00:05:46,635 - uvicorn.error - INFO - Finished server process [24884]
2025-07-04 00:05:48,417 - uvicorn.error - INFO - Application startup complete.
2025-07-04 00:05:48,420 - uvicorn.error - ERROR - Traceback (most recent call last):
  File "C:\Program Files\Python311\Lib\asyncio\runners.py", line 118, in run
    return self._loop.run_until_complete(task)
           ^^^^^^^^^^^^^^^^^^^^^^^^^^^^^^^^^^^
  File "C:\Program Files\Python311\Lib\asyncio\base_events.py", line 650, in run_until_complete
    return future.result()
           ^^^^^^^^^^^^^^^
asyncio.exceptions.CancelledError

During handling of the above exception, another exception occurred:

Traceback (most recent call last):
  File "C:\Program Files\Python311\Lib\asyncio\runners.py", line 190, in run
    return runner.run(main)
           ^^^^^^^^^^^^^^^^
  File "C:\Program Files\Python311\Lib\asyncio\runners.py", line 123, in run
    raise KeyboardInterrupt()
KeyboardInterrupt

During handling of the above exception, another exception occurred:

Traceback (most recent call last):
  File "C:\Program Files\Python311\Lib\contextlib.py", line 222, in __aexit__
    await self.gen.athrow(typ, value, traceback)
  File "E:\tech\trm-os-branches\trm_api\main.py", line 31, in lifespan
    yield
  File "C:\Users\devpc\AppData\Roaming\Python\Python311\site-packages\starlette\routing.py", line 743, in lifespan
    await receive()
  File "C:\Users\devpc\AppData\Roaming\Python\Python311\site-packages\uvicorn\lifespan\on.py", line 137, in receive
    return await self.receive_queue.get()
           ^^^^^^^^^^^^^^^^^^^^^^^^^^^^^^
  File "C:\Program Files\Python311\Lib\asyncio\queues.py", line 158, in get
    await getter
asyncio.exceptions.CancelledError

2025-07-04 00:05:50,091 - uvicorn.error - INFO - Application startup complete.
2025-07-04 00:10:48,728 - uvicorn.error - INFO - Shutting down
2025-07-04 00:10:48,837 - uvicorn.error - INFO - Waiting for application shutdown.
2025-07-04 00:10:48,839 - uvicorn.error - INFO - Application shutdown complete.
2025-07-04 00:10:48,839 - uvicorn.error - INFO - Finished server process [39284]
2025-07-04 00:10:50,336 - uvicorn.error - INFO - Application startup complete.
2025-07-04 00:10:50,340 - uvicorn.error - ERROR - Traceback (most recent call last):
  File "C:\Program Files\Python311\Lib\asyncio\runners.py", line 118, in run
    return self._loop.run_until_complete(task)
           ^^^^^^^^^^^^^^^^^^^^^^^^^^^^^^^^^^^
  File "C:\Program Files\Python311\Lib\asyncio\base_events.py", line 650, in run_until_complete
    return future.result()
           ^^^^^^^^^^^^^^^
asyncio.exceptions.CancelledError

During handling of the above exception, another exception occurred:

Traceback (most recent call last):
  File "C:\Program Files\Python311\Lib\asyncio\runners.py", line 190, in run
    return runner.run(main)
           ^^^^^^^^^^^^^^^^
  File "C:\Program Files\Python311\Lib\asyncio\runners.py", line 123, in run
    raise KeyboardInterrupt()
KeyboardInterrupt

During handling of the above exception, another exception occurred:

Traceback (most recent call last):
  File "C:\Program Files\Python311\Lib\contextlib.py", line 222, in __aexit__
    await self.gen.athrow(typ, value, traceback)
  File "E:\tech\trm-os-branches\trm_api\main.py", line 31, in lifespan
    yield
  File "C:\Users\devpc\AppData\Roaming\Python\Python311\site-packages\starlette\routing.py", line 743, in lifespan
    await receive()
  File "C:\Users\devpc\AppData\Roaming\Python\Python311\site-packages\uvicorn\lifespan\on.py", line 137, in receive
    return await self.receive_queue.get()
           ^^^^^^^^^^^^^^^^^^^^^^^^^^^^^^
  File "C:\Program Files\Python311\Lib\asyncio\queues.py", line 158, in get
    await getter
asyncio.exceptions.CancelledError

2025-07-04 00:10:51,782 - uvicorn.error - INFO - Application startup complete.
2025-07-04 00:13:53,585 - uvicorn.error - INFO - Shutting down
2025-07-04 00:13:53,694 - uvicorn.error - INFO - Waiting for application shutdown.
2025-07-04 00:13:53,695 - uvicorn.error - INFO - Application shutdown complete.
2025-07-04 00:13:53,695 - uvicorn.error - INFO - Finished server process [41208]
2025-07-04 00:13:55,234 - uvicorn.error - INFO - Application startup complete.
2025-07-04 00:13:55,235 - uvicorn.error - ERROR - Traceback (most recent call last):
  File "C:\Program Files\Python311\Lib\asyncio\runners.py", line 118, in run
    return self._loop.run_until_complete(task)
           ^^^^^^^^^^^^^^^^^^^^^^^^^^^^^^^^^^^
  File "C:\Program Files\Python311\Lib\asyncio\base_events.py", line 650, in run_until_complete
    return future.result()
           ^^^^^^^^^^^^^^^
asyncio.exceptions.CancelledError

During handling of the above exception, another exception occurred:

Traceback (most recent call last):
  File "C:\Program Files\Python311\Lib\asyncio\runners.py", line 190, in run
    return runner.run(main)
           ^^^^^^^^^^^^^^^^
  File "C:\Program Files\Python311\Lib\asyncio\runners.py", line 123, in run
    raise KeyboardInterrupt()
KeyboardInterrupt

During handling of the above exception, another exception occurred:

Traceback (most recent call last):
  File "C:\Program Files\Python311\Lib\contextlib.py", line 222, in __aexit__
    await self.gen.athrow(typ, value, traceback)
  File "E:\tech\trm-os-branches\trm_api\main.py", line 31, in lifespan
    yield
  File "C:\Users\devpc\AppData\Roaming\Python\Python311\site-packages\starlette\routing.py", line 743, in lifespan
    await receive()
  File "C:\Users\devpc\AppData\Roaming\Python\Python311\site-packages\uvicorn\lifespan\on.py", line 137, in receive
    return await self.receive_queue.get()
           ^^^^^^^^^^^^^^^^^^^^^^^^^^^^^^
  File "C:\Program Files\Python311\Lib\asyncio\queues.py", line 158, in get
    await getter
asyncio.exceptions.CancelledError

2025-07-04 00:13:56,603 - uvicorn.error - INFO - Application startup complete.
2025-07-04 00:14:14,393 - uvicorn.error - INFO - Shutting down
2025-07-04 00:14:14,501 - uvicorn.error - INFO - Waiting for application shutdown.
2025-07-04 00:14:14,501 - uvicorn.error - INFO - Application shutdown complete.
2025-07-04 00:14:14,502 - uvicorn.error - INFO - Finished server process [41816]
2025-07-04 00:14:16,252 - uvicorn.error - INFO - Application startup complete.
2025-07-04 00:14:16,256 - uvicorn.error - ERROR - Traceback (most recent call last):
  File "C:\Program Files\Python311\Lib\asyncio\runners.py", line 118, in run
    return self._loop.run_until_complete(task)
           ^^^^^^^^^^^^^^^^^^^^^^^^^^^^^^^^^^^
  File "C:\Program Files\Python311\Lib\asyncio\base_events.py", line 650, in run_until_complete
    return future.result()
           ^^^^^^^^^^^^^^^
asyncio.exceptions.CancelledError

During handling of the above exception, another exception occurred:

Traceback (most recent call last):
  File "C:\Program Files\Python311\Lib\asyncio\runners.py", line 190, in run
    return runner.run(main)
           ^^^^^^^^^^^^^^^^
  File "C:\Program Files\Python311\Lib\asyncio\runners.py", line 123, in run
    raise KeyboardInterrupt()
KeyboardInterrupt

During handling of the above exception, another exception occurred:

Traceback (most recent call last):
  File "C:\Program Files\Python311\Lib\contextlib.py", line 222, in __aexit__
    await self.gen.athrow(typ, value, traceback)
  File "E:\tech\trm-os-branches\trm_api\main.py", line 31, in lifespan
    yield
  File "C:\Users\devpc\AppData\Roaming\Python\Python311\site-packages\starlette\routing.py", line 743, in lifespan
    await receive()
  File "C:\Users\devpc\AppData\Roaming\Python\Python311\site-packages\uvicorn\lifespan\on.py", line 137, in receive
    return await self.receive_queue.get()
           ^^^^^^^^^^^^^^^^^^^^^^^^^^^^^^
  File "C:\Program Files\Python311\Lib\asyncio\queues.py", line 158, in get
    await getter
asyncio.exceptions.CancelledError

2025-07-04 00:14:17,944 - uvicorn.error - INFO - Application startup complete.
2025-07-04 00:19:16,598 - uvicorn.error - INFO - Shutting down
2025-07-04 00:19:16,707 - uvicorn.error - INFO - Waiting for application shutdown.
2025-07-04 00:19:16,708 - uvicorn.error - INFO - Application shutdown complete.
2025-07-04 00:19:16,708 - uvicorn.error - INFO - Finished server process [41592]
2025-07-04 00:19:18,121 - uvicorn.error - INFO - Application startup complete.
2025-07-04 00:19:18,123 - uvicorn.error - ERROR - Traceback (most recent call last):
  File "C:\Program Files\Python311\Lib\asyncio\runners.py", line 118, in run
    return self._loop.run_until_complete(task)
           ^^^^^^^^^^^^^^^^^^^^^^^^^^^^^^^^^^^
  File "C:\Program Files\Python311\Lib\asyncio\base_events.py", line 650, in run_until_complete
    return future.result()
           ^^^^^^^^^^^^^^^
asyncio.exceptions.CancelledError

During handling of the above exception, another exception occurred:

Traceback (most recent call last):
  File "C:\Program Files\Python311\Lib\asyncio\runners.py", line 190, in run
    return runner.run(main)
           ^^^^^^^^^^^^^^^^
  File "C:\Program Files\Python311\Lib\asyncio\runners.py", line 123, in run
    raise KeyboardInterrupt()
KeyboardInterrupt

During handling of the above exception, another exception occurred:

Traceback (most recent call last):
  File "C:\Program Files\Python311\Lib\contextlib.py", line 222, in __aexit__
    await self.gen.athrow(typ, value, traceback)
  File "E:\tech\trm-os-branches\trm_api\main.py", line 31, in lifespan
    yield
  File "C:\Users\devpc\AppData\Roaming\Python\Python311\site-packages\starlette\routing.py", line 743, in lifespan
    await receive()
  File "C:\Users\devpc\AppData\Roaming\Python\Python311\site-packages\uvicorn\lifespan\on.py", line 137, in receive
    return await self.receive_queue.get()
           ^^^^^^^^^^^^^^^^^^^^^^^^^^^^^^
  File "C:\Program Files\Python311\Lib\asyncio\queues.py", line 158, in get
    await getter
asyncio.exceptions.CancelledError

2025-07-04 00:19:19,445 - uvicorn.error - INFO - Application startup complete.
2025-07-04 00:23:43,886 - uvicorn.error - INFO - Application startup complete.
2025-07-04 00:24:18,380 - uvicorn.error - INFO - Shutting down
2025-07-04 00:24:18,490 - uvicorn.error - INFO - Waiting for application shutdown.
2025-07-04 00:24:18,490 - uvicorn.error - INFO - Application shutdown complete.
2025-07-04 00:24:18,491 - uvicorn.error - INFO - Finished server process [20176]
2025-07-04 00:24:19,927 - uvicorn.error - INFO - Application startup complete.
2025-07-04 00:24:19,929 - uvicorn.error - ERROR - Traceback (most recent call last):
  File "C:\Program Files\Python311\Lib\asyncio\runners.py", line 118, in run
    return self._loop.run_until_complete(task)
           ^^^^^^^^^^^^^^^^^^^^^^^^^^^^^^^^^^^
  File "C:\Program Files\Python311\Lib\asyncio\base_events.py", line 650, in run_until_complete
    return future.result()
           ^^^^^^^^^^^^^^^
asyncio.exceptions.CancelledError

During handling of the above exception, another exception occurred:

Traceback (most recent call last):
  File "C:\Program Files\Python311\Lib\asyncio\runners.py", line 190, in run
    return runner.run(main)
           ^^^^^^^^^^^^^^^^
  File "C:\Program Files\Python311\Lib\asyncio\runners.py", line 123, in run
    raise KeyboardInterrupt()
KeyboardInterrupt

During handling of the above exception, another exception occurred:

Traceback (most recent call last):
  File "C:\Program Files\Python311\Lib\contextlib.py", line 222, in __aexit__
    await self.gen.athrow(typ, value, traceback)
  File "E:\tech\trm-os-branches\trm_api\main.py", line 31, in lifespan
    yield
  File "C:\Users\devpc\AppData\Roaming\Python\Python311\site-packages\starlette\routing.py", line 743, in lifespan
    await receive()
  File "C:\Users\devpc\AppData\Roaming\Python\Python311\site-packages\uvicorn\lifespan\on.py", line 137, in receive
    return await self.receive_queue.get()
           ^^^^^^^^^^^^^^^^^^^^^^^^^^^^^^
  File "C:\Program Files\Python311\Lib\asyncio\queues.py", line 158, in get
    await getter
asyncio.exceptions.CancelledError

2025-07-04 00:24:21,856 - uvicorn.error - INFO - Application startup complete.
2025-07-04 00:24:29,195 - uvicorn.access - INFO - None:0 - "GET /?vscodeBrowserReqId=1751563469185 HTTP/1.1" 200
2025-07-04 00:24:45,643 - uvicorn.error - INFO - Shutting down
2025-07-04 00:24:45,752 - uvicorn.error - INFO - Waiting for application shutdown.
2025-07-04 00:24:45,753 - uvicorn.error - INFO - Application shutdown complete.
2025-07-04 00:24:45,753 - uvicorn.error - INFO - Finished server process [6152]
2025-07-04 00:29:20,258 - uvicorn.error - INFO - Shutting down
2025-07-04 00:29:20,367 - uvicorn.error - INFO - Waiting for application shutdown.
2025-07-04 00:29:20,368 - uvicorn.error - INFO - Application shutdown complete.
2025-07-04 00:29:20,368 - uvicorn.error - INFO - Finished server process [41448]
2025-07-04 00:29:21,700 - uvicorn.error - INFO - Application startup complete.
2025-07-04 00:29:21,702 - uvicorn.error - ERROR - Traceback (most recent call last):
  File "C:\Program Files\Python311\Lib\asyncio\runners.py", line 118, in run
    return self._loop.run_until_complete(task)
           ^^^^^^^^^^^^^^^^^^^^^^^^^^^^^^^^^^^
  File "C:\Program Files\Python311\Lib\asyncio\base_events.py", line 650, in run_until_complete
    return future.result()
           ^^^^^^^^^^^^^^^
asyncio.exceptions.CancelledError

During handling of the above exception, another exception occurred:

Traceback (most recent call last):
  File "C:\Program Files\Python311\Lib\asyncio\runners.py", line 190, in run
    return runner.run(main)
           ^^^^^^^^^^^^^^^^
  File "C:\Program Files\Python311\Lib\asyncio\runners.py", line 123, in run
    raise KeyboardInterrupt()
KeyboardInterrupt

During handling of the above exception, another exception occurred:

Traceback (most recent call last):
  File "C:\Program Files\Python311\Lib\contextlib.py", line 222, in __aexit__
    await self.gen.athrow(typ, value, traceback)
  File "E:\tech\trm-os-branches\trm_api\main.py", line 31, in lifespan
    yield
  File "C:\Users\devpc\AppData\Roaming\Python\Python311\site-packages\starlette\routing.py", line 743, in lifespan
    await receive()
  File "C:\Users\devpc\AppData\Roaming\Python\Python311\site-packages\uvicorn\lifespan\on.py", line 137, in receive
    return await self.receive_queue.get()
           ^^^^^^^^^^^^^^^^^^^^^^^^^^^^^^
  File "C:\Program Files\Python311\Lib\asyncio\queues.py", line 158, in get
    await getter
asyncio.exceptions.CancelledError

2025-07-04 00:29:23,105 - uvicorn.error - INFO - Application startup complete.
2025-07-04 00:34:21,921 - uvicorn.error - INFO - Shutting down
2025-07-04 00:34:22,031 - uvicorn.error - INFO - Waiting for application shutdown.
2025-07-04 00:34:22,032 - uvicorn.error - INFO - Application shutdown complete.
2025-07-04 00:34:22,033 - uvicorn.error - INFO - Finished server process [17256]
2025-07-04 00:34:23,751 - uvicorn.error - INFO - Application startup complete.
2025-07-04 00:34:23,753 - uvicorn.error - ERROR - Traceback (most recent call last):
  File "C:\Program Files\Python311\Lib\asyncio\runners.py", line 118, in run
    return self._loop.run_until_complete(task)
           ^^^^^^^^^^^^^^^^^^^^^^^^^^^^^^^^^^^
  File "C:\Program Files\Python311\Lib\asyncio\base_events.py", line 650, in run_until_complete
    return future.result()
           ^^^^^^^^^^^^^^^
asyncio.exceptions.CancelledError

During handling of the above exception, another exception occurred:

Traceback (most recent call last):
  File "C:\Program Files\Python311\Lib\asyncio\runners.py", line 190, in run
    return runner.run(main)
           ^^^^^^^^^^^^^^^^
  File "C:\Program Files\Python311\Lib\asyncio\runners.py", line 123, in run
    raise KeyboardInterrupt()
KeyboardInterrupt

During handling of the above exception, another exception occurred:

Traceback (most recent call last):
  File "C:\Program Files\Python311\Lib\contextlib.py", line 222, in __aexit__
    await self.gen.athrow(typ, value, traceback)
  File "E:\tech\trm-os-branches\trm_api\main.py", line 31, in lifespan
    yield
  File "C:\Users\devpc\AppData\Roaming\Python\Python311\site-packages\starlette\routing.py", line 743, in lifespan
    await receive()
  File "C:\Users\devpc\AppData\Roaming\Python\Python311\site-packages\uvicorn\lifespan\on.py", line 137, in receive
    return await self.receive_queue.get()
           ^^^^^^^^^^^^^^^^^^^^^^^^^^^^^^
  File "C:\Program Files\Python311\Lib\asyncio\queues.py", line 158, in get
    await getter
asyncio.exceptions.CancelledError

2025-07-04 00:34:25,285 - uvicorn.error - INFO - Application startup complete.
2025-07-04 00:36:30,813 - uvicorn.error - INFO - Shutting down
2025-07-04 00:36:30,922 - uvicorn.error - INFO - Waiting for application shutdown.
2025-07-04 00:36:30,923 - uvicorn.error - INFO - Application shutdown complete.
2025-07-04 00:36:30,923 - uvicorn.error - INFO - Finished server process [41708]
2025-07-04 00:36:32,552 - uvicorn.error - INFO - Application startup complete.
2025-07-04 00:36:32,554 - uvicorn.error - ERROR - Traceback (most recent call last):
  File "C:\Program Files\Python311\Lib\asyncio\runners.py", line 118, in run
    return self._loop.run_until_complete(task)
           ^^^^^^^^^^^^^^^^^^^^^^^^^^^^^^^^^^^
  File "C:\Program Files\Python311\Lib\asyncio\base_events.py", line 650, in run_until_complete
    return future.result()
           ^^^^^^^^^^^^^^^
asyncio.exceptions.CancelledError

During handling of the above exception, another exception occurred:

Traceback (most recent call last):
  File "C:\Program Files\Python311\Lib\asyncio\runners.py", line 190, in run
    return runner.run(main)
           ^^^^^^^^^^^^^^^^
  File "C:\Program Files\Python311\Lib\asyncio\runners.py", line 123, in run
    raise KeyboardInterrupt()
KeyboardInterrupt

During handling of the above exception, another exception occurred:

Traceback (most recent call last):
  File "C:\Program Files\Python311\Lib\contextlib.py", line 222, in __aexit__
    await self.gen.athrow(typ, value, traceback)
  File "E:\tech\trm-os-branches\trm_api\main.py", line 31, in lifespan
    yield
  File "C:\Users\devpc\AppData\Roaming\Python\Python311\site-packages\starlette\routing.py", line 743, in lifespan
    await receive()
  File "C:\Users\devpc\AppData\Roaming\Python\Python311\site-packages\uvicorn\lifespan\on.py", line 137, in receive
    return await self.receive_queue.get()
           ^^^^^^^^^^^^^^^^^^^^^^^^^^^^^^
  File "C:\Program Files\Python311\Lib\asyncio\queues.py", line 158, in get
    await getter
asyncio.exceptions.CancelledError

2025-07-04 00:36:34,047 - uvicorn.error - INFO - Application startup complete.
2025-07-04 00:37:26,522 - uvicorn.error - INFO - Application startup complete.
2025-07-04 00:38:08,078 - uvicorn.error - INFO - Shutting down
2025-07-04 00:38:08,185 - uvicorn.error - INFO - Waiting for application shutdown.
2025-07-04 00:38:08,192 - uvicorn.error - INFO - Application shutdown complete.
2025-07-04 00:38:08,194 - uvicorn.error - INFO - Finished server process [38704]
2025-07-04 00:38:13,527 - uvicorn.access - INFO - None:0 - "GET /?vscodeBrowserReqId=1751564293516 HTTP/1.1" 200
2025-07-04 00:38:13,605 - uvicorn.error - INFO - Shutting down
2025-07-04 00:38:13,715 - uvicorn.error - INFO - Waiting for application shutdown.
2025-07-04 00:38:13,715 - uvicorn.error - INFO - Application shutdown complete.
2025-07-04 00:38:13,715 - uvicorn.error - INFO - Finished server process [40268]
2025-07-04 00:38:15,199 - uvicorn.error - INFO - Application startup complete.
2025-07-04 00:39:46,762 - uvicorn.error - INFO - Shutting down
2025-07-04 00:39:46,871 - uvicorn.error - INFO - Waiting for application shutdown.
2025-07-04 00:39:46,873 - uvicorn.error - INFO - Application shutdown complete.
2025-07-04 00:39:46,874 - uvicorn.error - INFO - Finished server process [35620]
2025-07-04 00:39:48,577 - uvicorn.error - INFO - Application startup complete.
2025-07-04 00:39:48,579 - uvicorn.error - ERROR - Traceback (most recent call last):
  File "C:\Program Files\Python311\Lib\asyncio\runners.py", line 118, in run
    return self._loop.run_until_complete(task)
           ^^^^^^^^^^^^^^^^^^^^^^^^^^^^^^^^^^^
  File "C:\Program Files\Python311\Lib\asyncio\base_events.py", line 650, in run_until_complete
    return future.result()
           ^^^^^^^^^^^^^^^
asyncio.exceptions.CancelledError

During handling of the above exception, another exception occurred:

Traceback (most recent call last):
  File "C:\Program Files\Python311\Lib\asyncio\runners.py", line 190, in run
    return runner.run(main)
           ^^^^^^^^^^^^^^^^
  File "C:\Program Files\Python311\Lib\asyncio\runners.py", line 123, in run
    raise KeyboardInterrupt()
KeyboardInterrupt

During handling of the above exception, another exception occurred:

Traceback (most recent call last):
  File "C:\Program Files\Python311\Lib\contextlib.py", line 222, in __aexit__
    await self.gen.athrow(typ, value, traceback)
  File "E:\tech\trm-os-branches\trm_api\main.py", line 31, in lifespan
    yield
  File "C:\Users\devpc\AppData\Roaming\Python\Python311\site-packages\starlette\routing.py", line 743, in lifespan
    await receive()
  File "C:\Users\devpc\AppData\Roaming\Python\Python311\site-packages\uvicorn\lifespan\on.py", line 137, in receive
    return await self.receive_queue.get()
           ^^^^^^^^^^^^^^^^^^^^^^^^^^^^^^
  File "C:\Program Files\Python311\Lib\asyncio\queues.py", line 158, in get
    await getter
asyncio.exceptions.CancelledError

2025-07-04 00:39:49,963 - uvicorn.error - INFO - Application startup complete.
2025-07-04 00:41:27,438 - uvicorn.error - INFO - Application startup complete.
2025-07-04 00:41:28,024 - uvicorn.error - INFO - Application startup complete.
2025-07-04 00:41:53,100 - uvicorn.error - INFO - Shutting down
2025-07-04 00:41:53,208 - uvicorn.error - INFO - Waiting for application shutdown.
2025-07-04 00:41:53,209 - uvicorn.error - INFO - Application shutdown complete.
2025-07-04 00:41:53,209 - uvicorn.error - INFO - Finished server process [21004]
2025-07-04 00:41:53,676 - uvicorn.error - INFO - Shutting down
2025-07-04 00:41:53,786 - uvicorn.error - INFO - Waiting for application shutdown.
2025-07-04 00:41:53,787 - uvicorn.error - INFO - Application shutdown complete.
2025-07-04 00:41:53,787 - uvicorn.error - INFO - Finished server process [29956]
2025-07-04 00:41:54,415 - uvicorn.error - INFO - Application startup complete.
2025-07-04 00:41:54,963 - uvicorn.error - INFO - Application startup complete.
2025-07-04 00:43:41,855 - uvicorn.error - INFO - Shutting down
2025-07-04 00:43:41,966 - uvicorn.error - INFO - Waiting for application shutdown.
2025-07-04 00:43:41,966 - uvicorn.error - INFO - Application shutdown complete.
2025-07-04 00:43:41,966 - uvicorn.error - INFO - Finished server process [4644]
2025-07-04 00:43:42,505 - uvicorn.error - INFO - Shutting down
2025-07-04 00:43:42,612 - uvicorn.error - INFO - Waiting for application shutdown.
2025-07-04 00:43:42,613 - uvicorn.error - INFO - Application shutdown complete.
2025-07-04 00:43:42,613 - uvicorn.error - INFO - Finished server process [42048]
2025-07-04 00:43:43,145 - uvicorn.error - INFO - Application startup complete.
2025-07-04 00:43:43,741 - uvicorn.error - INFO - Application startup complete.
2025-07-04 00:44:02,726 - uvicorn.error - INFO - Shutting down
2025-07-04 00:44:02,834 - uvicorn.error - INFO - Waiting for application shutdown.
2025-07-04 00:44:02,835 - uvicorn.error - INFO - Application shutdown complete.
2025-07-04 00:44:02,836 - uvicorn.error - INFO - Finished server process [38704]
2025-07-04 00:44:03,226 - uvicorn.error - INFO - Shutting down
2025-07-04 00:44:03,337 - uvicorn.error - INFO - Waiting for application shutdown.
2025-07-04 00:44:03,337 - uvicorn.error - INFO - Application shutdown complete.
2025-07-04 00:44:03,337 - uvicorn.error - INFO - Finished server process [42980]
2025-07-04 00:44:04,013 - uvicorn.error - INFO - Application startup complete.
2025-07-04 00:44:04,488 - uvicorn.error - INFO - Application startup complete.
2025-07-04 00:44:30,178 - uvicorn.error - INFO - Shutting down
2025-07-04 00:44:30,287 - uvicorn.error - INFO - Waiting for application shutdown.
2025-07-04 00:44:30,288 - uvicorn.error - INFO - Application shutdown complete.
2025-07-04 00:44:30,288 - uvicorn.error - INFO - Finished server process [22092]
2025-07-04 00:44:30,867 - uvicorn.error - INFO - Shutting down
2025-07-04 00:44:30,976 - uvicorn.error - INFO - Waiting for application shutdown.
2025-07-04 00:44:30,978 - uvicorn.error - INFO - Application shutdown complete.
2025-07-04 00:44:30,978 - uvicorn.error - INFO - Finished server process [32620]
2025-07-04 00:44:31,420 - uvicorn.error - INFO - Application startup complete.
2025-07-04 00:44:32,147 - uvicorn.error - INFO - Application startup complete.
2025-07-04 00:44:48,848 - uvicorn.error - INFO - Shutting down
2025-07-04 00:44:48,957 - uvicorn.error - INFO - Waiting for application shutdown.
2025-07-04 00:44:48,958 - uvicorn.error - INFO - Application shutdown complete.
2025-07-04 00:44:48,959 - uvicorn.error - INFO - Finished server process [40696]
2025-07-04 00:44:50,759 - uvicorn.error - INFO - Application startup complete.
2025-07-04 00:44:50,762 - uvicorn.error - ERROR - Traceback (most recent call last):
  File "C:\Program Files\Python311\Lib\asyncio\runners.py", line 118, in run
    return self._loop.run_until_complete(task)
           ^^^^^^^^^^^^^^^^^^^^^^^^^^^^^^^^^^^
  File "C:\Program Files\Python311\Lib\asyncio\base_events.py", line 650, in run_until_complete
    return future.result()
           ^^^^^^^^^^^^^^^
asyncio.exceptions.CancelledError

During handling of the above exception, another exception occurred:

Traceback (most recent call last):
  File "C:\Program Files\Python311\Lib\asyncio\runners.py", line 190, in run
    return runner.run(main)
           ^^^^^^^^^^^^^^^^
  File "C:\Program Files\Python311\Lib\asyncio\runners.py", line 123, in run
    raise KeyboardInterrupt()
KeyboardInterrupt

During handling of the above exception, another exception occurred:

Traceback (most recent call last):
  File "C:\Program Files\Python311\Lib\contextlib.py", line 222, in __aexit__
    await self.gen.athrow(typ, value, traceback)
  File "E:\tech\trm-os-branches\trm_api\main.py", line 31, in lifespan
    yield
  File "C:\Users\devpc\AppData\Roaming\Python\Python311\site-packages\starlette\routing.py", line 743, in lifespan
    await receive()
  File "C:\Users\devpc\AppData\Roaming\Python\Python311\site-packages\uvicorn\lifespan\on.py", line 137, in receive
    return await self.receive_queue.get()
           ^^^^^^^^^^^^^^^^^^^^^^^^^^^^^^
  File "C:\Program Files\Python311\Lib\asyncio\queues.py", line 158, in get
    await getter
asyncio.exceptions.CancelledError

2025-07-04 00:44:52,472 - uvicorn.error - INFO - Application startup complete.
2025-07-04 00:46:08,768 - uvicorn.error - INFO - Shutting down
2025-07-04 00:46:08,878 - uvicorn.error - INFO - Waiting for application shutdown.
2025-07-04 00:46:08,879 - uvicorn.error - INFO - Application shutdown complete.
2025-07-04 00:46:08,879 - uvicorn.error - INFO - Finished server process [42924]
2025-07-04 00:46:09,127 - uvicorn.error - INFO - Shutting down
2025-07-04 00:46:09,235 - uvicorn.error - INFO - Waiting for application shutdown.
2025-07-04 00:46:09,235 - uvicorn.error - INFO - Application shutdown complete.
2025-07-04 00:46:09,236 - uvicorn.error - INFO - Finished server process [20628]
2025-07-04 00:46:10,003 - uvicorn.error - INFO - Application startup complete.
2025-07-04 00:46:10,454 - uvicorn.error - INFO - Application startup complete.
2025-07-04 00:47:24,612 - uvicorn.error - INFO - Shutting down
2025-07-04 00:47:24,721 - uvicorn.error - INFO - Waiting for application shutdown.
2025-07-04 00:47:24,722 - uvicorn.error - INFO - Application shutdown complete.
2025-07-04 00:47:24,722 - uvicorn.error - INFO - Finished server process [30768]
2025-07-04 00:47:25,286 - uvicorn.error - INFO - Shutting down
2025-07-04 00:47:25,395 - uvicorn.error - INFO - Waiting for application shutdown.
2025-07-04 00:47:25,395 - uvicorn.error - INFO - Application shutdown complete.
2025-07-04 00:47:25,395 - uvicorn.error - INFO - Finished server process [11732]
2025-07-04 00:47:25,949 - uvicorn.error - INFO - Application startup complete.
2025-07-04 00:47:26,571 - uvicorn.error - INFO - Application startup complete.
2025-07-04 00:48:00,917 - uvicorn.error - INFO - Shutting down
2025-07-04 00:48:01,026 - uvicorn.error - INFO - Waiting for application shutdown.
2025-07-04 00:48:01,026 - uvicorn.error - INFO - Application shutdown complete.
2025-07-04 00:48:01,027 - uvicorn.error - INFO - Finished server process [26892]
2025-07-04 00:48:01,213 - uvicorn.error - INFO - Shutting down
2025-07-04 00:48:01,323 - uvicorn.error - INFO - Waiting for application shutdown.
2025-07-04 00:48:01,323 - uvicorn.error - INFO - Application shutdown complete.
2025-07-04 00:48:01,324 - uvicorn.error - INFO - Finished server process [23896]
2025-07-04 00:48:02,144 - uvicorn.error - INFO - Application startup complete.
2025-07-04 00:48:02,517 - uvicorn.error - INFO - Application startup complete.
2025-07-04 00:48:36,324 - uvicorn.error - INFO - Shutting down
2025-07-04 00:48:36,432 - uvicorn.error - INFO - Waiting for application shutdown.
2025-07-04 00:48:36,433 - uvicorn.error - INFO - Application shutdown complete.
2025-07-04 00:48:36,433 - uvicorn.error - INFO - Finished server process [30416]
2025-07-04 00:48:36,933 - uvicorn.error - INFO - Shutting down
2025-07-04 00:48:37,041 - uvicorn.error - INFO - Waiting for application shutdown.
2025-07-04 00:48:37,042 - uvicorn.error - INFO - Application shutdown complete.
2025-07-04 00:48:37,042 - uvicorn.error - INFO - Finished server process [42900]
2025-07-04 00:48:37,573 - uvicorn.error - INFO - Application startup complete.
2025-07-04 00:48:38,217 - uvicorn.error - INFO - Application startup complete.
2025-07-04 00:49:51,217 - uvicorn.error - INFO - Shutting down
2025-07-04 00:49:51,328 - uvicorn.error - INFO - Waiting for application shutdown.
2025-07-04 00:49:51,328 - uvicorn.error - INFO - Application shutdown complete.
2025-07-04 00:49:51,329 - uvicorn.error - INFO - Finished server process [42272]
2025-07-04 00:49:53,022 - uvicorn.error - INFO - Application startup complete.
2025-07-04 00:49:53,025 - uvicorn.error - ERROR - Traceback (most recent call last):
  File "C:\Program Files\Python311\Lib\asyncio\runners.py", line 118, in run
    return self._loop.run_until_complete(task)
           ^^^^^^^^^^^^^^^^^^^^^^^^^^^^^^^^^^^
  File "C:\Program Files\Python311\Lib\asyncio\base_events.py", line 650, in run_until_complete
    return future.result()
           ^^^^^^^^^^^^^^^
asyncio.exceptions.CancelledError

During handling of the above exception, another exception occurred:

Traceback (most recent call last):
  File "C:\Program Files\Python311\Lib\asyncio\runners.py", line 190, in run
    return runner.run(main)
           ^^^^^^^^^^^^^^^^
  File "C:\Program Files\Python311\Lib\asyncio\runners.py", line 123, in run
    raise KeyboardInterrupt()
KeyboardInterrupt

During handling of the above exception, another exception occurred:

Traceback (most recent call last):
  File "C:\Program Files\Python311\Lib\contextlib.py", line 222, in __aexit__
    await self.gen.athrow(typ, value, traceback)
  File "E:\tech\trm-os-branches\trm_api\main.py", line 31, in lifespan
    yield
  File "C:\Users\devpc\AppData\Roaming\Python\Python311\site-packages\starlette\routing.py", line 743, in lifespan
    await receive()
  File "C:\Users\devpc\AppData\Roaming\Python\Python311\site-packages\uvicorn\lifespan\on.py", line 137, in receive
    return await self.receive_queue.get()
           ^^^^^^^^^^^^^^^^^^^^^^^^^^^^^^
  File "C:\Program Files\Python311\Lib\asyncio\queues.py", line 158, in get
    await getter
asyncio.exceptions.CancelledError

2025-07-04 00:49:54,719 - uvicorn.error - INFO - Application startup complete.
2025-07-04 00:51:38,573 - uvicorn.error - INFO - Shutting down
2025-07-04 00:51:38,683 - uvicorn.error - INFO - Waiting for application shutdown.
2025-07-04 00:51:38,685 - uvicorn.error - INFO - Application shutdown complete.
2025-07-04 00:51:38,685 - uvicorn.error - INFO - Finished server process [41120]
2025-07-04 00:51:39,226 - uvicorn.error - INFO - Shutting down
2025-07-04 00:51:39,335 - uvicorn.error - INFO - Waiting for application shutdown.
2025-07-04 00:51:39,336 - uvicorn.error - INFO - Application shutdown complete.
2025-07-04 00:51:39,336 - uvicorn.error - INFO - Finished server process [40984]
2025-07-04 00:51:39,959 - uvicorn.error - INFO - Application startup complete.
2025-07-04 00:51:40,613 - uvicorn.error - INFO - Application startup complete.
2025-07-04 00:53:24,632 - uvicorn.error - INFO - Shutting down
2025-07-04 00:53:24,742 - uvicorn.error - INFO - Waiting for application shutdown.
2025-07-04 00:53:24,743 - uvicorn.error - INFO - Application shutdown complete.
2025-07-04 00:53:24,744 - uvicorn.error - INFO - Finished server process [40652]
2025-07-04 00:53:25,819 - uvicorn.error - INFO - Shutting down
2025-07-04 00:53:25,927 - uvicorn.error - INFO - Waiting for application shutdown.
2025-07-04 00:53:25,929 - uvicorn.error - INFO - Application shutdown complete.
2025-07-04 00:53:25,929 - uvicorn.error - INFO - Finished server process [18860]
2025-07-04 00:53:26,145 - uvicorn.error - INFO - Application startup complete.
2025-07-04 00:53:27,359 - uvicorn.error - INFO - Application startup complete.
2025-07-04 00:54:53,402 - uvicorn.error - INFO - Shutting down
2025-07-04 00:54:53,513 - uvicorn.error - INFO - Waiting for application shutdown.
2025-07-04 00:54:53,514 - uvicorn.error - INFO - Application shutdown complete.
2025-07-04 00:54:53,514 - uvicorn.error - INFO - Finished server process [22992]
2025-07-04 00:54:55,105 - uvicorn.error - INFO - Application startup complete.
2025-07-04 00:54:55,108 - uvicorn.error - ERROR - Traceback (most recent call last):
  File "C:\Program Files\Python311\Lib\asyncio\runners.py", line 118, in run
    return self._loop.run_until_complete(task)
           ^^^^^^^^^^^^^^^^^^^^^^^^^^^^^^^^^^^
  File "C:\Program Files\Python311\Lib\asyncio\base_events.py", line 650, in run_until_complete
    return future.result()
           ^^^^^^^^^^^^^^^
asyncio.exceptions.CancelledError

During handling of the above exception, another exception occurred:

Traceback (most recent call last):
  File "C:\Program Files\Python311\Lib\asyncio\runners.py", line 190, in run
    return runner.run(main)
           ^^^^^^^^^^^^^^^^
  File "C:\Program Files\Python311\Lib\asyncio\runners.py", line 123, in run
    raise KeyboardInterrupt()
KeyboardInterrupt

During handling of the above exception, another exception occurred:

Traceback (most recent call last):
  File "C:\Program Files\Python311\Lib\contextlib.py", line 222, in __aexit__
    await self.gen.athrow(typ, value, traceback)
  File "E:\tech\trm-os-branches\trm_api\main.py", line 31, in lifespan
    yield
  File "C:\Users\devpc\AppData\Roaming\Python\Python311\site-packages\starlette\routing.py", line 743, in lifespan
    await receive()
  File "C:\Users\devpc\AppData\Roaming\Python\Python311\site-packages\uvicorn\lifespan\on.py", line 137, in receive
    return await self.receive_queue.get()
           ^^^^^^^^^^^^^^^^^^^^^^^^^^^^^^
  File "C:\Program Files\Python311\Lib\asyncio\queues.py", line 158, in get
    await getter
asyncio.exceptions.CancelledError

2025-07-04 00:54:56,658 - uvicorn.error - INFO - Application startup complete.
2025-07-04 00:55:21,225 - uvicorn.error - INFO - Shutting down
2025-07-04 00:55:21,334 - uvicorn.error - INFO - Waiting for application shutdown.
2025-07-04 00:55:21,340 - uvicorn.error - INFO - Application shutdown complete.
2025-07-04 00:55:21,341 - uvicorn.error - INFO - Finished server process [38932]
2025-07-04 00:55:22,397 - uvicorn.error - INFO - Application startup complete.
2025-07-04 00:55:22,410 - uvicorn.error - INFO - Shutting down
2025-07-04 00:55:22,518 - uvicorn.error - INFO - Waiting for application shutdown.
2025-07-04 00:55:22,521 - uvicorn.error - INFO - Application shutdown complete.
2025-07-04 00:55:22,521 - uvicorn.error - INFO - Finished server process [16680]
2025-07-04 00:55:23,628 - uvicorn.error - INFO - Application startup complete.
2025-07-04 00:57:06,692 - uvicorn.error - INFO - Shutting down
2025-07-04 00:57:06,818 - uvicorn.error - INFO - Waiting for application shutdown.
2025-07-04 00:57:06,831 - uvicorn.error - INFO - Application shutdown complete.
2025-07-04 00:57:06,834 - uvicorn.error - INFO - Finished server process [25516]
2025-07-04 00:57:07,532 - uvicorn.error - INFO - Shutting down
2025-07-04 00:57:07,640 - uvicorn.error - INFO - Waiting for application shutdown.
2025-07-04 00:57:07,641 - uvicorn.error - INFO - Application shutdown complete.
2025-07-04 00:57:07,642 - uvicorn.error - INFO - Finished server process [26300]
2025-07-04 00:57:07,921 - uvicorn.error - INFO - Application startup complete.
2025-07-04 00:57:08,686 - uvicorn.error - INFO - Application startup complete.
2025-07-04 00:59:23,686 - uvicorn.access - INFO - 127.0.0.1:53898 - "GET /api/v1/openapi.json HTTP/1.1" 200
2025-07-04 00:59:23,798 - uvicorn.error - INFO - Shutting down
2025-07-04 00:59:23,907 - uvicorn.error - INFO - Waiting for application shutdown.
2025-07-04 00:59:23,907 - uvicorn.error - INFO - Application shutdown complete.
2025-07-04 00:59:23,907 - uvicorn.error - INFO - Finished server process [37152]
2025-07-04 00:59:25,349 - uvicorn.error - INFO - Application startup complete.
2025-07-04 00:59:25,352 - uvicorn.error - ERROR - Traceback (most recent call last):
  File "C:\Program Files\Python311\Lib\asyncio\runners.py", line 118, in run
    return self._loop.run_until_complete(task)
           ^^^^^^^^^^^^^^^^^^^^^^^^^^^^^^^^^^^
  File "C:\Program Files\Python311\Lib\asyncio\base_events.py", line 650, in run_until_complete
    return future.result()
           ^^^^^^^^^^^^^^^
asyncio.exceptions.CancelledError

During handling of the above exception, another exception occurred:

Traceback (most recent call last):
  File "C:\Program Files\Python311\Lib\asyncio\runners.py", line 190, in run
    return runner.run(main)
           ^^^^^^^^^^^^^^^^
  File "C:\Program Files\Python311\Lib\asyncio\runners.py", line 123, in run
    raise KeyboardInterrupt()
KeyboardInterrupt

During handling of the above exception, another exception occurred:

Traceback (most recent call last):
  File "C:\Program Files\Python311\Lib\contextlib.py", line 222, in __aexit__
    await self.gen.athrow(typ, value, traceback)
  File "E:\tech\trm-os-branches\trm_api\main.py", line 31, in lifespan
    yield
  File "C:\Users\devpc\AppData\Roaming\Python\Python311\site-packages\starlette\routing.py", line 743, in lifespan
    await receive()
  File "C:\Users\devpc\AppData\Roaming\Python\Python311\site-packages\uvicorn\lifespan\on.py", line 137, in receive
    return await self.receive_queue.get()
           ^^^^^^^^^^^^^^^^^^^^^^^^^^^^^^
  File "C:\Program Files\Python311\Lib\asyncio\queues.py", line 158, in get
    await getter
asyncio.exceptions.CancelledError

2025-07-04 00:59:26,747 - uvicorn.error - INFO - Application startup complete.
2025-07-04 00:59:57,473 - uvicorn.error - INFO - Shutting down
2025-07-04 00:59:57,582 - uvicorn.error - INFO - Waiting for application shutdown.
2025-07-04 00:59:57,588 - uvicorn.error - INFO - Application shutdown complete.
2025-07-04 00:59:57,589 - uvicorn.error - INFO - Finished server process [42092]
2025-07-04 00:59:58,639 - uvicorn.error - INFO - Application startup complete.
2025-07-04 00:59:58,996 - uvicorn.error - INFO - Shutting down
2025-07-04 00:59:59,105 - uvicorn.error - INFO - Waiting for application shutdown.
2025-07-04 00:59:59,107 - uvicorn.error - INFO - Application shutdown complete.
2025-07-04 00:59:59,107 - uvicorn.error - INFO - Finished server process [41644]
2025-07-04 01:00:00,198 - uvicorn.error - INFO - Application startup complete.
2025-07-04 01:00:37,823 - uvicorn.error - INFO - Shutting down
2025-07-04 01:00:37,932 - uvicorn.error - INFO - Waiting for application shutdown.
2025-07-04 01:00:37,934 - uvicorn.error - INFO - Application shutdown complete.
2025-07-04 01:00:37,935 - uvicorn.error - INFO - Finished server process [39984]
2025-07-04 01:00:38,662 - uvicorn.error - INFO - Shutting down
2025-07-04 01:00:38,771 - uvicorn.error - INFO - Waiting for application shutdown.
2025-07-04 01:00:38,772 - uvicorn.error - INFO - Application shutdown complete.
2025-07-04 01:00:38,772 - uvicorn.error - INFO - Finished server process [13240]
2025-07-04 01:00:39,030 - uvicorn.error - INFO - Application startup complete.
2025-07-04 01:00:39,810 - uvicorn.error - INFO - Application startup complete.
2025-07-04 01:01:58,702 - uvicorn.error - INFO - Shutting down
2025-07-04 01:01:58,812 - uvicorn.error - INFO - Waiting for application shutdown.
2025-07-04 01:01:58,830 - uvicorn.error - INFO - Application shutdown complete.
2025-07-04 01:01:58,830 - uvicorn.error - INFO - Finished server process [19040]
2025-07-04 01:01:59,771 - uvicorn.error - INFO - Shutting down
2025-07-04 01:01:59,841 - uvicorn.error - INFO - Application startup complete.
2025-07-04 01:01:59,880 - uvicorn.error - INFO - Waiting for application shutdown.
2025-07-04 01:01:59,886 - uvicorn.error - INFO - Application shutdown complete.
2025-07-04 01:01:59,886 - uvicorn.error - INFO - Finished server process [27176]
2025-07-04 01:02:00,963 - uvicorn.error - INFO - Application startup complete.
2025-07-04 01:04:00,351 - uvicorn.error - INFO - Shutting down
2025-07-04 01:04:00,461 - uvicorn.error - INFO - Waiting for application shutdown.
2025-07-04 01:04:00,463 - uvicorn.error - INFO - Application shutdown complete.
2025-07-04 01:04:00,463 - uvicorn.error - INFO - Finished server process [36076]
2025-07-04 01:04:00,883 - uvicorn.error - INFO - Shutting down
2025-07-04 01:04:00,993 - uvicorn.error - INFO - Waiting for application shutdown.
2025-07-04 01:04:00,994 - uvicorn.error - INFO - Application shutdown complete.
2025-07-04 01:04:00,994 - uvicorn.error - INFO - Finished server process [32772]
2025-07-04 01:04:01,591 - uvicorn.error - INFO - Application startup complete.
2025-07-04 01:04:02,102 - uvicorn.error - INFO - Application startup complete.
2025-07-04 01:04:25,612 - uvicorn.error - INFO - Shutting down
2025-07-04 01:04:25,720 - uvicorn.error - INFO - Waiting for application shutdown.
2025-07-04 01:04:25,721 - uvicorn.error - INFO - Application shutdown complete.
2025-07-04 01:04:25,721 - uvicorn.error - INFO - Finished server process [10768]
2025-07-04 01:04:27,347 - uvicorn.error - INFO - Application startup complete.
2025-07-04 01:04:27,349 - uvicorn.error - ERROR - Traceback (most recent call last):
  File "C:\Program Files\Python311\Lib\asyncio\runners.py", line 118, in run
    return self._loop.run_until_complete(task)
           ^^^^^^^^^^^^^^^^^^^^^^^^^^^^^^^^^^^
  File "C:\Program Files\Python311\Lib\asyncio\base_events.py", line 650, in run_until_complete
    return future.result()
           ^^^^^^^^^^^^^^^
asyncio.exceptions.CancelledError

During handling of the above exception, another exception occurred:

Traceback (most recent call last):
  File "C:\Program Files\Python311\Lib\asyncio\runners.py", line 190, in run
    return runner.run(main)
           ^^^^^^^^^^^^^^^^
  File "C:\Program Files\Python311\Lib\asyncio\runners.py", line 123, in run
    raise KeyboardInterrupt()
KeyboardInterrupt

During handling of the above exception, another exception occurred:

Traceback (most recent call last):
  File "C:\Program Files\Python311\Lib\contextlib.py", line 222, in __aexit__
    await self.gen.athrow(typ, value, traceback)
  File "E:\tech\trm-os-branches\trm_api\main.py", line 31, in lifespan
    yield
  File "C:\Users\devpc\AppData\Roaming\Python\Python311\site-packages\starlette\routing.py", line 743, in lifespan
    await receive()
  File "C:\Users\devpc\AppData\Roaming\Python\Python311\site-packages\uvicorn\lifespan\on.py", line 137, in receive
    return await self.receive_queue.get()
           ^^^^^^^^^^^^^^^^^^^^^^^^^^^^^^
  File "C:\Program Files\Python311\Lib\asyncio\queues.py", line 158, in get
    await getter
asyncio.exceptions.CancelledError

2025-07-04 01:04:28,880 - uvicorn.error - INFO - Application startup complete.
2025-07-04 01:06:17,800 - uvicorn.error - INFO - Shutting down
2025-07-04 01:06:17,831 - uvicorn.error - INFO - Shutting down
2025-07-04 01:06:17,910 - uvicorn.error - INFO - Waiting for application shutdown.
2025-07-04 01:06:17,910 - uvicorn.error - INFO - Application shutdown complete.
2025-07-04 01:06:17,910 - uvicorn.error - INFO - Finished server process [16804]
2025-07-04 01:06:17,941 - uvicorn.error - INFO - Waiting for application shutdown.
2025-07-04 01:06:17,942 - uvicorn.error - INFO - Application shutdown complete.
2025-07-04 01:06:17,942 - uvicorn.error - INFO - Finished server process [13988]
2025-07-04 01:06:19,021 - uvicorn.error - INFO - Application startup complete.
2025-07-04 01:06:19,022 - uvicorn.error - INFO - Application startup complete.
2025-07-04 01:09:27,555 - uvicorn.error - INFO - Shutting down
2025-07-04 01:09:27,632 - uvicorn.error - INFO - Shutting down
2025-07-04 01:09:27,662 - uvicorn.error - INFO - Waiting for application shutdown.
2025-07-04 01:09:27,668 - uvicorn.error - INFO - Application shutdown complete.
2025-07-04 01:09:27,669 - uvicorn.error - INFO - Finished server process [26612]
2025-07-04 01:09:27,740 - uvicorn.error - INFO - Waiting for application shutdown.
2025-07-04 01:09:27,746 - uvicorn.error - INFO - Application shutdown complete.
2025-07-04 01:09:27,748 - uvicorn.error - INFO - Finished server process [35504]
2025-07-04 01:09:27,851 - uvicorn.error - INFO - Shutting down
2025-07-04 01:09:27,958 - uvicorn.error - INFO - Waiting for application shutdown.
2025-07-04 01:09:27,960 - uvicorn.error - INFO - Application shutdown complete.
2025-07-04 01:09:27,961 - uvicorn.error - INFO - Finished server process [29972]
2025-07-04 01:09:28,852 - uvicorn.error - INFO - Application startup complete.
2025-07-04 01:09:29,064 - uvicorn.error - INFO - Application startup complete.
2025-07-04 01:09:29,305 - uvicorn.error - INFO - Application startup complete.
2025-07-04 01:09:29,308 - uvicorn.error - ERROR - Traceback (most recent call last):
  File "C:\Program Files\Python311\Lib\asyncio\runners.py", line 118, in run
    return self._loop.run_until_complete(task)
           ^^^^^^^^^^^^^^^^^^^^^^^^^^^^^^^^^^^
  File "C:\Program Files\Python311\Lib\asyncio\base_events.py", line 650, in run_until_complete
    return future.result()
           ^^^^^^^^^^^^^^^
asyncio.exceptions.CancelledError

During handling of the above exception, another exception occurred:

Traceback (most recent call last):
  File "C:\Program Files\Python311\Lib\asyncio\runners.py", line 190, in run
    return runner.run(main)
           ^^^^^^^^^^^^^^^^
  File "C:\Program Files\Python311\Lib\asyncio\runners.py", line 123, in run
    raise KeyboardInterrupt()
KeyboardInterrupt

During handling of the above exception, another exception occurred:

Traceback (most recent call last):
  File "C:\Program Files\Python311\Lib\contextlib.py", line 222, in __aexit__
    await self.gen.athrow(typ, value, traceback)
  File "E:\tech\trm-os-branches\trm_api\main.py", line 31, in lifespan
    yield
  File "C:\Users\devpc\AppData\Roaming\Python\Python311\site-packages\starlette\routing.py", line 743, in lifespan
    await receive()
  File "C:\Users\devpc\AppData\Roaming\Python\Python311\site-packages\uvicorn\lifespan\on.py", line 137, in receive
    return await self.receive_queue.get()
           ^^^^^^^^^^^^^^^^^^^^^^^^^^^^^^
  File "C:\Program Files\Python311\Lib\asyncio\queues.py", line 158, in get
    await getter
asyncio.exceptions.CancelledError

2025-07-04 01:09:30,734 - uvicorn.error - INFO - Application startup complete.
2025-07-04 01:14:52,717 - uvicorn.error - INFO - Shutting down
2025-07-04 01:14:52,827 - uvicorn.error - INFO - Waiting for application shutdown.
2025-07-04 01:14:52,828 - uvicorn.error - INFO - Application shutdown complete.
2025-07-04 01:14:52,831 - uvicorn.error - INFO - Finished server process [32136]
2025-07-04 01:14:53,902 - uvicorn.error - INFO - Application startup complete.
2025-07-04 01:14:54,767 - uvicorn.error - INFO - Shutting down
2025-07-04 01:14:54,878 - uvicorn.error - INFO - Waiting for application shutdown.
2025-07-04 01:14:54,881 - uvicorn.error - INFO - Application shutdown complete.
2025-07-04 01:14:54,881 - uvicorn.error - INFO - Finished server process [41920]
2025-07-04 01:14:55,912 - uvicorn.error - INFO - Application startup complete.
2025-07-04 01:16:44,009 - uvicorn.error - INFO - Shutting down
2025-07-04 01:16:44,116 - uvicorn.error - INFO - Waiting for application shutdown.
2025-07-04 01:16:44,119 - uvicorn.error - INFO - Application shutdown complete.
2025-07-04 01:16:44,119 - uvicorn.error - INFO - Finished server process [30916]
2025-07-04 01:16:44,378 - uvicorn.error - INFO - Shutting down
2025-07-04 01:16:44,488 - uvicorn.error - INFO - Waiting for application shutdown.
2025-07-04 01:16:44,490 - uvicorn.error - INFO - Application shutdown complete.
2025-07-04 01:16:44,490 - uvicorn.error - INFO - Finished server process [42340]
2025-07-04 01:16:45,169 - uvicorn.error - INFO - Application startup complete.
2025-07-04 01:16:45,540 - uvicorn.error - INFO - Application startup complete.
2025-07-04 01:16:56,651 - uvicorn.error - INFO - Shutting down
2025-07-04 01:16:56,761 - uvicorn.error - INFO - Waiting for application shutdown.
2025-07-04 01:16:56,764 - uvicorn.error - INFO - Application shutdown complete.
2025-07-04 01:16:56,765 - uvicorn.error - INFO - Finished server process [42772]
2025-07-04 01:16:58,462 - uvicorn.error - INFO - Application startup complete.
2025-07-04 01:16:58,466 - uvicorn.error - ERROR - Traceback (most recent call last):
  File "C:\Program Files\Python311\Lib\asyncio\runners.py", line 118, in run
    return self._loop.run_until_complete(task)
           ^^^^^^^^^^^^^^^^^^^^^^^^^^^^^^^^^^^
  File "C:\Program Files\Python311\Lib\asyncio\base_events.py", line 650, in run_until_complete
    return future.result()
           ^^^^^^^^^^^^^^^
asyncio.exceptions.CancelledError

During handling of the above exception, another exception occurred:

Traceback (most recent call last):
  File "C:\Program Files\Python311\Lib\asyncio\runners.py", line 190, in run
    return runner.run(main)
           ^^^^^^^^^^^^^^^^
  File "C:\Program Files\Python311\Lib\asyncio\runners.py", line 123, in run
    raise KeyboardInterrupt()
KeyboardInterrupt

During handling of the above exception, another exception occurred:

Traceback (most recent call last):
  File "C:\Program Files\Python311\Lib\contextlib.py", line 222, in __aexit__
    await self.gen.athrow(typ, value, traceback)
  File "E:\tech\trm-os-branches\trm_api\main.py", line 31, in lifespan
    yield
  File "C:\Users\devpc\AppData\Roaming\Python\Python311\site-packages\starlette\routing.py", line 743, in lifespan
    await receive()
  File "C:\Users\devpc\AppData\Roaming\Python\Python311\site-packages\uvicorn\lifespan\on.py", line 137, in receive
    return await self.receive_queue.get()
           ^^^^^^^^^^^^^^^^^^^^^^^^^^^^^^
  File "C:\Program Files\Python311\Lib\asyncio\queues.py", line 158, in get
    await getter
asyncio.exceptions.CancelledError

2025-07-04 01:17:00,003 - uvicorn.error - INFO - Application startup complete.
2025-07-04 01:18:41,593 - uvicorn.error - INFO - Shutting down
2025-07-04 01:18:41,703 - uvicorn.error - INFO - Waiting for application shutdown.
2025-07-04 01:18:41,704 - uvicorn.error - INFO - Application shutdown complete.
2025-07-04 01:18:41,705 - uvicorn.error - INFO - Finished server process [5336]
2025-07-04 01:18:41,876 - uvicorn.error - INFO - Shutting down
2025-07-04 01:18:41,986 - uvicorn.error - INFO - Waiting for application shutdown.
2025-07-04 01:18:41,990 - uvicorn.error - INFO - Application shutdown complete.
2025-07-04 01:18:41,991 - uvicorn.error - INFO - Finished server process [24992]
2025-07-04 01:18:42,726 - uvicorn.error - INFO - Application startup complete.
2025-07-04 01:18:43,058 - uvicorn.error - INFO - Application startup complete.
2025-07-04 01:21:58,721 - uvicorn.error - INFO - Shutting down
2025-07-04 01:21:58,828 - uvicorn.error - INFO - Waiting for application shutdown.
2025-07-04 01:21:58,829 - uvicorn.error - INFO - Application shutdown complete.
2025-07-04 01:21:58,830 - uvicorn.error - INFO - Finished server process [41224]
2025-07-04 01:22:00,332 - uvicorn.error - INFO - Application startup complete.
2025-07-04 01:24:42,421 - uvicorn.error - INFO - Shutting down
2025-07-04 01:24:42,529 - uvicorn.error - INFO - Waiting for application shutdown.
2025-07-04 01:24:42,532 - uvicorn.error - INFO - Application shutdown complete.
2025-07-04 01:24:42,533 - uvicorn.error - INFO - Finished server process [25516]
2025-07-04 01:24:42,965 - uvicorn.error - INFO - Shutting down
2025-07-04 01:24:43,074 - uvicorn.error - INFO - Waiting for application shutdown.
2025-07-04 01:24:43,076 - uvicorn.error - INFO - Application shutdown complete.
2025-07-04 01:24:43,076 - uvicorn.error - INFO - Finished server process [5512]
2025-07-04 01:24:43,538 - uvicorn.error - INFO - Application startup complete.
2025-07-04 01:24:44,110 - uvicorn.error - INFO - Application startup complete.
2025-07-04 01:26:59,155 - uvicorn.error - INFO - Shutting down
2025-07-04 01:26:59,265 - uvicorn.error - INFO - Waiting for application shutdown.
2025-07-04 01:26:59,266 - uvicorn.error - INFO - Application shutdown complete.
2025-07-04 01:26:59,266 - uvicorn.error - INFO - Finished server process [40072]
2025-07-04 01:27:00,927 - uvicorn.error - INFO - Application startup complete.
2025-07-04 01:31:59,541 - uvicorn.error - INFO - Shutting down
2025-07-04 01:31:59,651 - uvicorn.error - INFO - Waiting for application shutdown.
2025-07-04 01:31:59,655 - uvicorn.error - INFO - Application shutdown complete.
2025-07-04 01:31:59,656 - uvicorn.error - INFO - Finished server process [39676]
2025-07-04 01:32:01,160 - uvicorn.error - INFO - Application startup complete.
2025-07-04 01:32:01,163 - uvicorn.error - ERROR - Traceback (most recent call last):
  File "C:\Program Files\Python311\Lib\asyncio\runners.py", line 118, in run
    return self._loop.run_until_complete(task)
           ^^^^^^^^^^^^^^^^^^^^^^^^^^^^^^^^^^^
  File "C:\Program Files\Python311\Lib\asyncio\base_events.py", line 650, in run_until_complete
    return future.result()
           ^^^^^^^^^^^^^^^
asyncio.exceptions.CancelledError

During handling of the above exception, another exception occurred:

Traceback (most recent call last):
  File "C:\Program Files\Python311\Lib\asyncio\runners.py", line 190, in run
    return runner.run(main)
           ^^^^^^^^^^^^^^^^
  File "C:\Program Files\Python311\Lib\asyncio\runners.py", line 123, in run
    raise KeyboardInterrupt()
KeyboardInterrupt

During handling of the above exception, another exception occurred:

Traceback (most recent call last):
  File "C:\Program Files\Python311\Lib\contextlib.py", line 222, in __aexit__
    await self.gen.athrow(typ, value, traceback)
  File "E:\tech\trm-os-branches\trm_api\main.py", line 31, in lifespan
    yield
  File "C:\Users\devpc\AppData\Roaming\Python\Python311\site-packages\starlette\routing.py", line 743, in lifespan
    await receive()
  File "C:\Users\devpc\AppData\Roaming\Python\Python311\site-packages\uvicorn\lifespan\on.py", line 137, in receive
    return await self.receive_queue.get()
           ^^^^^^^^^^^^^^^^^^^^^^^^^^^^^^
  File "C:\Program Files\Python311\Lib\asyncio\queues.py", line 158, in get
    await getter
asyncio.exceptions.CancelledError

2025-07-04 01:32:02,588 - uvicorn.error - INFO - Application startup complete.
2025-07-04 01:32:58,480 - uvicorn.error - INFO - Shutting down
2025-07-04 01:32:58,589 - uvicorn.error - INFO - Waiting for application shutdown.
2025-07-04 01:32:58,591 - uvicorn.error - INFO - Application shutdown complete.
2025-07-04 01:32:58,591 - uvicorn.error - INFO - Finished server process [16256]
2025-07-04 01:32:59,603 - uvicorn.error - INFO - Application startup complete.
2025-07-04 01:33:00,347 - uvicorn.error - INFO - Shutting down
2025-07-04 01:33:00,456 - uvicorn.error - INFO - Waiting for application shutdown.
2025-07-04 01:33:00,457 - uvicorn.error - INFO - Application shutdown complete.
2025-07-04 01:33:00,458 - uvicorn.error - INFO - Finished server process [25076]
2025-07-04 01:33:01,434 - uvicorn.error - INFO - Application startup complete.
2025-07-04 01:33:34,759 - uvicorn.error - INFO - Shutting down
2025-07-04 01:33:34,869 - uvicorn.error - INFO - Waiting for application shutdown.
2025-07-04 01:33:34,876 - uvicorn.error - INFO - Application shutdown complete.
2025-07-04 01:33:34,876 - uvicorn.error - INFO - Finished server process [1556]
2025-07-04 01:33:35,210 - uvicorn.error - INFO - Shutting down
2025-07-04 01:33:35,319 - uvicorn.error - INFO - Waiting for application shutdown.
2025-07-04 01:33:35,320 - uvicorn.error - INFO - Application shutdown complete.
2025-07-04 01:33:35,321 - uvicorn.error - INFO - Finished server process [42148]
2025-07-04 01:33:35,963 - uvicorn.error - INFO - Application startup complete.
2025-07-04 01:33:36,369 - uvicorn.error - INFO - Application startup complete.
2025-07-04 01:35:29,515 - uvicorn.error - INFO - Shutting down
2025-07-04 01:35:29,624 - uvicorn.error - INFO - Waiting for application shutdown.
2025-07-04 01:35:29,627 - uvicorn.error - INFO - Application shutdown complete.
2025-07-04 01:35:29,627 - uvicorn.error - INFO - Finished server process [37184]
2025-07-04 01:35:29,809 - uvicorn.error - INFO - Shutting down
2025-07-04 01:35:29,917 - uvicorn.error - INFO - Waiting for application shutdown.
2025-07-04 01:35:29,919 - uvicorn.error - INFO - Application shutdown complete.
2025-07-04 01:35:29,919 - uvicorn.error - INFO - Finished server process [33480]
2025-07-04 01:35:30,640 - uvicorn.error - INFO - Application startup complete.
2025-07-04 01:35:30,927 - uvicorn.error - INFO - Application startup complete.
2025-07-04 01:37:01,390 - uvicorn.error - INFO - Shutting down
2025-07-04 01:37:01,499 - uvicorn.error - INFO - Waiting for application shutdown.
2025-07-04 01:37:01,501 - uvicorn.error - INFO - Application shutdown complete.
2025-07-04 01:37:01,502 - uvicorn.error - INFO - Finished server process [41140]
2025-07-04 01:37:03,144 - uvicorn.error - INFO - Application startup complete.
2025-07-04 01:37:03,146 - uvicorn.error - ERROR - Traceback (most recent call last):
  File "C:\Program Files\Python311\Lib\asyncio\runners.py", line 118, in run
    return self._loop.run_until_complete(task)
           ^^^^^^^^^^^^^^^^^^^^^^^^^^^^^^^^^^^
  File "C:\Program Files\Python311\Lib\asyncio\base_events.py", line 650, in run_until_complete
    return future.result()
           ^^^^^^^^^^^^^^^
asyncio.exceptions.CancelledError

During handling of the above exception, another exception occurred:

Traceback (most recent call last):
  File "C:\Program Files\Python311\Lib\asyncio\runners.py", line 190, in run
    return runner.run(main)
           ^^^^^^^^^^^^^^^^
  File "C:\Program Files\Python311\Lib\asyncio\runners.py", line 123, in run
    raise KeyboardInterrupt()
KeyboardInterrupt

During handling of the above exception, another exception occurred:

Traceback (most recent call last):
  File "C:\Program Files\Python311\Lib\contextlib.py", line 222, in __aexit__
    await self.gen.athrow(typ, value, traceback)
  File "E:\tech\trm-os-branches\trm_api\main.py", line 31, in lifespan
    yield
  File "C:\Users\devpc\AppData\Roaming\Python\Python311\site-packages\starlette\routing.py", line 743, in lifespan
    await receive()
  File "C:\Users\devpc\AppData\Roaming\Python\Python311\site-packages\uvicorn\lifespan\on.py", line 137, in receive
    return await self.receive_queue.get()
           ^^^^^^^^^^^^^^^^^^^^^^^^^^^^^^
  File "C:\Program Files\Python311\Lib\asyncio\queues.py", line 158, in get
    await getter
asyncio.exceptions.CancelledError

2025-07-04 01:37:04,651 - uvicorn.error - INFO - Application startup complete.
2025-07-04 01:39:05,928 - uvicorn.error - INFO - Shutting down
2025-07-04 01:39:06,035 - uvicorn.error - INFO - Waiting for application shutdown.
2025-07-04 01:39:06,038 - uvicorn.error - INFO - Application shutdown complete.
2025-07-04 01:39:06,039 - uvicorn.error - INFO - Finished server process [26060]
2025-07-04 01:39:06,720 - uvicorn.error - INFO - Shutting down
2025-07-04 01:39:06,829 - uvicorn.error - INFO - Waiting for application shutdown.
2025-07-04 01:39:06,830 - uvicorn.error - INFO - Application shutdown complete.
2025-07-04 01:39:06,830 - uvicorn.error - INFO - Finished server process [40004]
2025-07-04 01:39:07,062 - uvicorn.error - INFO - Application startup complete.
2025-07-04 01:39:07,817 - uvicorn.error - INFO - Application startup complete.
2025-07-04 01:40:56,312 - uvicorn.error - INFO - Shutting down
2025-07-04 01:40:56,421 - uvicorn.error - INFO - Waiting for application shutdown.
2025-07-04 01:40:56,422 - uvicorn.error - INFO - Application shutdown complete.
2025-07-04 01:40:56,422 - uvicorn.error - INFO - Finished server process [8328]
2025-07-04 01:40:56,971 - uvicorn.error - INFO - Shutting down
2025-07-04 01:40:57,078 - uvicorn.error - INFO - Waiting for application shutdown.
2025-07-04 01:40:57,079 - uvicorn.error - INFO - Application shutdown complete.
2025-07-04 01:40:57,080 - uvicorn.error - INFO - Finished server process [41956]
2025-07-04 01:40:57,409 - uvicorn.error - INFO - Application startup complete.
2025-07-04 01:40:58,074 - uvicorn.error - INFO - Application startup complete.
2025-07-04 01:41:29,645 - uvicorn.error - INFO - Shutting down
2025-07-04 01:41:29,755 - uvicorn.error - INFO - Waiting for application shutdown.
2025-07-04 01:41:29,757 - uvicorn.error - INFO - Application shutdown complete.
2025-07-04 01:41:29,757 - uvicorn.error - INFO - Finished server process [23868]
2025-07-04 01:41:30,748 - uvicorn.error - INFO - Shutting down
2025-07-04 01:41:30,780 - uvicorn.error - INFO - Application startup complete.
2025-07-04 01:41:30,857 - uvicorn.error - INFO - Waiting for application shutdown.
2025-07-04 01:41:30,859 - uvicorn.error - INFO - Application shutdown complete.
2025-07-04 01:41:30,859 - uvicorn.error - INFO - Finished server process [27468]
2025-07-04 01:41:31,855 - uvicorn.error - INFO - Application startup complete.
2025-07-04 01:42:03,376 - uvicorn.error - INFO - Shutting down
2025-07-04 01:42:03,487 - uvicorn.error - INFO - Waiting for application shutdown.
2025-07-04 01:42:03,490 - uvicorn.error - INFO - Application shutdown complete.
2025-07-04 01:42:03,491 - uvicorn.error - INFO - Finished server process [25252]
2025-07-04 01:42:04,919 - uvicorn.error - INFO - Application startup complete.
2025-07-04 01:42:04,922 - uvicorn.error - ERROR - Traceback (most recent call last):
  File "C:\Program Files\Python311\Lib\asyncio\runners.py", line 118, in run
    return self._loop.run_until_complete(task)
           ^^^^^^^^^^^^^^^^^^^^^^^^^^^^^^^^^^^
  File "C:\Program Files\Python311\Lib\asyncio\base_events.py", line 650, in run_until_complete
    return future.result()
           ^^^^^^^^^^^^^^^
asyncio.exceptions.CancelledError

During handling of the above exception, another exception occurred:

Traceback (most recent call last):
  File "C:\Program Files\Python311\Lib\asyncio\runners.py", line 190, in run
    return runner.run(main)
           ^^^^^^^^^^^^^^^^
  File "C:\Program Files\Python311\Lib\asyncio\runners.py", line 123, in run
    raise KeyboardInterrupt()
KeyboardInterrupt

During handling of the above exception, another exception occurred:

Traceback (most recent call last):
  File "C:\Program Files\Python311\Lib\contextlib.py", line 222, in __aexit__
    await self.gen.athrow(typ, value, traceback)
  File "E:\tech\trm-os-branches\trm_api\main.py", line 31, in lifespan
    yield
  File "C:\Users\devpc\AppData\Roaming\Python\Python311\site-packages\starlette\routing.py", line 743, in lifespan
    await receive()
  File "C:\Users\devpc\AppData\Roaming\Python\Python311\site-packages\uvicorn\lifespan\on.py", line 137, in receive
    return await self.receive_queue.get()
           ^^^^^^^^^^^^^^^^^^^^^^^^^^^^^^
  File "C:\Program Files\Python311\Lib\asyncio\queues.py", line 158, in get
    await getter
asyncio.exceptions.CancelledError

2025-07-04 01:42:06,298 - uvicorn.error - INFO - Application startup complete.
2025-07-04 01:47:05,181 - uvicorn.error - INFO - Shutting down
2025-07-04 01:47:05,290 - uvicorn.error - INFO - Waiting for application shutdown.
2025-07-04 01:47:05,292 - uvicorn.error - INFO - Application shutdown complete.
2025-07-04 01:47:05,292 - uvicorn.error - INFO - Finished server process [5224]
2025-07-04 01:47:06,789 - uvicorn.error - INFO - Application startup complete.
2025-07-04 01:47:06,791 - uvicorn.error - ERROR - Traceback (most recent call last):
  File "C:\Program Files\Python311\Lib\asyncio\runners.py", line 118, in run
    return self._loop.run_until_complete(task)
           ^^^^^^^^^^^^^^^^^^^^^^^^^^^^^^^^^^^
  File "C:\Program Files\Python311\Lib\asyncio\base_events.py", line 650, in run_until_complete
    return future.result()
           ^^^^^^^^^^^^^^^
asyncio.exceptions.CancelledError

During handling of the above exception, another exception occurred:

Traceback (most recent call last):
  File "C:\Program Files\Python311\Lib\asyncio\runners.py", line 190, in run
    return runner.run(main)
           ^^^^^^^^^^^^^^^^
  File "C:\Program Files\Python311\Lib\asyncio\runners.py", line 123, in run
    raise KeyboardInterrupt()
KeyboardInterrupt

During handling of the above exception, another exception occurred:

Traceback (most recent call last):
  File "C:\Program Files\Python311\Lib\contextlib.py", line 222, in __aexit__
    await self.gen.athrow(typ, value, traceback)
  File "E:\tech\trm-os-branches\trm_api\main.py", line 31, in lifespan
    yield
  File "C:\Users\devpc\AppData\Roaming\Python\Python311\site-packages\starlette\routing.py", line 743, in lifespan
    await receive()
  File "C:\Users\devpc\AppData\Roaming\Python\Python311\site-packages\uvicorn\lifespan\on.py", line 137, in receive
    return await self.receive_queue.get()
           ^^^^^^^^^^^^^^^^^^^^^^^^^^^^^^
  File "C:\Program Files\Python311\Lib\asyncio\queues.py", line 158, in get
    await getter
asyncio.exceptions.CancelledError

2025-07-04 01:47:08,171 - uvicorn.error - INFO - Application startup complete.
2025-07-04 01:52:06,973 - uvicorn.error - INFO - Shutting down
2025-07-04 01:52:07,083 - uvicorn.error - INFO - Waiting for application shutdown.
2025-07-04 01:52:07,086 - uvicorn.error - INFO - Application shutdown complete.
2025-07-04 01:52:07,086 - uvicorn.error - INFO - Finished server process [32892]
2025-07-04 01:52:08,628 - uvicorn.error - INFO - Application startup complete.
2025-07-04 01:52:08,632 - uvicorn.error - ERROR - Traceback (most recent call last):
  File "C:\Program Files\Python311\Lib\asyncio\runners.py", line 118, in run
    return self._loop.run_until_complete(task)
           ^^^^^^^^^^^^^^^^^^^^^^^^^^^^^^^^^^^
  File "C:\Program Files\Python311\Lib\asyncio\base_events.py", line 650, in run_until_complete
    return future.result()
           ^^^^^^^^^^^^^^^
asyncio.exceptions.CancelledError

During handling of the above exception, another exception occurred:

Traceback (most recent call last):
  File "C:\Program Files\Python311\Lib\asyncio\runners.py", line 190, in run
    return runner.run(main)
           ^^^^^^^^^^^^^^^^
  File "C:\Program Files\Python311\Lib\asyncio\runners.py", line 123, in run
    raise KeyboardInterrupt()
KeyboardInterrupt

During handling of the above exception, another exception occurred:

Traceback (most recent call last):
  File "C:\Program Files\Python311\Lib\contextlib.py", line 222, in __aexit__
    await self.gen.athrow(typ, value, traceback)
  File "E:\tech\trm-os-branches\trm_api\main.py", line 31, in lifespan
    yield
  File "C:\Users\devpc\AppData\Roaming\Python\Python311\site-packages\starlette\routing.py", line 743, in lifespan
    await receive()
  File "C:\Users\devpc\AppData\Roaming\Python\Python311\site-packages\uvicorn\lifespan\on.py", line 137, in receive
    return await self.receive_queue.get()
           ^^^^^^^^^^^^^^^^^^^^^^^^^^^^^^
  File "C:\Program Files\Python311\Lib\asyncio\queues.py", line 158, in get
    await getter
asyncio.exceptions.CancelledError

2025-07-04 01:52:09,973 - uvicorn.error - INFO - Application startup complete.
2025-07-04 02:06:30,400 - uvicorn.error - INFO - Shutting down
2025-07-04 02:06:30,510 - uvicorn.error - INFO - Waiting for application shutdown.
2025-07-04 02:06:30,513 - uvicorn.error - INFO - Application shutdown complete.
2025-07-04 02:06:30,513 - uvicorn.error - INFO - Finished server process [27804]
2025-07-04 02:06:30,729 - uvicorn.error - INFO - Shutting down
2025-07-04 02:06:30,840 - uvicorn.error - INFO - Waiting for application shutdown.
2025-07-04 02:06:30,847 - uvicorn.error - INFO - Application shutdown complete.
2025-07-04 02:06:30,848 - uvicorn.error - INFO - Finished server process [13812]
2025-07-04 02:06:31,552 - uvicorn.error - INFO - Application startup complete.
2025-07-04 02:06:31,917 - uvicorn.error - INFO - Application startup complete.
2025-07-04 02:07:32,934 - uvicorn.error - INFO - Shutting down
2025-07-04 02:07:33,042 - uvicorn.error - INFO - Waiting for application shutdown.
2025-07-04 02:07:33,043 - uvicorn.error - INFO - Application shutdown complete.
2025-07-04 02:07:33,043 - uvicorn.error - INFO - Finished server process [29156]
2025-07-04 02:07:33,849 - uvicorn.error - INFO - Shutting down
2025-07-04 02:07:33,958 - uvicorn.error - INFO - Waiting for application shutdown.
2025-07-04 02:07:33,960 - uvicorn.error - INFO - Application shutdown complete.
2025-07-04 02:07:33,960 - uvicorn.error - INFO - Finished server process [39964]
2025-07-04 02:07:34,085 - uvicorn.error - INFO - Application startup complete.
2025-07-04 02:07:34,980 - uvicorn.error - INFO - Application startup complete.
2025-07-04 02:07:45,005 - uvicorn.error - INFO - Shutting down
2025-07-04 02:07:45,115 - uvicorn.error - INFO - Waiting for application shutdown.
2025-07-04 02:07:45,116 - uvicorn.error - INFO - Application shutdown complete.
2025-07-04 02:07:45,116 - uvicorn.error - INFO - Finished server process [41692]
2025-07-04 02:07:46,162 - uvicorn.error - INFO - Application startup complete.
2025-07-04 02:07:46,301 - uvicorn.error - INFO - Shutting down
2025-07-04 02:07:46,412 - uvicorn.error - INFO - Waiting for application shutdown.
2025-07-04 02:07:46,413 - uvicorn.error - INFO - Application shutdown complete.
2025-07-04 02:07:46,414 - uvicorn.error - INFO - Finished server process [9408]
2025-07-04 02:07:47,467 - uvicorn.error - INFO - Application startup complete.
2025-07-04 02:14:11,216 - uvicorn.error - INFO - Shutting down
2025-07-04 02:14:11,326 - uvicorn.error - INFO - Waiting for application shutdown.
2025-07-04 02:14:11,328 - uvicorn.error - INFO - Application shutdown complete.
2025-07-04 02:14:11,328 - uvicorn.error - INFO - Finished server process [24404]
2025-07-04 02:14:11,652 - uvicorn.error - INFO - Shutting down
2025-07-04 02:14:11,761 - uvicorn.error - INFO - Waiting for application shutdown.
2025-07-04 02:14:11,762 - uvicorn.error - INFO - Application shutdown complete.
2025-07-04 02:14:11,763 - uvicorn.error - INFO - Finished server process [15596]
2025-07-04 02:14:12,380 - uvicorn.error - INFO - Application startup complete.
2025-07-04 02:14:12,840 - uvicorn.error - INFO - Application startup complete.
2025-07-04 02:15:09,752 - uvicorn.error - INFO - Shutting down
2025-07-04 02:15:09,860 - uvicorn.error - INFO - Waiting for application shutdown.
2025-07-04 02:15:09,862 - uvicorn.error - INFO - Application shutdown complete.
2025-07-04 02:15:09,863 - uvicorn.error - INFO - Finished server process [21828]
2025-07-04 02:15:10,850 - uvicorn.error - INFO - Application startup complete.
2025-07-04 02:15:11,402 - uvicorn.error - INFO - Shutting down
2025-07-04 02:15:11,510 - uvicorn.error - INFO - Waiting for application shutdown.
2025-07-04 02:15:11,513 - uvicorn.error - INFO - Application shutdown complete.
2025-07-04 02:15:11,513 - uvicorn.error - INFO - Finished server process [34416]
2025-07-04 02:15:12,490 - uvicorn.error - INFO - Application startup complete.
2025-07-04 02:21:12,627 - uvicorn.error - INFO - Shutting down
2025-07-04 02:21:12,627 - uvicorn.error - INFO - Shutting down
2025-07-04 02:21:12,735 - uvicorn.error - INFO - Waiting for application shutdown.
2025-07-04 02:21:12,736 - uvicorn.error - INFO - Application shutdown complete.
2025-07-04 02:21:12,736 - uvicorn.error - INFO - Application shutdown complete.
2025-07-04 02:21:12,736 - uvicorn.error - INFO - Finished server process [42460]
2025-07-04 02:21:12,736 - uvicorn.error - INFO - Finished server process [42252]
2025-07-04 02:21:13,853 - uvicorn.error - INFO - Application startup complete.
2025-07-04 02:21:13,854 - uvicorn.error - INFO - Application startup complete.
2025-07-04 02:22:58,715 - uvicorn.error - INFO - Shutting down
2025-07-04 02:22:58,715 - uvicorn.error - INFO - Shutting down
2025-07-04 02:22:58,840 - uvicorn.error - INFO - Waiting for application shutdown.
2025-07-04 02:22:58,840 - uvicorn.error - INFO - Waiting for application shutdown.
2025-07-04 02:22:58,843 - uvicorn.error - INFO - Application shutdown complete.
2025-07-04 02:22:58,844 - uvicorn.error - INFO - Application shutdown complete.
2025-07-04 02:22:58,843 - uvicorn.error - INFO - Finished server process [38928]
2025-07-04 02:22:58,845 - uvicorn.error - INFO - Finished server process [37680]
2025-07-04 02:22:59,915 - uvicorn.error - INFO - Application startup complete.
2025-07-04 02:22:59,918 - uvicorn.error - INFO - Application startup complete.
2025-07-04 02:23:59,266 - uvicorn.error - INFO - Shutting down
2025-07-04 02:23:59,374 - uvicorn.error - INFO - Waiting for application shutdown.
2025-07-04 02:23:59,379 - uvicorn.error - INFO - Application shutdown complete.
2025-07-04 02:23:59,380 - uvicorn.error - INFO - Finished server process [37272]
2025-07-04 02:23:59,593 - uvicorn.error - INFO - Shutting down
2025-07-04 02:23:59,704 - uvicorn.error - INFO - Waiting for application shutdown.
2025-07-04 02:23:59,708 - uvicorn.error - INFO - Application shutdown complete.
2025-07-04 02:23:59,708 - uvicorn.error - INFO - Finished server process [22428]
2025-07-04 02:24:00,415 - uvicorn.error - INFO - Application startup complete.
2025-07-04 02:24:00,699 - uvicorn.error - INFO - Application startup complete.
2025-07-04 02:24:59,545 - uvicorn.error - INFO - Shutting down
2025-07-04 02:24:59,653 - uvicorn.error - INFO - Waiting for application shutdown.
2025-07-04 02:24:59,662 - uvicorn.error - INFO - Application shutdown complete.
2025-07-04 02:24:59,662 - uvicorn.error - INFO - Finished server process [30868]
2025-07-04 02:24:59,844 - uvicorn.error - INFO - Shutting down
2025-07-04 02:24:59,952 - uvicorn.error - INFO - Waiting for application shutdown.
2025-07-04 02:24:59,954 - uvicorn.error - INFO - Application shutdown complete.
2025-07-04 02:24:59,954 - uvicorn.error - INFO - Finished server process [25324]
2025-07-04 02:25:00,711 - uvicorn.error - INFO - Application startup complete.
2025-07-04 02:25:00,991 - uvicorn.error - INFO - Application startup complete.
2025-07-04 02:25:21,924 - uvicorn.error - INFO - Shutting down
2025-07-04 02:25:22,034 - uvicorn.error - INFO - Waiting for application shutdown.
2025-07-04 02:25:22,036 - uvicorn.error - INFO - Application shutdown complete.
2025-07-04 02:25:22,036 - uvicorn.error - INFO - Finished server process [38516]
2025-07-04 02:25:23,047 - uvicorn.error - INFO - Application startup complete.
2025-07-04 02:25:23,817 - uvicorn.error - INFO - Shutting down
2025-07-04 02:25:23,928 - uvicorn.error - INFO - Waiting for application shutdown.
2025-07-04 02:25:23,932 - uvicorn.error - INFO - Application shutdown complete.
2025-07-04 02:25:23,933 - uvicorn.error - INFO - Finished server process [28592]
2025-07-04 02:25:24,896 - uvicorn.error - INFO - Application startup complete.
2025-07-04 02:25:43,777 - uvicorn.error - INFO - Shutting down
2025-07-04 02:25:43,885 - uvicorn.error - INFO - Waiting for application shutdown.
2025-07-04 02:25:43,887 - uvicorn.error - INFO - Application shutdown complete.
2025-07-04 02:25:43,887 - uvicorn.error - INFO - Finished server process [18052]
2025-07-04 02:25:44,101 - uvicorn.error - INFO - Shutting down
2025-07-04 02:25:44,211 - uvicorn.error - INFO - Waiting for application shutdown.
2025-07-04 02:25:44,213 - uvicorn.error - INFO - Application shutdown complete.
2025-07-04 02:25:44,214 - uvicorn.error - INFO - Finished server process [39404]
2025-07-04 02:25:44,872 - uvicorn.error - INFO - Application startup complete.
2025-07-04 02:25:45,226 - uvicorn.error - INFO - Application startup complete.
2025-07-04 02:26:33,070 - uvicorn.error - INFO - Shutting down
2025-07-04 02:26:33,180 - uvicorn.error - INFO - Waiting for application shutdown.
2025-07-04 02:26:33,181 - uvicorn.error - INFO - Application shutdown complete.
2025-07-04 02:26:33,181 - uvicorn.error - INFO - Finished server process [18980]
2025-07-04 02:26:33,523 - uvicorn.error - INFO - Shutting down
2025-07-04 02:26:33,633 - uvicorn.error - INFO - Waiting for application shutdown.
2025-07-04 02:26:33,634 - uvicorn.error - INFO - Application shutdown complete.
2025-07-04 02:26:33,635 - uvicorn.error - INFO - Finished server process [29104]
2025-07-04 02:26:34,213 - uvicorn.error - INFO - Application startup complete.
2025-07-04 02:26:34,639 - uvicorn.error - INFO - Application startup complete.
2025-07-04 02:28:18,529 - uvicorn.error - INFO - Shutting down
2025-07-04 02:28:18,636 - uvicorn.error - INFO - Waiting for application shutdown.
2025-07-04 02:28:18,637 - uvicorn.error - INFO - Application shutdown complete.
2025-07-04 02:28:18,638 - uvicorn.error - INFO - Finished server process [17128]
2025-07-04 02:28:19,184 - uvicorn.error - INFO - Shutting down
2025-07-04 02:28:19,294 - uvicorn.error - INFO - Waiting for application shutdown.
2025-07-04 02:28:19,294 - uvicorn.error - INFO - Application shutdown complete.
2025-07-04 02:28:19,295 - uvicorn.error - INFO - Finished server process [20132]
2025-07-04 02:28:19,630 - uvicorn.error - INFO - Application startup complete.
2025-07-04 02:28:20,302 - uvicorn.error - INFO - Application startup complete.
2025-07-04 02:28:52,552 - uvicorn.error - INFO - Shutting down
2025-07-04 02:28:52,662 - uvicorn.error - INFO - Waiting for application shutdown.
2025-07-04 02:28:52,663 - uvicorn.error - INFO - Application shutdown complete.
2025-07-04 02:28:52,663 - uvicorn.error - INFO - Finished server process [17160]
2025-07-04 02:28:53,346 - uvicorn.error - INFO - Shutting down
2025-07-04 02:28:53,457 - uvicorn.error - INFO - Waiting for application shutdown.
2025-07-04 02:28:53,458 - uvicorn.error - INFO - Application shutdown complete.
2025-07-04 02:28:53,458 - uvicorn.error - INFO - Finished server process [42204]
2025-07-04 02:28:53,663 - uvicorn.error - INFO - Application startup complete.
2025-07-04 02:28:54,438 - uvicorn.error - INFO - Application startup complete.
2025-07-04 02:31:17,429 - uvicorn.error - INFO - Shutting down
2025-07-04 02:31:17,540 - uvicorn.error - INFO - Waiting for application shutdown.
2025-07-04 02:31:17,540 - uvicorn.error - INFO - Application shutdown complete.
2025-07-04 02:31:17,541 - uvicorn.error - INFO - Finished server process [40108]
2025-07-04 02:31:17,556 - uvicorn.error - INFO - Shutting down
2025-07-04 02:31:17,665 - uvicorn.error - INFO - Waiting for application shutdown.
2025-07-04 02:31:17,666 - uvicorn.error - INFO - Application shutdown complete.
2025-07-04 02:31:17,666 - uvicorn.error - INFO - Finished server process [33548]
2025-07-04 02:31:18,539 - uvicorn.error - INFO - Application startup complete.
2025-07-04 02:31:18,683 - uvicorn.error - INFO - Application startup complete.
2025-07-04 02:36:43,484 - uvicorn.error - INFO - Shutting down
2025-07-04 02:36:43,593 - uvicorn.error - INFO - Waiting for application shutdown.
2025-07-04 02:36:43,594 - uvicorn.error - INFO - Application shutdown complete.
2025-07-04 02:36:43,594 - uvicorn.error - INFO - Finished server process [27924]
2025-07-04 02:36:43,840 - uvicorn.error - INFO - Shutting down
2025-07-04 02:36:43,947 - uvicorn.error - INFO - Waiting for application shutdown.
2025-07-04 02:36:43,948 - uvicorn.error - INFO - Application shutdown complete.
2025-07-04 02:36:43,949 - uvicorn.error - INFO - Finished server process [42304]
2025-07-04 02:36:44,852 - uvicorn.error - INFO - Application startup complete.
2025-07-04 02:36:45,105 - uvicorn.error - INFO - Application startup complete.
2025-07-04 02:37:10,121 - uvicorn.error - INFO - Shutting down
2025-07-04 02:37:10,228 - uvicorn.error - INFO - Waiting for application shutdown.
2025-07-04 02:37:10,228 - uvicorn.error - INFO - Application shutdown complete.
2025-07-04 02:37:10,228 - uvicorn.error - INFO - Finished server process [33436]
2025-07-04 02:37:10,616 - uvicorn.error - INFO - Shutting down
2025-07-04 02:37:10,726 - uvicorn.error - INFO - Waiting for application shutdown.
2025-07-04 02:37:10,726 - uvicorn.error - INFO - Application shutdown complete.
2025-07-04 02:37:10,727 - uvicorn.error - INFO - Finished server process [23504]
2025-07-04 02:37:11,155 - uvicorn.error - INFO - Application startup complete.
2025-07-04 02:37:11,731 - uvicorn.error - INFO - Application startup complete.
2025-07-04 02:38:56,740 - uvicorn.error - INFO - Shutting down
2025-07-04 02:38:56,851 - uvicorn.error - INFO - Waiting for application shutdown.
2025-07-04 02:38:56,851 - uvicorn.error - INFO - Application shutdown complete.
2025-07-04 02:38:56,852 - uvicorn.error - INFO - Finished server process [42148]
2025-07-04 02:38:56,866 - uvicorn.error - INFO - Shutting down
2025-07-04 02:38:56,976 - uvicorn.error - INFO - Waiting for application shutdown.
2025-07-04 02:38:56,976 - uvicorn.error - INFO - Application shutdown complete.
2025-07-04 02:38:56,977 - uvicorn.error - INFO - Finished server process [20484]
2025-07-04 02:38:57,964 - uvicorn.error - INFO - Application startup complete.
2025-07-04 02:38:58,104 - uvicorn.error - INFO - Application startup complete.
2025-07-04 02:39:55,756 - uvicorn.error - INFO - Shutting down
2025-07-04 02:39:55,865 - uvicorn.error - INFO - Waiting for application shutdown.
2025-07-04 02:39:55,870 - uvicorn.error - INFO - Application shutdown complete.
2025-07-04 02:39:55,870 - uvicorn.error - INFO - Finished server process [17064]
2025-07-04 02:39:57,350 - uvicorn.error - INFO - Application startup complete.
2025-07-04 02:39:57,352 - uvicorn.error - ERROR - Traceback (most recent call last):
  File "C:\Program Files\Python311\Lib\asyncio\runners.py", line 118, in run
    return self._loop.run_until_complete(task)
           ^^^^^^^^^^^^^^^^^^^^^^^^^^^^^^^^^^^
  File "C:\Program Files\Python311\Lib\asyncio\base_events.py", line 650, in run_until_complete
    return future.result()
           ^^^^^^^^^^^^^^^
asyncio.exceptions.CancelledError

During handling of the above exception, another exception occurred:

Traceback (most recent call last):
  File "C:\Program Files\Python311\Lib\asyncio\runners.py", line 190, in run
    return runner.run(main)
           ^^^^^^^^^^^^^^^^
  File "C:\Program Files\Python311\Lib\asyncio\runners.py", line 123, in run
    raise KeyboardInterrupt()
KeyboardInterrupt

During handling of the above exception, another exception occurred:

Traceback (most recent call last):
  File "C:\Program Files\Python311\Lib\contextlib.py", line 222, in __aexit__
    await self.gen.athrow(typ, value, traceback)
  File "E:\tech\trm-os-branches\trm_api\main.py", line 31, in lifespan
    yield
  File "C:\Users\devpc\AppData\Roaming\Python\Python311\site-packages\starlette\routing.py", line 743, in lifespan
    await receive()
  File "C:\Users\devpc\AppData\Roaming\Python\Python311\site-packages\uvicorn\lifespan\on.py", line 137, in receive
    return await self.receive_queue.get()
           ^^^^^^^^^^^^^^^^^^^^^^^^^^^^^^
  File "C:\Program Files\Python311\Lib\asyncio\queues.py", line 158, in get
    await getter
asyncio.exceptions.CancelledError

2025-07-04 02:39:58,740 - uvicorn.error - INFO - Application startup complete.
2025-07-04 03:02:17,269 - uvicorn.error - INFO - Shutting down
2025-07-04 03:02:17,378 - uvicorn.error - INFO - Waiting for application shutdown.
2025-07-04 03:02:17,378 - uvicorn.error - INFO - Application shutdown complete.
2025-07-04 03:02:17,379 - uvicorn.error - INFO - Finished server process [42988]
2025-07-04 03:02:17,410 - uvicorn.error - INFO - Shutting down
2025-07-04 03:02:17,519 - uvicorn.error - INFO - Waiting for application shutdown.
2025-07-04 03:02:17,520 - uvicorn.error - INFO - Application shutdown complete.
2025-07-04 03:02:17,520 - uvicorn.error - INFO - Finished server process [3952]
2025-07-04 03:02:18,340 - uvicorn.error - INFO - Application startup complete.
2025-07-04 03:02:18,525 - uvicorn.error - INFO - Application startup complete.
2025-07-04 03:04:20,118 - uvicorn.error - INFO - Shutting down
2025-07-04 03:04:20,180 - uvicorn.error - INFO - Shutting down
2025-07-04 03:04:20,226 - uvicorn.error - INFO - Waiting for application shutdown.
2025-07-04 03:04:20,229 - uvicorn.error - INFO - Application shutdown complete.
2025-07-04 03:04:20,230 - uvicorn.error - INFO - Finished server process [40292]
2025-07-04 03:04:20,289 - uvicorn.error - INFO - Waiting for application shutdown.
2025-07-04 03:04:20,292 - uvicorn.error - INFO - Application shutdown complete.
2025-07-04 03:04:20,293 - uvicorn.error - INFO - Finished server process [41444]
2025-07-04 03:04:21,210 - uvicorn.error - INFO - Application startup complete.
2025-07-04 03:04:21,270 - uvicorn.error - INFO - Application startup complete.
2025-07-04 03:05:46,517 - uvicorn.error - INFO - Shutting down
2025-07-04 03:05:46,625 - uvicorn.error - INFO - Waiting for application shutdown.
2025-07-04 03:05:46,627 - uvicorn.error - INFO - Application shutdown complete.
2025-07-04 03:05:46,628 - uvicorn.error - INFO - Finished server process [36220]
2025-07-04 03:05:48,270 - uvicorn.error - INFO - Application startup complete.
2025-07-04 03:05:48,274 - uvicorn.error - ERROR - Traceback (most recent call last):
  File "C:\Program Files\Python311\Lib\asyncio\runners.py", line 118, in run
    return self._loop.run_until_complete(task)
           ^^^^^^^^^^^^^^^^^^^^^^^^^^^^^^^^^^^
  File "C:\Program Files\Python311\Lib\asyncio\base_events.py", line 650, in run_until_complete
    return future.result()
           ^^^^^^^^^^^^^^^
asyncio.exceptions.CancelledError

During handling of the above exception, another exception occurred:

Traceback (most recent call last):
  File "C:\Program Files\Python311\Lib\asyncio\runners.py", line 190, in run
    return runner.run(main)
           ^^^^^^^^^^^^^^^^
  File "C:\Program Files\Python311\Lib\asyncio\runners.py", line 123, in run
    raise KeyboardInterrupt()
KeyboardInterrupt

During handling of the above exception, another exception occurred:

Traceback (most recent call last):
  File "C:\Program Files\Python311\Lib\contextlib.py", line 222, in __aexit__
    await self.gen.athrow(typ, value, traceback)
  File "E:\tech\trm-os-branches\trm_api\main.py", line 31, in lifespan
    yield
  File "C:\Users\devpc\AppData\Roaming\Python\Python311\site-packages\starlette\routing.py", line 743, in lifespan
    await receive()
  File "C:\Users\devpc\AppData\Roaming\Python\Python311\site-packages\uvicorn\lifespan\on.py", line 137, in receive
    return await self.receive_queue.get()
           ^^^^^^^^^^^^^^^^^^^^^^^^^^^^^^
  File "C:\Program Files\Python311\Lib\asyncio\queues.py", line 158, in get
    await getter
asyncio.exceptions.CancelledError

2025-07-04 03:05:49,895 - uvicorn.error - INFO - Application startup complete.
2025-07-04 03:06:34,953 - uvicorn.error - INFO - Shutting down
2025-07-04 03:06:35,061 - uvicorn.error - INFO - Waiting for application shutdown.
2025-07-04 03:06:35,066 - uvicorn.error - INFO - Application shutdown complete.
2025-07-04 03:06:35,068 - uvicorn.error - INFO - Finished server process [21072]
2025-07-04 03:06:35,432 - uvicorn.error - INFO - Shutting down
2025-07-04 03:06:35,540 - uvicorn.error - INFO - Waiting for application shutdown.
2025-07-04 03:06:35,542 - uvicorn.error - INFO - Application shutdown complete.
2025-07-04 03:06:35,542 - uvicorn.error - INFO - Finished server process [23996]
2025-07-04 03:06:36,198 - uvicorn.error - INFO - Application startup complete.
2025-07-04 03:06:36,555 - uvicorn.error - INFO - Application startup complete.
2025-07-04 03:10:48,685 - uvicorn.error - INFO - Shutting down
2025-07-04 03:10:48,793 - uvicorn.error - INFO - Waiting for application shutdown.
2025-07-04 03:10:48,793 - uvicorn.error - INFO - Application shutdown complete.
2025-07-04 03:10:48,794 - uvicorn.error - INFO - Finished server process [22192]
2025-07-04 03:10:50,226 - uvicorn.error - INFO - Application startup complete.
2025-07-04 04:42:40,026 - uvicorn.error - INFO - Shutting down
2025-07-04 04:42:40,136 - uvicorn.error - INFO - Waiting for application shutdown.
2025-07-04 04:42:40,138 - uvicorn.error - INFO - Application shutdown complete.
2025-07-04 04:42:40,138 - uvicorn.error - INFO - Finished server process [19540]
2025-07-04 04:42:40,540 - uvicorn.error - INFO - Shutting down
2025-07-04 04:42:40,650 - uvicorn.error - INFO - Waiting for application shutdown.
2025-07-04 04:42:40,651 - uvicorn.error - INFO - Application shutdown complete.
2025-07-04 04:42:40,651 - uvicorn.error - INFO - Finished server process [18592]
2025-07-04 04:42:41,264 - uvicorn.error - INFO - Application startup complete.
2025-07-04 04:42:41,775 - uvicorn.error - INFO - Application startup complete.
2025-07-04 04:51:11,917 - uvicorn.error - INFO - Shutting down
2025-07-04 04:51:12,026 - uvicorn.error - INFO - Waiting for application shutdown.
2025-07-04 04:51:12,028 - uvicorn.error - INFO - Application shutdown complete.
2025-07-04 04:51:12,028 - uvicorn.error - INFO - Finished server process [31212]
2025-07-04 04:51:13,276 - uvicorn.error - INFO - Application startup complete.
2025-07-04 04:51:13,357 - uvicorn.error - INFO - Shutting down
2025-07-04 04:51:13,466 - uvicorn.error - INFO - Waiting for application shutdown.
2025-07-04 04:51:13,466 - uvicorn.error - INFO - Application shutdown complete.
2025-07-04 04:51:13,467 - uvicorn.error - INFO - Finished server process [6236]
2025-07-04 04:51:14,556 - uvicorn.error - INFO - Application startup complete.
2025-07-04 04:54:20,671 - uvicorn.error - INFO - Shutting down
2025-07-04 04:54:20,781 - uvicorn.error - INFO - Waiting for application shutdown.
2025-07-04 04:54:20,782 - uvicorn.error - INFO - Application shutdown complete.
2025-07-04 04:54:20,782 - uvicorn.error - INFO - Finished server process [37088]
2025-07-04 04:54:21,361 - uvicorn.error - INFO - Shutting down
2025-07-04 04:54:21,469 - uvicorn.error - INFO - Waiting for application shutdown.
2025-07-04 04:54:21,470 - uvicorn.error - INFO - Application shutdown complete.
2025-07-04 04:54:21,470 - uvicorn.error - INFO - Finished server process [42604]
2025-07-04 04:54:21,899 - uvicorn.error - INFO - Application startup complete.
2025-07-04 04:54:22,588 - uvicorn.error - INFO - Application startup complete.
2025-07-04 05:00:32,363 - uvicorn.error - INFO - Shutting down
2025-07-04 05:00:32,472 - uvicorn.error - INFO - Waiting for application shutdown.
2025-07-04 05:00:32,476 - uvicorn.error - INFO - Application shutdown complete.
2025-07-04 05:00:32,476 - uvicorn.error - INFO - Finished server process [37628]
2025-07-04 05:00:35,821 - uvicorn.error - INFO - Application startup complete.
2025-07-04 05:00:35,864 - uvicorn.error - ERROR - Traceback (most recent call last):
  File "C:\Program Files\Python311\Lib\asyncio\runners.py", line 118, in run
    return self._loop.run_until_complete(task)
           ^^^^^^^^^^^^^^^^^^^^^^^^^^^^^^^^^^^
  File "C:\Program Files\Python311\Lib\asyncio\base_events.py", line 650, in run_until_complete
    return future.result()
           ^^^^^^^^^^^^^^^
asyncio.exceptions.CancelledError

During handling of the above exception, another exception occurred:

Traceback (most recent call last):
  File "C:\Program Files\Python311\Lib\asyncio\runners.py", line 190, in run
    return runner.run(main)
           ^^^^^^^^^^^^^^^^
  File "C:\Program Files\Python311\Lib\asyncio\runners.py", line 123, in run
    raise KeyboardInterrupt()
KeyboardInterrupt

During handling of the above exception, another exception occurred:

Traceback (most recent call last):
  File "C:\Program Files\Python311\Lib\contextlib.py", line 222, in __aexit__
    await self.gen.athrow(typ, value, traceback)
  File "E:\tech\trm-os-branches\trm_api\main.py", line 31, in lifespan
    yield
  File "C:\Users\devpc\AppData\Roaming\Python\Python311\site-packages\starlette\routing.py", line 743, in lifespan
    await receive()
  File "C:\Users\devpc\AppData\Roaming\Python\Python311\site-packages\uvicorn\lifespan\on.py", line 137, in receive
    return await self.receive_queue.get()
           ^^^^^^^^^^^^^^^^^^^^^^^^^^^^^^
  File "C:\Program Files\Python311\Lib\asyncio\queues.py", line 158, in get
    await getter
asyncio.exceptions.CancelledError

2025-07-04 05:00:37,408 - uvicorn.error - INFO - Application startup complete.
2025-07-04 05:05:36,133 - uvicorn.error - INFO - Shutting down
2025-07-04 05:05:36,242 - uvicorn.error - INFO - Waiting for application shutdown.
2025-07-04 05:05:36,244 - uvicorn.error - INFO - Application shutdown complete.
2025-07-04 05:05:36,244 - uvicorn.error - INFO - Finished server process [6328]
2025-07-04 05:05:37,740 - uvicorn.error - INFO - Application startup complete.
2025-07-04 05:05:37,745 - uvicorn.error - ERROR - Traceback (most recent call last):
  File "C:\Program Files\Python311\Lib\asyncio\runners.py", line 118, in run
    return self._loop.run_until_complete(task)
           ^^^^^^^^^^^^^^^^^^^^^^^^^^^^^^^^^^^
  File "C:\Program Files\Python311\Lib\asyncio\base_events.py", line 650, in run_until_complete
    return future.result()
           ^^^^^^^^^^^^^^^
asyncio.exceptions.CancelledError

During handling of the above exception, another exception occurred:

Traceback (most recent call last):
  File "C:\Program Files\Python311\Lib\asyncio\runners.py", line 190, in run
    return runner.run(main)
           ^^^^^^^^^^^^^^^^
  File "C:\Program Files\Python311\Lib\asyncio\runners.py", line 123, in run
    raise KeyboardInterrupt()
KeyboardInterrupt

During handling of the above exception, another exception occurred:

Traceback (most recent call last):
  File "C:\Program Files\Python311\Lib\contextlib.py", line 222, in __aexit__
    await self.gen.athrow(typ, value, traceback)
  File "E:\tech\trm-os-branches\trm_api\main.py", line 31, in lifespan
    yield
  File "C:\Users\devpc\AppData\Roaming\Python\Python311\site-packages\starlette\routing.py", line 743, in lifespan
    await receive()
  File "C:\Users\devpc\AppData\Roaming\Python\Python311\site-packages\uvicorn\lifespan\on.py", line 137, in receive
    return await self.receive_queue.get()
           ^^^^^^^^^^^^^^^^^^^^^^^^^^^^^^
  File "C:\Program Files\Python311\Lib\asyncio\queues.py", line 158, in get
    await getter
asyncio.exceptions.CancelledError

2025-07-04 05:05:39,230 - uvicorn.error - INFO - Application startup complete.
2025-07-04 06:05:46,519 - uvicorn.error - INFO - Shutting down
2025-07-04 06:05:46,630 - uvicorn.error - INFO - Waiting for application shutdown.
2025-07-04 06:05:46,634 - uvicorn.error - INFO - Application shutdown complete.
2025-07-04 06:05:46,634 - uvicorn.error - INFO - Finished server process [3628]
2025-07-04 06:05:48,175 - uvicorn.error - INFO - Application startup complete.
2025-07-04 06:05:48,177 - uvicorn.error - ERROR - Traceback (most recent call last):
  File "C:\Program Files\Python311\Lib\asyncio\runners.py", line 118, in run
    return self._loop.run_until_complete(task)
           ^^^^^^^^^^^^^^^^^^^^^^^^^^^^^^^^^^^
  File "C:\Program Files\Python311\Lib\asyncio\base_events.py", line 650, in run_until_complete
    return future.result()
           ^^^^^^^^^^^^^^^
asyncio.exceptions.CancelledError

During handling of the above exception, another exception occurred:

Traceback (most recent call last):
  File "C:\Program Files\Python311\Lib\asyncio\runners.py", line 190, in run
    return runner.run(main)
           ^^^^^^^^^^^^^^^^
  File "C:\Program Files\Python311\Lib\asyncio\runners.py", line 123, in run
    raise KeyboardInterrupt()
KeyboardInterrupt

During handling of the above exception, another exception occurred:

Traceback (most recent call last):
  File "C:\Program Files\Python311\Lib\contextlib.py", line 222, in __aexit__
    await self.gen.athrow(typ, value, traceback)
  File "E:\tech\trm-os-branches\trm_api\main.py", line 31, in lifespan
    yield
  File "C:\Users\devpc\AppData\Roaming\Python\Python311\site-packages\starlette\routing.py", line 743, in lifespan
    await receive()
  File "C:\Users\devpc\AppData\Roaming\Python\Python311\site-packages\uvicorn\lifespan\on.py", line 137, in receive
    return await self.receive_queue.get()
           ^^^^^^^^^^^^^^^^^^^^^^^^^^^^^^
  File "C:\Program Files\Python311\Lib\asyncio\queues.py", line 158, in get
    await getter
asyncio.exceptions.CancelledError

2025-07-04 06:05:49,519 - uvicorn.error - INFO - Application startup complete.
